<?xml version="1.0" ?>
<!-- =================================================================================== -->
<!-- |    This document was autogenerated by xacro from xacro/V1.xacro                 | -->
<!-- |    EDITING THIS FILE BY HAND IS NOT RECOMMENDED                                 | -->
<!-- =================================================================================== -->
<robot name="valkyrie" xmlns:xacro="http://www.ros.org/wiki/xacro">
  <!-- <xacro:include filename="$(find common_xacro)/xacro/mode_setup_hw.xacro" /> -->
  <!-- <xacro:include filename="$(find valkyrie_description)/robots/valkyrie_A/xacro/common/hw_actuator_types.xacro"/> -->
  <!-- May 2015: However zero mass/inertials links are still useful. (And removed with gz sdf)
  This macro here was added to allow fixed links to have (almost) no effect on the output compound
  sdf mass and inertia
  -->
  <material name="White">
    <color rgba="1.0 1.0 1.0 1.0"/>
  </material>
  <material name="Gold">
    <color rgba="1.0 0.67 0 1.0"/>
  </material>
  <material name="Gray">
    <color rgba="0.5 0.5 0.5 1.0"/>
  </material>
  <material name="Pink">
    <color rgba="0.8 0 0.45 1.0"/>
  </material>
  <!-- Properties -->
  <!-- Actuators -->
  <!-- Transmissions -->
  <!-- Modes -->
  <!-- Battery -->
  <!-- TODO: Get better numbers for battery center from mech team -->
  <!-- <xacro:fixed_joint jointName="battery_offset"
                     parent="/v1/trunk" child="/v1/battery"
                     origin_xyz=".3 0 -0.2"
                     origin_rpy="0 0 0" /> -->
  <!-- TODO: Get better approximation for battery -->
  <!-- <xacro:link_box name="/v1/battery"
                  width=".2" height="0.2" depth="0.2" mass="15.0"
                  origin_rpy="0 0 0"
                  origin_xyz="0 0 0" /> -->
  <!-- Properties -->
  <!-- Link properties. -->
  <!-- Sensors -->
  <!-- Actuators -->
  <!-- Sensors -->
  <!-- Actuators -->
  <!-- Sensors -->
  <!-- Link properties. -->
  <!-- Actuators -->
  <!-- Transmissions -->
  <!-- Modes -->
  <!-- Complete interface -->
  <!-- ${prefix}Palm -->
  <!-- Link properties. -->
  <!-- Actuators -->
  <!-- Transmissions -->
  <!-- Modes -->
  <!-- Complete interface -->
  <!-- Simple interface -->
  <!-- Link properties. -->
  <!-- Actuators -->
  <!-- Transmissions -->
  <!-- Modes -->
  <!-- Complete interface -->
  <!-- Simple interface -->
  <!-- Actuators -->
  <!-- Modes -->
  <!-- Complete interface -->
  <!-- Simple interface -->
  <!-- 	<xacro:macro name="make_thumb_interface" params="prefix channel">
       <xacro:v1_thumb_actuators channel="${channel}" />
       <xacro:v1_thumb_transmissions prefix="${prefix}" channel="${channel}" />
       <xacro:v1_thumb_modes prefix="${prefix}" channel="${channel}" />
       </xacro:macro>
  -->
  <!-- 	<xacro:macro name="make_primary_finger_interface" params="prefix channel">
       <xacro:v1_primary_finger_actuators channel="${channel}" />
       <xacro:v1_primary_finger_transmissions prefix="${prefix}" channel="${channel}" />
       <xacro:v1_primary_finger_modes prefix="${prefix}" channel="${channel}" />
       </xacro:macro> -->
  <!-- 	<xacro:macro name="make_middle_finger_interface" params="prefix channel">
       <xacro:v1_middle_finger_actuators channel="${channel}" />
       <xacro:v1_middle_finger_transmissions prefix="${prefix}" channel="${channel}" />
       <xacro:v1_middle_finger_modes prefix="${prefix}" channel="${channel}" />
       </xacro:macro>

<xacro:macro name="make_little_finger_interface" params="prefix channel">
<xacro:v1_little_finger_actuators channel="${channel}" />
<xacro:v1_little_finger_transmissions prefix="${prefix}" channel="${channel}" />
<xacro:v1_little_finger_modes prefix="${prefix}" channel="${channel}" />
</xacro:macro> -->
  <!-- ===== GAZEBO PLUGINS ===== -->
  <gazebo>
    <plugin filename="libSMInterface.so" name="SharedMemoryInterface">
      <updateRate>1000</updateRate>
      <robotDescriptionParam>/robot_description_sim</robotDescriptionParam>
    </plugin>
    <plugin filename="libJointStatePublisher.so" name="JointStatePublisher">
      <updateRate>1000.0</updateRate>
      <topicName>joint_states_sim</topicName>
    </plugin>
    <plugin filename="libPinPlugin.so" name="PinPlugin">
      <node>/pin_plugin</node>
    </plugin>
  </gazebo>
  <!-- ===== PUBLISH ODOMETRY DATA ==== -->
  <gazebo>
    <plugin filename="libgazebo_ros_p3d.so" name="pos_plugin_ros">
      <alwaysOn>true</alwaysOn>
      <updateRate>1000.0</updateRate>
      <bodyName>/v1/Trunk</bodyName>
      <topicName>/v1/pose</topicName>
      <frameName>world</frameName>
      <rpyOffset>0 0 0</rpyOffset>
      <xyzOffset>0 0 0</xyzOffset>
    </plugin>
  </gazebo>
  <!-- ===== PUBLISH ODOMETRY DATA ==== -->
  <gazebo>
    <plugin filename="libgazebo_ros_p3d.so" name="pos_plugin_ros">
      <alwaysOn>true</alwaysOn>
      <updateRate>1000.0</updateRate>
      <bodyName>/v1/Pelvis</bodyName>
      <topicName>/v1/Pelvis/pose</topicName>
      <frameName>world</frameName>
      <rpyOffset>0 0 0</rpyOffset>
      <xyzOffset>0 0 0</xyzOffset>
    </plugin>
  </gazebo>
  <!-- ===== PELVIS ===== -->
  <link name="Pelvis">
    <inertial>
      <mass value="6.986"/>
      <origin rpy="0 0 0" xyz="0.000733954 -0.000895362 -0.0702552"/>
      <inertia ixx="0.147962" ixy="0.0" ixz="0.0" iyy="0.125353" iyz="0.0" izz="0.115537"/>
    </inertial>
    <visual>
      <geometry>
        <mesh filename="package://valkyrie_description/meshes/reduced_polygon_meshes/pelvis.stl"/>
      </geometry>
      <origin rpy="0 0 0" xyz="0 0 0"/>
      <material name="White"/>
    </visual>
    <collision>
      <geometry>
        <mesh filename="package://valkyrie_description/meshes/reduced_polygon_meshes/pelvis.stl"/>
      </geometry>
      <origin rpy="0 0 0" xyz="0 0 0"/>
    </collision>
  </link>
  <gazebo reference="Pelvis">
    <material>Gazebo/White</material>
  </gazebo>
  <!-- <xacro:v1_pelvis_sensors/> -->
  <!-- ===== TRUNK ===== -->
  <link name="TorsoRoll">
    <inertial>
      <mass value="42.6"/>
      <origin rpy="0 0 0" xyz="0.219 0.03 -0.104"/>
      <inertia ixx="1.19515" ixy="0.0" ixz="0.0" iyy="1.43685" iyz="0.0" izz="1.36738"/>
    </inertial>
    <visual>
      <geometry>
        <mesh filename="package://valkyrie_description/meshes/reduced_polygon_meshes/wj3.stl"/>
      </geometry>
      <origin rpy="0 0 0" xyz="0 0 0"/>
      <material name="White"/>
    </visual>
    <collision>
      <geometry>
        <mesh filename="package://valkyrie_description/meshes/reduced_polygon_meshes/wj3.stl"/>
      </geometry>
      <origin rpy="0 0 0" xyz="0 0 0"/>
    </collision>
  </link>
  <gazebo reference="TorsoRoll">
    <material>Gazebo/White</material>
  </gazebo>
  <!-- Links -->
  <link name="TorsoYaw">
    <!-- Virtual Link -->
    <inertial>
      <mass value="0.1"/>
      <origin rpy="0 0 0" xyz="0 0 0"/>
      <inertia ixx="8.33333333333e-05" ixy="0.0" ixz="0.0" iyy="8.33333333333e-05" iyz="0.0" izz="0.000125"/>
    </inertial>
  </link>
  <link name="TorsoPitch">
    <!-- Virtual Link -->
    <inertial>
      <mass value="0.1"/>
      <origin rpy="0 0 0" xyz="0 0 0"/>
      <inertia ixx="8.33333333333e-05" ixy="0.0" ixz="0.0" iyy="8.33333333333e-05" iyz="0.0" izz="0.000125"/>
    </inertial>
  </link>
  <!-- WJ1 -->
  <joint name="TorsoYaw" type="revolute">
    <origin rpy="0 0 0" xyz="0 0 0"/>
    <axis xyz="0 0 1"/>
    <parent link="Pelvis"/>
    <child link="TorsoYaw"/>
    <limit effort="190" lower="-0.6981317004" upper="0.6981317004" velocity="5.89"/>
    <controller_gains Kd="400" Kp="20000"/>
    <dynamics damping="1.0" friction="0.0"/>
  </joint>
  <gazebo reference="TorsoYaw">
    <provideFeedback>1</provideFeedback>
  </gazebo>
  <!-- WJ2 -->
  <joint name="TorsoPitch" type="revolute">
    <origin rpy="1.57079632679 0 0" xyz="0.04191 0 0"/>
    <axis xyz="0 0 1"/>
    <parent link="TorsoYaw"/>
    <child link="TorsoPitch"/>
    <limit effort="150" lower="-0.6981317004" upper="0.08726646255" velocity="9"/>
    <controller_gains Kd="400" Kp="20000"/>
    <dynamics damping="1.0" friction="0.0"/>
  </joint>
  <gazebo reference="TorsoPitch">
    <provideFeedback>1</provideFeedback>
  </gazebo>
  <!-- WJ3 -->
  <joint name="TorsoRoll" type="revolute">
    <origin rpy="1.57079632679 0 1.57079632679" xyz="0 0.020352 0"/>
    <axis xyz="0 0 1"/>
    <parent link="TorsoPitch"/>
    <child link="TorsoRoll"/>
    <limit effort="150" lower="-0.26179938765" upper="0.26179938765" velocity="9"/>
    <controller_gains Kd="400" Kp="20000"/>
    <dynamics damping="1.0" friction="0.0"/>
  </joint>
  <gazebo reference="TorsoRoll">
    <provideFeedback>1</provideFeedback>
  </gazebo>
  <!-- <xacro:v1_waist_actuators name1="${waist_name1}" type1="${waist_type1}" name2="${waist_name2}" type2="${waist_type2}" name3="${waist_name3}" type3="${waist_type3}"/> -->
  <!-- <xacro:v1_trunk_sensors/> -->
  <!-- ===== HEAD ===== -->
  <!-- LINKS -->
  <link name="LowerNeckPitchLink">
    <!-- Virtual Link -->
    <inertial>
      <mass value="0.1"/>
      <origin rpy="0 0 0" xyz="0 0 0"/>
      <inertia ixx="8.33333333333e-05" ixy="0.0" ixz="0.0" iyy="8.33333333333e-05" iyz="0.0" izz="0.000125"/>
    </inertial>
    <visual>
      <origin rpy="0 0 0" xyz="0 0 0"/>
      <geometry>
        <mesh filename="package://valkyrie_description/meshes/reduced_polygon_meshes/nj1.stl"/>
      </geometry>
      <material name="gold">
        <color rgba="1 0.67 0 1"/>
      </material>
    </visual>
    <collision>
      <origin rpy="0 0 0" xyz="0 0 0"/>
      <geometry>
        <mesh filename="package://valkyrie_description/meshes/reduced_polygon_meshes/nj1.stl"/>
      </geometry>
    </collision>
  </link>
  <link name="NeckYawLink">
    <!-- Virtual Link -->
    <inertial>
      <mass value="0.1"/>
      <origin rpy="0 0 0" xyz="0 0 0"/>
      <inertia ixx="8.33333333333e-05" ixy="0.0" ixz="0.0" iyy="8.33333333333e-05" iyz="0.0" izz="0.000125"/>
    </inertial>
    <visual>
      <origin rpy="0 0 0" xyz="0 0 0"/>
      <geometry>
        <mesh filename="package://valkyrie_description/meshes/reduced_polygon_meshes/nj2.stl"/>
      </geometry>
      <material name="gold">
        <color rgba="1 0.67 0 1"/>
      </material>
    </visual>
    <collision>
      <origin rpy="0 0 0" xyz="0 0 0"/>
      <geometry>
        <mesh filename="package://valkyrie_description/meshes/reduced_polygon_meshes/nj2.stl"/>
      </geometry>
    </collision>
  </link>
  <link name="Head">
    <inertial>
      <mass value="4.06"/>
      <origin rpy="0 0 0" xyz="-0.08380066 0.01114801 -0.00038569"/>
      <inertia ixx="0.031377304" ixy="0.0" ixz="0.0" iyy="0.031377304" iyz="0.0" izz="0.031377304"/>
    </inertial>
    <visual>
      <origin rpy="0 0 0" xyz="0 0 0"/>
      <geometry>
        <mesh filename="package://valkyrie_description/meshes/reduced_polygon_meshes/head.stl"/>
      </geometry>
      <material name="White"/>
    </visual>
    <collision>
      <origin rpy="0 0 0" xyz="0 0 0"/>
      <geometry>
        <mesh filename="package://valkyrie_description/meshes/reduced_polygon_meshes/head.stl"/>
      </geometry>
    </collision>
  </link>
  <gazebo reference="Head">
    <material>Gazebo/White</material>
  </gazebo>
  <!-- NJ1 -->
  <joint name="LowerNeckPitch" type="revolute">
    <origin rpy="0.0 0.0 0.0" xyz="0.3383 0 0.0519"/>
    <axis xyz="0 0 1"/>
    <parent link="TorsoRoll"/>
    <child link="LowerNeckPitchLink"/>
    <limit effort="26" lower="-1.5707963259" upper="0" velocity="5"/>
    <controller_gains Kd="0" Kp="20000"/>
    <dynamics damping="1.0" friction="0.0"/>
  </joint>
  <gazebo reference="LowerNeckPitch">
    <provideFeedback>1</provideFeedback>
  </gazebo>
  <!-- NJ2 -->
  <joint name="NeckYaw" type="revolute">
    <origin rpy="0.0 0.0 0.0" xyz="0 0.0519 0"/>
    <axis xyz="0 0 1"/>
    <parent link="LowerNeckPitchLink"/>
    <child link="NeckYawLink"/>
    <limit effort="26" lower="-1.5707963259" upper="1.5707963259" velocity="5"/>
    <controller_gains Kd="0" Kp="20000"/>
    <dynamics damping="1.0" friction="0.0"/>
  </joint>
  <gazebo reference="NeckYaw">
    <provideFeedback>1</provideFeedback>
  </gazebo>
  <!-- NJ3 -->
  <joint name="UpperNeckPitch" type="revolute">
    <origin rpy="0.0 0.0 0.0" xyz="0.06 0 0.196"/>
    <axis xyz="0 0 1"/>
    <parent link="NeckYawLink"/>
    <child link="Head"/>
    <limit effort="26" lower="-0.08726646255" upper="0.78539816295" velocity="5"/>
    <controller_gains Kd="0" Kp="20000"/>
    <dynamics damping="1.0" friction="0.0"/>
  </joint>
  <gazebo reference="UpperNeckPitch">
    <provideFeedback>1</provideFeedback>
  </gazebo>
  <!-- <xacro:make_head_interface name1="/neck/j1" type1="${neck_type1}"
                               name2="/neck/j2" type2="${neck_type2}"
                               name3="/neck/j3" type3="${neck_type3}"/> -->
  <!-- ===== RIGHT ARM ===== -->
  <!-- LINKS -->
  <link name="RightShoulderPitch">
    <inertial>
      <mass value="2.65"/>
      <origin rpy="0 0 0" xyz="0 -0.01204 -0.251"/>
      <inertia ixx="0.0137181666667" ixy="0.0" ixz="0.0" iyy="0.0105028333333" iyz="0.0" izz="0.0148064333333"/>
    </inertial>
    <visual>
      <geometry>
        <mesh filename="package://valkyrie_description/meshes/reduced_polygon_meshes/aj1_Right.stl"/>
      </geometry>
      <origin rpy="0 0 0" xyz="0 0 0"/>
      <material name="Gold"/>
    </visual>
    <collision>
      <geometry>
        <mesh filename="package://valkyrie_description/meshes/reduced_polygon_meshes/aj1_Right.stl"/>
      </geometry>
      <origin rpy="0 0 0" xyz="0 0 0"/>
    </collision>
  </link>
  <gazebo reference="RightShoulderPitch">
    <material>Gazebo/Gold</material>
  </gazebo>
  <link name="RightShoulderRoll">
    <inertial>
      <mass value="2.87"/>
      <origin rpy="0 0 0" xyz="0.04 0.005 -0.02"/>
      <inertia ixx="0.0122024325" ixy="0.0" ixz="0.0" iyy="0.0175559325" iyz="0.0" izz="0.018176745"/>
    </inertial>
    <visual>
      <geometry>
        <mesh filename="package://valkyrie_description/meshes/reduced_polygon_meshes/aj2.stl"/>
      </geometry>
      <origin rpy="0 0 0" xyz="0 0 0"/>
      <material name="White"/>
    </visual>
    <collision>
      <geometry>
        <mesh filename="package://valkyrie_description/meshes/reduced_polygon_meshes/aj2.stl"/>
      </geometry>
      <origin rpy="0 0 0" xyz="0 0 0"/>
    </collision>
  </link>
  <gazebo reference="RightShoulderRoll">
    <material>Gazebo/White</material>
  </gazebo>
  <link name="RightShoulderYaw">
    <inertial>
      <mass value="2.575"/>
      <origin rpy="0 0 0" xyz="0.02 -0.004 -0.273"/>
      <inertia ixx="0.0227863895833" ixy="0.0" ixz="0.0" iyy="0.0213984645833" iyz="0.0" izz="0.00932579166667"/>
    </inertial>
    <visual>
      <geometry>
        <mesh filename="package://valkyrie_description/meshes/reduced_polygon_meshes/aj3_Right.stl"/>
      </geometry>
      <origin rpy="0 0 0" xyz="0 0 0"/>
      <material name="White"/>
    </visual>
    <collision>
      <geometry>
        <mesh filename="package://valkyrie_description/meshes/reduced_polygon_meshes/aj3_Right.stl"/>
      </geometry>
      <origin rpy="0 0 0" xyz="0 0 0"/>
    </collision>
  </link>
  <gazebo reference="RightShoulderYaw">
    <material>Gazebo/White</material>
  </gazebo>
  <link name="RightElbowPitch">
    <inertial>
      <mass value="2.367"/>
      <origin rpy="0 0 0" xyz="0.0270 -0.0802 0"/>
      <inertia ixx="0.00494170499998" ixy="0.0" ixz="0.0" iyy="0.00469849291665" iyz="0.0" izz="0.00530133991666"/>
    </inertial>
    <visual>
      <geometry>
        <mesh filename="package://valkyrie_description/meshes/reduced_polygon_meshes/aj4.stl"/>
      </geometry>
      <origin rpy="0 0 0" xyz="0 0 0"/>
      <material name="Gold"/>
    </visual>
    <collision>
      <geometry>
        <mesh filename="package://valkyrie_description/meshes/reduced_polygon_meshes/aj4.stl"/>
      </geometry>
      <origin rpy="0 0 0" xyz="0 0 0"/>
    </collision>
  </link>
  <gazebo reference="RightElbowPitch">
    <material>Gazebo/Gold</material>
  </gazebo>
  <!-- AJ1 -->
  <joint name="RightShoulderPitch" type="revolute">
    <origin rpy="1.57079632679 0 0" xyz="0.29842 0 -0.03157"/>
    <axis xyz="0 0 1"/>
    <parent link="TorsoRoll"/>
    <child link="RightShoulderPitch"/>
    <limit effort="190" lower="-3.1415926518" upper="3.1415926518" velocity="5.89"/>
    <controller_gains Kd="400" Kp="20000"/>
    <dynamics damping="1.0" friction="0.0"/>
  </joint>
  <gazebo reference="RightShoulderPitch">
    <provideFeedback>1</provideFeedback>
  </gazebo>
  <!-- AJ2 -->
  <joint name="RightShoulderRoll" type="revolute">
    <origin rpy="1.57079632679 0 3.14159265359" xyz="0 0 -0.246"/>
    <axis xyz="0 0 1"/>
    <parent link="RightShoulderPitch"/>
    <child link="RightShoulderRoll"/>
    <limit effort="190" lower="-3.05432618925" upper="-0.155" velocity="5.89"/>
    <controller_gains Kd="400" Kp="20000"/>
    <dynamics damping="1.0" friction="0.0"/>
  </joint>
  <gazebo reference="RightShoulderRoll">
    <provideFeedback>1</provideFeedback>
  </gazebo>
  <!-- AJ3 -->
  <joint name="RightShoulderYaw" type="revolute">
    <origin rpy="-1.57079632679 0 1.57079632679" xyz="0 0 0"/>
    <axis xyz="0 0 1"/>
    <parent link="RightShoulderRoll"/>
    <child link="RightShoulderYaw"/>
    <limit effort="65" lower="-1.5707963259" upper="1.7" velocity="11.5"/>
    <controller_gains Kd="400" Kp="20000"/>
    <dynamics damping="1.0" friction="0.0"/>
  </joint>
  <gazebo reference="RightShoulderYaw">
    <provideFeedback>1</provideFeedback>
  </gazebo>
  <!-- AJ4 -->
  <joint name="RightElbowPitch" type="revolute">
    <origin rpy="1.57079632679 0 1.57079632679" xyz="0 -0.0254 -0.33"/>
    <axis xyz="0 0 1"/>
    <parent link="RightShoulderYaw"/>
    <child link="RightElbowPitch"/>
    <limit effort="65" lower="-1.9198621761" upper="-0.08726646255" velocity="11.5"/>
    <controller_gains Kd="400" Kp="20000"/>
    <dynamics damping="1.0" friction="0.0"/>
  </joint>
  <gazebo reference="RightElbowPitch">
    <provideFeedback>1</provideFeedback>
  </gazebo>
  <!-- LINKS -->
  <link name="RightForearm">
    <inertial>
      <mass value="2.903"/>
      <origin rpy="0 0 0" xyz="0.015 0.02 -0.11"/>
      <inertia ixx="0.0187305" ixy="0.0" ixz="0.0" iyy="0.0200111" iyz="0.0" izz="0.00761213000002"/>
    </inertial>
    <visual>
      <geometry>
        <mesh filename="package://valkyrie_description/meshes/reduced_polygon_meshes/aj5_Right.stl"/>
      </geometry>
      <origin rpy="0 0 0" xyz="0 0 0"/>
      <material name="White"/>
    </visual>
    <collision>
      <geometry>
        <mesh filename="package://valkyrie_description/meshes/reduced_polygon_meshes/aj5_Right.stl"/>
      </geometry>
      <origin rpy="0 0 0" xyz="0 0 0"/>
    </collision>
  </link>
  <gazebo reference="RightForearm">
    <material>Gazebo/White</material>
  </gazebo>
  <link name="RightWristPitch">
    <inertial>
      <mass value="0.1"/>
      <origin rpy="0 0 0" xyz="0 0 0"/>
      <inertia ixx="2.25083333333e-05" ixy="0.0" ixz="0.0" iyy="2.9175e-05" iyz="0.0" izz="8.33333333333e-06"/>
    </inertial>
    <visual>
      <geometry>
        <box size="0.03 0.01 0.051"/>
      </geometry>
      <origin rpy="0 0 0" xyz="0 0 0"/>
      <material name="Gray"/>
    </visual>
    <collision>
      <geometry>
        <box size="0.03 0.01 0.051"/>
      </geometry>
      <origin rpy="0 0 0" xyz="0 0 0"/>
    </collision>
  </link>
  <link name="RightPalm">
    <inertial>
      <mass value="0.712"/>
      <origin rpy="0 0 0" xyz="0.0425 0 0"/>
      <inertia ixx="0.000679010666667" ixy="0.0" ixz="0.0" iyy="0.000514360666667" iyz="0.0" izz="0.00102201666667"/>
    </inertial>
    <visual>
      <geometry>
        <mesh filename="package://valkyrie_description/meshes/reduced_polygon_meshes/palm_Right.stl"/>
      </geometry>
      <origin rpy="0 0 0" xyz="0 0 0"/>
      <material name="Gold"/>
    </visual>
    <collision>
      <geometry>
        <mesh filename="package://valkyrie_description/meshes/reduced_polygon_meshes/palm_Right.stl"/>
      </geometry>
      <origin rpy="0 0 0" xyz="0 0 0"/>
    </collision>
  </link>
  <gazebo reference="RightPalm">
    <material>Gazebo/Gold</material>
  </gazebo>
  <!-- AJ5 -->
  <joint name="RightForearmYaw" type="revolute">
    <origin rpy="1.57079632679 0 3.14159265359" xyz="0.0254 0 0"/>
    <axis xyz="0 0 1"/>
    <parent link="RightElbowPitch"/>
    <child link="RightForearm"/>
    <limit effort="26" lower="-2.35619448885" upper="2.35619448885" velocity="5"/>
    <controller_gains Kd="0" Kp="20000"/>
    <dynamics damping="1.0" friction="0.0"/>
  </joint>
  <gazebo reference="RightForearmYaw">
    <provideFeedback>1</provideFeedback>
  </gazebo>
  <!-- AJ6 -->
  <joint name="RightWristPitch" type="revolute">
    <origin rpy="-1.57079632679 0 1.57079632679" xyz="0 0 -0.287"/>
    <axis xyz="0 0 1"/>
    <parent link="RightForearm"/>
    <child link="RightWristPitch"/>
    <limit effort="14" lower="-0.8726646255" upper="0.6981317004" velocity="1"/>
    <controller_gains Kd="400" Kp="20000"/>
    <dynamics damping="1.0" friction="0.0"/>
  </joint>
  <gazebo reference="RightWristPitch">
    <provideFeedback>1</provideFeedback>
  </gazebo>
  <!-- AJ7 -->
  <joint name="RightWristRoll" type="revolute">
    <origin rpy="1.57079632679 0 1.57079632679" xyz="0 0 0"/>
    <axis xyz="0 0 1"/>
    <parent link="RightWristPitch"/>
    <child link="RightPalm"/>
    <limit effort="14" lower="-0.5235987753" upper="0.43633231275" velocity="1"/>
    <controller_gains Kd="400" Kp="20000"/>
    <dynamics damping="1.0" friction="0.0"/>
  </joint>
  <gazebo reference="RightWristRoll">
    <provideFeedback>1</provideFeedback>
  </gazebo>
  <!-- <xacro:v1_arm_actuators name1="${rightarm_name1}" type1="${arm_type1}"
                            name2="${rightarm_name2}" type2="${arm_type2}"
                            name3="${rightarm_name3}" type3="${arm_type3}"
                            name4="${rightarm_name4}" type4="${arm_type4}"
                            name5="${rightarm_name5}" type5="${arm_type5}"
                            name6="${rightarm_name6}" type6="${arm_type6}"
                            name7="${rightarm_name7}" type7="${arm_type7}"/> -->
  <!-- <xacro:v1_arm_sensors /> -->
  <!-- ===== RIGHT THUMB ===== -->
  <!-- LINKS -->
  <link name="RightThumbPitch1">
    <inertial>
      <mass value="0.017"/>
      <origin rpy="0 0 0" xyz="0 0 0"/>
      <inertia ixx="2.83333333333e-07" ixy="0.0" ixz="0.0" iyy="2.83333333333e-07" iyz="0.0" izz="2.83333333333e-07"/>
    </inertial>
    <visual>
      <geometry>
        <mesh filename="package://valkyrie_description/meshes/reduced_polygon_meshes/tf1_Right.stl"/>
      </geometry>
      <origin rpy="0 0 0" xyz="0 0 0"/>
      <material name="Gold"/>
    </visual>
    <collision>
      <geometry>
        <mesh filename="package://valkyrie_description/meshes/reduced_polygon_meshes/tf1_Right.stl"/>
      </geometry>
      <origin rpy="0 0 0" xyz="0 0 0"/>
    </collision>
  </link>
  <gazebo reference="RightThumbPitch1">
    <material>Gazebo/Gold</material>
  </gazebo>
  <link name="RightThumbPitch2">
    <inertial>
      <mass value="0.02"/>
      <origin rpy="0 0 0" xyz="0.017 0 0"/>
      <inertia ixx="1.72833333333e-06" ixy="0.0" ixz="0.0" iyy="5.98666666667e-06" iyz="0.0" izz="5.46166666667e-06"/>
    </inertial>
    <visual>
      <geometry>
        <mesh filename="package://valkyrie_description/meshes/reduced_polygon_meshes/tf2.stl"/>
      </geometry>
      <origin rpy="0 0 0" xyz="0 0 0"/>
      <material name="Gold"/>
    </visual>
    <collision>
      <geometry>
        <mesh filename="package://valkyrie_description/meshes/reduced_polygon_meshes/tf2.stl"/>
      </geometry>
      <origin rpy="0 0 0" xyz="0 0 0"/>
    </collision>
  </link>
  <gazebo reference="RightThumbPitch2">
    <material>Gazebo/Gold</material>
  </gazebo>
  <link name="RightThumbPitch3">
    <inertial>
      <mass value="0.013"/>
      <origin rpy="0 0 0" xyz="0.011 0 0"/>
      <inertia ixx="7.07416666667e-07" ixy="0.0" ixz="0.0" iyy="1.77666666667e-06" iyz="0.0" izz="1.43541666667e-06"/>
    </inertial>
    <visual>
      <geometry>
        <mesh filename="package://valkyrie_description/meshes/reduced_polygon_meshes/tf3.stl"/>
      </geometry>
      <origin rpy="0 0 0" xyz="0 0 0"/>
      <material name="Gold"/>
    </visual>
    <collision>
      <geometry>
        <mesh filename="package://valkyrie_description/meshes/reduced_polygon_meshes/tf3.stl"/>
      </geometry>
      <origin rpy="0 0 0" xyz="0 0 0"/>
    </collision>
  </link>
  <gazebo reference="RightThumbPitch3">
    <material>Gazebo/Gold</material>
  </gazebo>
  <link name="RightThumbPitch4">
    <inertial>
      <mass value="0.006"/>
      <origin rpy="0 0 0" xyz="0.0086 0 0"/>
      <inertia ixx="2.525e-07" ixy="0.0" ixz="0.0" iyy="5.45e-07" iyz="0.0" izz="4.365e-07"/>
    </inertial>
    <visual>
      <geometry>
        <mesh filename="package://valkyrie_description/meshes/reduced_polygon_meshes/tf4.stl"/>
      </geometry>
      <origin rpy="0 0 0" xyz="0 0 0"/>
      <material name="Gold"/>
    </visual>
    <collision>
      <geometry>
        <mesh filename="package://valkyrie_description/meshes/reduced_polygon_meshes/tf4.stl"/>
      </geometry>
      <origin rpy="0 0 0" xyz="0 0 0"/>
    </collision>
  </link>
  <gazebo reference="RightThumbPitch4">
    <material>Gazebo/Gold</material>
  </gazebo>
  <!-- TJ1 -->
  <joint name="RightThumbRoll" type="fixed">
    <origin rpy="1.57079632679 0 -1.34390352" xyz="0.00748367180673 -0.0324153432851 0.005182"/>
    <axis xyz="0 0 1"/>
    <parent link="RightPalm"/>
    <child link="RightThumbPitch1"/>
  </joint>
  <!-- TJ2 -->
  <joint name="RightThumbPitch1" type="fixed">
    <origin rpy="1.57079632679 0 0" xyz="0.02286 0 -0.025091"/>
    <axis xyz="0 0 1"/>
    <parent link="RightThumbPitch1"/>
    <child link="RightThumbPitch2"/>
  </joint>
  <!-- TJ3 -->
  <joint name="RightThumbPitch2" type="fixed">
    <origin rpy="0 0 0" xyz="0.0381 0 0"/>
    <axis xyz="0 0 1"/>
    <parent link="RightThumbPitch2"/>
    <child link="RightThumbPitch3"/>
  </joint>
  <!-- TJ4 -->
  <joint name="RightThumbPitch3" type="fixed">
    <origin rpy="0 0 0" xyz="0.02794 0 0"/>
    <axis xyz="0 0 1"/>
    <parent link="RightThumbPitch3"/>
    <child link="RightThumbPitch4"/>
  </joint>
  <!-- ===== RIGHT PRIMARY FINGER ===== -->
  <!-- LINKS -->
  <link name="RightIndexFingerPitch1">
    <inertial>
      <mass value="0.006"/>
      <origin rpy="0 0 0" xyz="-0.0048 0 0"/>
      <inertia ixx="4.225e-07" ixy="0.0" ixz="0.0" iyy="6.625e-07" iyz="0.0" izz="6.01e-07"/>
    </inertial>
    <visual>
      <geometry>
        <mesh filename="package://valkyrie_description/meshes/reduced_polygon_meshes/pf1.stl"/>
      </geometry>
      <origin rpy="0 0 0" xyz="0 0 0"/>
      <material name="Gold"/>
    </visual>
    <collision>
      <geometry>
        <mesh filename="package://valkyrie_description/meshes/reduced_polygon_meshes/pf1.stl"/>
      </geometry>
      <origin rpy="0 0 0" xyz="0 0 0"/>
    </collision>
  </link>
  <gazebo reference="RightIndexFingerPitch1">
    <material>Gazebo/Gold</material>
  </gazebo>
  <link name="RightIndexFingerPitch2">
    <inertial>
      <mass value="0.018"/>
      <origin rpy="0 0 0" xyz="0.0175 0 0"/>
      <inertia ixx="1.203e-06" ixy="0.0" ixz="0.0" iyy="5.0355e-06" iyz="0.0" izz="4.9155e-06"/>
    </inertial>
    <visual>
      <geometry>
        <mesh filename="package://valkyrie_description/meshes/reduced_polygon_meshes/pf2.stl"/>
      </geometry>
      <origin rpy="0 0 0" xyz="0 0 0"/>
      <material name="Gold"/>
    </visual>
    <collision>
      <geometry>
        <mesh filename="package://valkyrie_description/meshes/reduced_polygon_meshes/pf2.stl"/>
      </geometry>
      <origin rpy="0 0 0" xyz="0 0 0"/>
    </collision>
  </link>
  <gazebo reference="RightIndexFingerPitch2">
    <material>Gazebo/Gold</material>
  </gazebo>
  <link name="RightIndexFingerPitch3">
    <inertial>
      <mass value="0.01"/>
      <origin rpy="0 0 0" xyz="0.0108 -0.0003 0"/>
      <inertia ixx="3.81666666667e-07" ixy="0.0" ixz="0.0" iyy="1.20416666667e-06" iyz="0.0" izz="1.10416666667e-06"/>
    </inertial>
    <visual>
      <geometry>
        <mesh filename="package://valkyrie_description/meshes/reduced_polygon_meshes/pf3.stl"/>
      </geometry>
      <origin rpy="0 0 0" xyz="0 0 0"/>
      <material name="Gold"/>
    </visual>
    <collision>
      <geometry>
        <mesh filename="package://valkyrie_description/meshes/reduced_polygon_meshes/pf3.stl"/>
      </geometry>
      <origin rpy="0 0 0" xyz="0 0 0"/>
    </collision>
  </link>
  <gazebo reference="RightIndexFingerPitch3">
    <material>Gazebo/Gold</material>
  </gazebo>
  <link name="RightIndexFingerPitch4">
    <inertial>
      <mass value="0.005"/>
      <origin rpy="0 0 0" xyz="0.00857 -0.000696 0"/>
      <inertia ixx="1.5375e-07" ixy="0.0" ixz="0.0" iyy="3.975e-07" iyz="0.0" izz="3.6375e-07"/>
    </inertial>
    <visual>
      <geometry>
        <mesh filename="package://valkyrie_description/meshes/reduced_polygon_meshes/pf4.stl"/>
      </geometry>
      <origin rpy="0 0 0" xyz="0 0 0"/>
      <material name="Gold"/>
    </visual>
    <collision>
      <geometry>
        <mesh filename="package://valkyrie_description/meshes/reduced_polygon_meshes/pf4.stl"/>
      </geometry>
      <origin rpy="0 0 0" xyz="0 0 0"/>
    </collision>
  </link>
  <gazebo reference="RightIndexFingerPitch4">
    <material>Gazebo/Gold</material>
  </gazebo>
  <!-- PFJ1 -->
  <joint name="RightPrimaryMPYaw" type="fixed">
    <origin rpy="0.0 0 -0.366519143" xyz="0.0776738914821 -0.0298162134085 0.00254"/>
    <axis xyz="0 0 1"/>
    <parent link="RightPalm"/>
    <child link="RightIndexFingerPitch1"/>
  </joint>
  <!-- PFJ2 -->
  <joint name="RightPrimaryMPExtensor" type="fixed">
    <origin rpy="-1.57079632679 0 0.0568977336" xyz="0.0169724899301 0.000966739661347 0"/>
    <axis xyz="0 0 1"/>
    <parent link="RightIndexFingerPitch1"/>
    <child link="RightIndexFingerPitch2"/>
  </joint>
  <!-- PFJ3 -->
  <joint name="RightPrimaryPIPExtensor" type="fixed">
    <origin rpy="0 0 0" xyz="0.0381 0 0"/>
    <axis xyz="0 0 1"/>
    <parent link="RightIndexFingerPitch2"/>
    <child link="RightIndexFingerPitch3"/>
  </joint>
  <!-- PFJ4 -->
  <joint name="RightPrimaryDIPExtensor" type="fixed">
    <origin rpy="0 0 0" xyz="0.02286 0 0"/>
    <axis xyz="0 0 1"/>
    <parent link="RightIndexFingerPitch3"/>
    <child link="RightIndexFingerPitch4"/>
  </joint>
  <!-- ===== RIGHT MIDDLE FINGER ===== -->
  <!-- LINKS -->
  <link name="RightMiddleFingerPitch1">
    <inertial>
      <mass value="0.02"/>
      <origin rpy="0 0 0" xyz="0.017 0 0"/>
      <inertia ixx="1.72833333333e-06" ixy="0.0" ixz="0.0" iyy="5.98666666667e-06" iyz="0.0" izz="5.46166666667e-06"/>
    </inertial>
    <visual>
      <geometry>
        <mesh filename="package://valkyrie_description/meshes/reduced_polygon_meshes/sf1.stl"/>
      </geometry>
      <origin rpy="0 0 0" xyz="0 0 0"/>
      <material name="Gold"/>
    </visual>
    <collision>
      <geometry>
        <mesh filename="package://valkyrie_description/meshes/reduced_polygon_meshes/sf1.stl"/>
      </geometry>
      <origin rpy="0 0 0" xyz="0 0 0"/>
    </collision>
  </link>
  <gazebo reference="RightMiddleFingerPitch1">
    <material>Gazebo/Gold</material>
  </gazebo>
  <link name="RightMiddleFingerPitch2">
    <inertial>
      <mass value="0.011"/>
      <origin rpy="0 0 0" xyz="0.011 0 0"/>
      <inertia ixx="5.98583333333e-07" ixy="0.0" ixz="0.0" iyy="1.50333333333e-06" iyz="0.0" izz="1.21458333333e-06"/>
    </inertial>
    <visual>
      <geometry>
        <mesh filename="package://valkyrie_description/meshes/reduced_polygon_meshes/sf2_ssf3.stl"/>
      </geometry>
      <origin rpy="0 0 0" xyz="0 0 0"/>
      <material name="Gold"/>
    </visual>
    <collision>
      <geometry>
        <mesh filename="package://valkyrie_description/meshes/reduced_polygon_meshes/sf2_ssf3.stl"/>
      </geometry>
      <origin rpy="0 0 0" xyz="0 0 0"/>
    </collision>
  </link>
  <gazebo reference="RightMiddleFingerPitch2">
    <material>Gazebo/Gold</material>
  </gazebo>
  <link name="RightMiddleFingerPitch3">
    <inertial>
      <mass value="0.006"/>
      <origin rpy="0 0 0" xyz="0.0086 0 0"/>
      <inertia ixx="2.525e-07" ixy="0.0" ixz="0.0" iyy="5.45e-07" iyz="0.0" izz="4.365e-07"/>
    </inertial>
    <visual>
      <geometry>
        <mesh filename="package://valkyrie_description/meshes/reduced_polygon_meshes/sf3_ssf4.stl"/>
      </geometry>
      <origin rpy="0 0 0" xyz="0 0 0"/>
      <material name="Gold"/>
    </visual>
    <collision>
      <geometry>
        <mesh filename="package://valkyrie_description/meshes/reduced_polygon_meshes/sf3_ssf4.stl"/>
      </geometry>
      <origin rpy="0 0 0" xyz="0 0 0"/>
    </collision>
  </link>
  <gazebo reference="RightMiddleFingerPitch3">
    <material>Gazebo/Gold</material>
  </gazebo>
  <!-- MFJ1 -->
  <joint name="RightMiddleFingerPitch1" type="fixed">
    <origin rpy="-1.57079632679 0 0" xyz="0.09767 0 0.00254"/>
    <axis xyz="0 0 1"/>
    <parent link="RightPalm"/>
    <child link="RightMiddleFingerPitch1"/>
  </joint>
  <!-- MFJ2 -->
  <joint name="RightMiddleFingerPitch2" type="fixed">
    <origin rpy="0 0 0" xyz="0.0381 0 0"/>
    <axis xyz="0 0 1"/>
    <parent link="RightMiddleFingerPitch1"/>
    <child link="RightMiddleFingerPitch2"/>
  </joint>
  <!-- MFJ3 -->
  <joint name="RightMiddleFingerPitch3" type="fixed">
    <origin rpy="0 0 0" xyz="0.02286 0 0"/>
    <axis xyz="0 0 1"/>
    <parent link="RightMiddleFingerPitch2"/>
    <child link="RightMiddleFingerPitch3"/>
  </joint>
  <!-- ===== RIGHT LITTLE FINGER ===== -->
  <!-- LINKS -->
  <link name="RightPinkyPitch1">
    <inertial>
      <mass value="0.047"/>
      <origin rpy="0 0 0" xyz="0 0 0"/>
      <inertia ixx="7.83333333333e-07" ixy="0.0" ixz="0.0" iyy="7.83333333333e-07" iyz="0.0" izz="7.83333333333e-07"/>
    </inertial>
    <visual>
      <geometry>
        <mesh filename="package://valkyrie_description/meshes/reduced_polygon_meshes/ssf1_Right.stl"/>
      </geometry>
      <origin rpy="0 0 0" xyz="0 0 0"/>
      <material name="Gold"/>
    </visual>
    <collision>
      <geometry>
        <mesh filename="package://valkyrie_description/meshes/reduced_polygon_meshes/ssf1_Right.stl"/>
      </geometry>
      <origin rpy="0 0 0" xyz="0 0 0"/>
    </collision>
  </link>
  <gazebo reference="RightPinkyPitch1">
    <material>Gazebo/Gold</material>
  </gazebo>
  <link name="RightPinkyPitch2">
    <inertial>
      <mass value="0.02"/>
      <origin rpy="0 0 0" xyz="0 0.017 0.050169"/>
      <inertia ixx="5.98666666667e-06" ixy="0.0" ixz="0.0" iyy="1.72833333333e-06" iyz="0.0" izz="5.46166666667e-06"/>
    </inertial>
    <visual>
      <geometry>
        <mesh filename="package://valkyrie_description/meshes/reduced_polygon_meshes/ssf2_Right.stl"/>
      </geometry>
      <origin rpy="0 0 0" xyz="0 0 0"/>
      <material name="Gold"/>
    </visual>
    <collision>
      <geometry>
        <mesh filename="package://valkyrie_description/meshes/reduced_polygon_meshes/ssf2_Right.stl"/>
      </geometry>
      <origin rpy="0 0 0" xyz="0 0 0"/>
    </collision>
  </link>
  <gazebo reference="RightPinkyPitch2">
    <material>Gazebo/Gold</material>
  </gazebo>
  <link name="RightPinkyPitch3">
    <inertial>
      <mass value="0.011"/>
      <origin rpy="0 0 0" xyz="0.011 0 0"/>
      <inertia ixx="5.98583333333e-07" ixy="0.0" ixz="0.0" iyy="1.50333333333e-06" iyz="0.0" izz="1.21458333333e-06"/>
    </inertial>
    <visual>
      <geometry>
        <mesh filename="package://valkyrie_description/meshes/reduced_polygon_meshes/sf2_ssf3.stl"/>
      </geometry>
      <origin rpy="0 0 0" xyz="0 0 0"/>
      <material name="Gold"/>
    </visual>
    <collision>
      <geometry>
        <mesh filename="package://valkyrie_description/meshes/reduced_polygon_meshes/sf2_ssf3.stl"/>
      </geometry>
      <origin rpy="0 0 0" xyz="0 0 0"/>
    </collision>
  </link>
  <gazebo reference="RightPinkyPitch3">
    <material>Gazebo/Gold</material>
  </gazebo>
  <!-- LFJ1 -->
  <joint name="RightPinkyPitch1" type="fixed">
    <origin rpy="-1.57079632679 0 0.690626785" xyz="0.0427072303336 0.0352928446888 -0.007747"/>
    <axis xyz="0 0 1"/>
    <parent link="RightPalm"/>
    <child link="RightPinkyPitch1"/>
  </joint>
  <!-- LFJ2 -->
  <joint name="RightPinkyPitch2" type="fixed">
    <origin rpy="-0.690626785 0 -1.57079632679" xyz="0 -0.010287 -0.071327"/>
    <axis xyz="0 0 1"/>
    <parent link="RightPinkyPitch1"/>
    <child link="RightPinkyPitch2"/>
  </joint>
  <!-- LFJ3 -->
  <joint name="RightPinkyPitch3" type="fixed">
    <origin rpy="0 0 1.57079632679" xyz="0 0.0381 0.050169"/>
    <axis xyz="0 0 1"/>
    <parent link="RightPinkyPitch2"/>
    <child link="RightPinkyPitch3"/>
  </joint>
  <!-- ===== LEFT ARM ===== -->
  <!-- LINKS -->
  <link name="LeftShoulderPitch">
    <inertial>
      <mass value="2.65"/>
      <origin rpy="0 0 0" xyz="0 -0.01204 0.251"/>
      <inertia ixx="0.0137181666667" ixy="0.0" ixz="0.0" iyy="0.0105028333333" iyz="0.0" izz="0.0148064333333"/>
    </inertial>
    <visual>
      <geometry>
        <mesh filename="package://valkyrie_description/meshes/reduced_polygon_meshes/aj1_Left.stl"/>
      </geometry>
      <origin rpy="0 0 0" xyz="0 0 0"/>
      <material name="Gold"/>
    </visual>
    <collision>
      <geometry>
        <mesh filename="package://valkyrie_description/meshes/reduced_polygon_meshes/aj1_Left.stl"/>
      </geometry>
      <origin rpy="0 0 0" xyz="0 0 0"/>
    </collision>
  </link>
  <gazebo reference="LeftShoulderPitch">
    <material>Gazebo/Gold</material>
  </gazebo>
  <link name="LeftShoulderRoll">
    <inertial>
      <mass value="2.87"/>
      <origin rpy="0 0 0" xyz="0.04 0.005 0.02"/>
      <inertia ixx="0.0122024325" ixy="0.0" ixz="0.0" iyy="0.0175559325" iyz="0.0" izz="0.018176745"/>
    </inertial>
    <visual>
      <geometry>
        <mesh filename="package://valkyrie_description/meshes/reduced_polygon_meshes/aj2.stl"/>
      </geometry>
      <origin rpy="0 0 0" xyz="0 0 0"/>
      <material name="White"/>
    </visual>
    <collision>
      <geometry>
        <mesh filename="package://valkyrie_description/meshes/reduced_polygon_meshes/aj2.stl"/>
      </geometry>
      <origin rpy="0 0 0" xyz="0 0 0"/>
    </collision>
  </link>
  <gazebo reference="LeftShoulderRoll">
    <material>Gazebo/White</material>
  </gazebo>
  <link name="LeftShoulderYaw">
    <inertial>
      <mass value="2.575"/>
      <origin rpy="0 0 0" xyz="-0.02 0.004 0.273"/>
      <inertia ixx="0.0227863895833" ixy="0.0" ixz="0.0" iyy="0.0213984645833" iyz="0.0" izz="0.00932579166667"/>
    </inertial>
    <visual>
      <geometry>
        <mesh filename="package://valkyrie_description/meshes/reduced_polygon_meshes/aj3_Left.stl"/>
      </geometry>
      <origin rpy="0 0 0" xyz="0 0 0"/>
      <material name="White"/>
    </visual>
    <collision>
      <geometry>
        <mesh filename="package://valkyrie_description/meshes/reduced_polygon_meshes/aj3_Left.stl"/>
      </geometry>
      <origin rpy="0 0 0" xyz="0 0 0"/>
    </collision>
  </link>
  <gazebo reference="LeftShoulderYaw">
    <material>Gazebo/White</material>
  </gazebo>
  <link name="LeftElbowPitch">
    <inertial>
      <mass value="2.367"/>
      <origin rpy="0 0 0" xyz="0.0270 -0.0802 0"/>
      <inertia ixx="0.00494170499998" ixy="0.0" ixz="0.0" iyy="0.00469849291665" iyz="0.0" izz="0.00530133991666"/>
    </inertial>
    <visual>
      <geometry>
        <mesh filename="package://valkyrie_description/meshes/reduced_polygon_meshes/aj4.stl"/>
      </geometry>
      <origin rpy="0 0 0" xyz="0 0 0"/>
      <material name="Gold"/>
    </visual>
    <collision>
      <geometry>
        <mesh filename="package://valkyrie_description/meshes/reduced_polygon_meshes/aj4.stl"/>
      </geometry>
      <origin rpy="0 0 0" xyz="0 0 0"/>
    </collision>
  </link>
  <gazebo reference="LeftElbowPitch">
    <material>Gazebo/Gold</material>
  </gazebo>
  <!-- AJ1 -->
  <joint name="LeftShoulderPitch" type="revolute">
    <origin rpy="1.57079632679 0 0" xyz="0.29842 0 -0.03157"/>
    <axis xyz="0 0 1"/>
    <parent link="TorsoRoll"/>
    <child link="LeftShoulderPitch"/>
    <limit effort="190" lower="-3.1415926518" upper="3.1415926518" velocity="5.89"/>
    <controller_gains Kd="400" Kp="20000"/>
    <dynamics damping="1.0" friction="0.0"/>
  </joint>
  <gazebo reference="LeftShoulderPitch">
    <provideFeedback>1</provideFeedback>
  </gazebo>
  <!-- AJ2 -->
  <joint name="LeftShoulderRoll" type="revolute">
    <origin rpy="-1.57079632679 0 3.14159265359" xyz="0 0 0.246"/>
    <axis xyz="0 0 1"/>
    <parent link="LeftShoulderPitch"/>
    <child link="LeftShoulderRoll"/>
    <limit effort="190" lower="-3.05432618925" upper="-0.155" velocity="5.89"/>
    <controller_gains Kd="400" Kp="20000"/>
    <dynamics damping="1.0" friction="0.0"/>
  </joint>
  <gazebo reference="LeftShoulderRoll">
    <provideFeedback>1</provideFeedback>
  </gazebo>
  <!-- AJ3 -->
  <joint name="LeftShoulderYaw" type="revolute">
    <origin rpy="-1.57079632679 0 -1.57079632679" xyz="0 0 0"/>
    <axis xyz="0 0 1"/>
    <parent link="LeftShoulderRoll"/>
    <child link="LeftShoulderYaw"/>
    <limit effort="65" lower="-1.5707963259" upper="1.7" velocity="11.5"/>
    <controller_gains Kd="400" Kp="20000"/>
    <dynamics damping="1.0" friction="0.0"/>
  </joint>
  <gazebo reference="LeftShoulderYaw">
    <provideFeedback>1</provideFeedback>
  </gazebo>
  <!-- AJ4 -->
  <joint name="LeftElbowPitch" type="revolute">
    <origin rpy="-1.57079632679 0 -1.57079632679" xyz="0 0.0254 0.33"/>
    <axis xyz="0 0 1"/>
    <parent link="LeftShoulderYaw"/>
    <child link="LeftElbowPitch"/>
    <limit effort="65" lower="-1.9198621761" upper="-0.08726646255" velocity="11.5"/>
    <controller_gains Kd="400" Kp="20000"/>
    <dynamics damping="1.0" friction="0.0"/>
  </joint>
  <gazebo reference="LeftElbowPitch">
    <provideFeedback>1</provideFeedback>
  </gazebo>
  <!-- LINKS -->
  <link name="LeftForearm">
    <inertial>
      <mass value="2.903"/>
      <origin rpy="0 0 0" xyz="0.015 -0.02 0.11"/>
      <inertia ixx="0.0187305" ixy="0.0" ixz="0.0" iyy="0.0200111" iyz="0.0" izz="0.00761213000002"/>
    </inertial>
    <visual>
      <geometry>
        <mesh filename="package://valkyrie_description/meshes/reduced_polygon_meshes/aj5_Left.stl"/>
      </geometry>
      <origin rpy="0 0 0" xyz="0 0 0"/>
      <material name="White"/>
    </visual>
    <collision>
      <geometry>
        <mesh filename="package://valkyrie_description/meshes/reduced_polygon_meshes/aj5_Left.stl"/>
      </geometry>
      <origin rpy="0 0 0" xyz="0 0 0"/>
    </collision>
  </link>
  <gazebo reference="LeftForearm">
    <material>Gazebo/White</material>
  </gazebo>
  <link name="LeftWristPitch">
    <inertial>
      <mass value="0.1"/>
      <origin rpy="0 0 0" xyz="0 0 0"/>
      <inertia ixx="2.25083333333e-05" ixy="0.0" ixz="0.0" iyy="2.9175e-05" iyz="0.0" izz="8.33333333333e-06"/>
    </inertial>
    <visual>
      <geometry>
        <box size="0.03 0.01 0.051"/>
      </geometry>
      <origin rpy="0 0 0" xyz="0 0 0"/>
      <material name="Gray"/>
    </visual>
    <collision>
      <geometry>
        <box size="0.03 0.01 0.051"/>
      </geometry>
      <origin rpy="0 0 0" xyz="0 0 0"/>
    </collision>
  </link>
  <link name="LeftPalm">
    <inertial>
      <mass value="0.712"/>
      <origin rpy="0 0 0" xyz="0.0425 0 0"/>
      <inertia ixx="0.000679010666667" ixy="0.0" ixz="0.0" iyy="0.000514360666667" iyz="0.0" izz="0.00102201666667"/>
    </inertial>
    <visual>
      <geometry>
        <mesh filename="package://valkyrie_description/meshes/reduced_polygon_meshes/palm_Left.stl"/>
      </geometry>
      <origin rpy="0 0 0" xyz="0 0 0"/>
      <material name="Gold"/>
    </visual>
    <collision>
      <geometry>
        <mesh filename="package://valkyrie_description/meshes/reduced_polygon_meshes/palm_Left.stl"/>
      </geometry>
      <origin rpy="0 0 0" xyz="0 0 0"/>
    </collision>
  </link>
  <gazebo reference="LeftPalm">
    <material>Gazebo/Gold</material>
  </gazebo>
  <!-- AJ5 -->
  <joint name="LeftForearmYaw" type="revolute">
    <origin rpy="-1.57079632679 0 3.14159265359" xyz="0.0254 0 0"/>
    <axis xyz="0 0 1"/>
    <parent link="LeftElbowPitch"/>
    <child link="LeftForearm"/>
    <limit effort="26" lower="-2.35619448885" upper="2.35619448885" velocity="5"/>
    <controller_gains Kd="0" Kp="20000"/>
    <dynamics damping="1.0" friction="0.0"/>
  </joint>
  <gazebo reference="LeftForearmYaw">
    <provideFeedback>1</provideFeedback>
  </gazebo>
  <!-- AJ6 -->
  <joint name="LeftWristPitch" type="revolute">
    <origin rpy="-1.57079632679 0 -1.57079632679" xyz="0 0 0.287"/>
    <axis xyz="0 0 1"/>
    <parent link="LeftForearm"/>
    <child link="LeftWristPitch"/>
    <limit effort="14" lower="-0.8726646255" upper="0.6981317004" velocity="1"/>
    <controller_gains Kd="400" Kp="20000"/>
    <dynamics damping="1.0" friction="0.0"/>
  </joint>
  <gazebo reference="LeftWristPitch">
    <provideFeedback>1</provideFeedback>
  </gazebo>
  <!-- AJ7 -->
  <joint name="LeftWristRoll" type="revolute">
    <origin rpy="-1.57079632679 0 -1.57079632679" xyz="0 0 0"/>
    <axis xyz="0 0 1"/>
    <parent link="LeftWristPitch"/>
    <child link="LeftPalm"/>
    <limit effort="14" lower="-0.5235987753" upper="0.43633231275" velocity="1"/>
    <controller_gains Kd="400" Kp="20000"/>
    <dynamics damping="1.0" friction="0.0"/>
  </joint>
  <gazebo reference="LeftWristRoll">
    <provideFeedback>1</provideFeedback>
  </gazebo>
  <!-- <xacro:v1_arm_actuators name1="${leftarm_name1}" type1="${arm_type1}"
                            name2="${leftarm_name2}" type2="${arm_type2}"
                            name3="${leftarm_name3}" type3="${arm_type3}"
                            name4="${leftarm_name4}" type4="${arm_type4}"
                            name5="${leftarm_name5}" type5="${arm_type5}"
                            name6="${leftarm_name6}" type6="${arm_type6}"
                            name7="${leftarm_name7}" type7="${arm_type7}"/> -->
  <!-- ===== LEFT THUMB ===== -->
  <!-- LINKS -->
  <link name="LeftThumbPitch1">
    <inertial>
      <mass value="0.017"/>
      <origin rpy="0 0 0" xyz="0 0 0"/>
      <inertia ixx="2.83333333333e-07" ixy="0.0" ixz="0.0" iyy="2.83333333333e-07" iyz="0.0" izz="2.83333333333e-07"/>
    </inertial>
    <visual>
      <geometry>
        <mesh filename="package://valkyrie_description/meshes/reduced_polygon_meshes/tf1_Left.stl"/>
      </geometry>
      <origin rpy="0 0 0" xyz="0 0 0"/>
      <material name="Gold"/>
    </visual>
    <collision>
      <geometry>
        <mesh filename="package://valkyrie_description/meshes/reduced_polygon_meshes/tf1_Left.stl"/>
      </geometry>
      <origin rpy="0 0 0" xyz="0 0 0"/>
    </collision>
  </link>
  <gazebo reference="LeftThumbPitch1">
    <material>Gazebo/Gold</material>
  </gazebo>
  <link name="LeftThumbPitch2">
    <inertial>
      <mass value="0.02"/>
      <origin rpy="0 0 0" xyz="0.017 0 0"/>
      <inertia ixx="1.72833333333e-06" ixy="0.0" ixz="0.0" iyy="5.98666666667e-06" iyz="0.0" izz="5.46166666667e-06"/>
    </inertial>
    <visual>
      <geometry>
        <mesh filename="package://valkyrie_description/meshes/reduced_polygon_meshes/tf2.stl"/>
      </geometry>
      <origin rpy="0 0 0" xyz="0 0 0"/>
      <material name="Gold"/>
    </visual>
    <collision>
      <geometry>
        <mesh filename="package://valkyrie_description/meshes/reduced_polygon_meshes/tf2.stl"/>
      </geometry>
      <origin rpy="0 0 0" xyz="0 0 0"/>
    </collision>
  </link>
  <gazebo reference="LeftThumbPitch2">
    <material>Gazebo/Gold</material>
  </gazebo>
  <link name="LeftThumbPitch3">
    <inertial>
      <mass value="0.013"/>
      <origin rpy="0 0 0" xyz="0.011 0 0"/>
      <inertia ixx="7.07416666667e-07" ixy="0.0" ixz="0.0" iyy="1.77666666667e-06" iyz="0.0" izz="1.43541666667e-06"/>
    </inertial>
    <visual>
      <geometry>
        <mesh filename="package://valkyrie_description/meshes/reduced_polygon_meshes/tf3.stl"/>
      </geometry>
      <origin rpy="0 0 0" xyz="0 0 0"/>
      <material name="Gold"/>
    </visual>
    <collision>
      <geometry>
        <mesh filename="package://valkyrie_description/meshes/reduced_polygon_meshes/tf3.stl"/>
      </geometry>
      <origin rpy="0 0 0" xyz="0 0 0"/>
    </collision>
  </link>
  <gazebo reference="LeftThumbPitch3">
    <material>Gazebo/Gold</material>
  </gazebo>
  <link name="LeftThumbPitch4">
    <inertial>
      <mass value="0.006"/>
      <origin rpy="0 0 0" xyz="0.0086 0 0"/>
      <inertia ixx="2.525e-07" ixy="0.0" ixz="0.0" iyy="5.45e-07" iyz="0.0" izz="4.365e-07"/>
    </inertial>
    <visual>
      <geometry>
        <mesh filename="package://valkyrie_description/meshes/reduced_polygon_meshes/tf4.stl"/>
      </geometry>
      <origin rpy="0 0 0" xyz="0 0 0"/>
      <material name="Gold"/>
    </visual>
    <collision>
      <geometry>
        <mesh filename="package://valkyrie_description/meshes/reduced_polygon_meshes/tf4.stl"/>
      </geometry>
      <origin rpy="0 0 0" xyz="0 0 0"/>
    </collision>
  </link>
  <gazebo reference="LeftThumbPitch4">
    <material>Gazebo/Gold</material>
  </gazebo>
  <!-- TJ1 -->
  <joint name="LeftThumbRoll" type="fixed">
    <origin rpy="-1.57079632679 0 -1.34390352" xyz="0.00748367180673 -0.0324153432851 -0.005182"/>
    <axis xyz="0 0 1"/>
    <parent link="LeftPalm"/>
    <child link="LeftThumbPitch1"/>
  </joint>
  <!-- TJ2 -->
  <joint name="LeftThumbPitch1" type="fixed">
    <origin rpy="-1.57079632679 0 0" xyz="0.02286 0 0.025091"/>
    <axis xyz="0 0 1"/>
    <parent link="LeftThumbPitch1"/>
    <child link="LeftThumbPitch2"/>
  </joint>
  <!-- TJ3 -->
  <joint name="LeftThumbPitch2" type="fixed">
    <origin rpy="0 0 0" xyz="0.0381 0 0"/>
    <axis xyz="0 0 1"/>
    <parent link="LeftThumbPitch2"/>
    <child link="LeftThumbPitch3"/>
  </joint>
  <!-- TJ4 -->
  <joint name="LeftThumbPitch3" type="fixed">
    <origin rpy="0 0 0" xyz="0.02794 0 0"/>
    <axis xyz="0 0 1"/>
    <parent link="LeftThumbPitch3"/>
    <child link="LeftThumbPitch4"/>
  </joint>
  <!-- ===== LEFT PRIMARY FINGER ===== -->
  <!-- LINKS -->
  <link name="LeftIndexFingerPitch1">
    <inertial>
      <mass value="0.006"/>
      <origin rpy="0 0 0" xyz="-0.0048 0 0"/>
      <inertia ixx="4.225e-07" ixy="0.0" ixz="0.0" iyy="6.625e-07" iyz="0.0" izz="6.01e-07"/>
    </inertial>
    <visual>
      <geometry>
        <mesh filename="package://valkyrie_description/meshes/reduced_polygon_meshes/pf1.stl"/>
      </geometry>
      <origin rpy="0 0 0" xyz="0 0 0"/>
      <material name="Gold"/>
    </visual>
    <collision>
      <geometry>
        <mesh filename="package://valkyrie_description/meshes/reduced_polygon_meshes/pf1.stl"/>
      </geometry>
      <origin rpy="0 0 0" xyz="0 0 0"/>
    </collision>
  </link>
  <gazebo reference="LeftIndexFingerPitch1">
    <material>Gazebo/Gold</material>
  </gazebo>
  <link name="LeftIndexFingerPitch2">
    <inertial>
      <mass value="0.018"/>
      <origin rpy="0 0 0" xyz="0.0175 0 0"/>
      <inertia ixx="1.203e-06" ixy="0.0" ixz="0.0" iyy="5.0355e-06" iyz="0.0" izz="4.9155e-06"/>
    </inertial>
    <visual>
      <geometry>
        <mesh filename="package://valkyrie_description/meshes/reduced_polygon_meshes/pf2.stl"/>
      </geometry>
      <origin rpy="0 0 0" xyz="0 0 0"/>
      <material name="Gold"/>
    </visual>
    <collision>
      <geometry>
        <mesh filename="package://valkyrie_description/meshes/reduced_polygon_meshes/pf2.stl"/>
      </geometry>
      <origin rpy="0 0 0" xyz="0 0 0"/>
    </collision>
  </link>
  <gazebo reference="LeftIndexFingerPitch2">
    <material>Gazebo/Gold</material>
  </gazebo>
  <link name="LeftIndexFingerPitch3">
    <inertial>
      <mass value="0.01"/>
      <origin rpy="0 0 0" xyz="0.0108 -0.0003 0"/>
      <inertia ixx="3.81666666667e-07" ixy="0.0" ixz="0.0" iyy="1.20416666667e-06" iyz="0.0" izz="1.10416666667e-06"/>
    </inertial>
    <visual>
      <geometry>
        <mesh filename="package://valkyrie_description/meshes/reduced_polygon_meshes/pf3.stl"/>
      </geometry>
      <origin rpy="0 0 0" xyz="0 0 0"/>
      <material name="Gold"/>
    </visual>
    <collision>
      <geometry>
        <mesh filename="package://valkyrie_description/meshes/reduced_polygon_meshes/pf3.stl"/>
      </geometry>
      <origin rpy="0 0 0" xyz="0 0 0"/>
    </collision>
  </link>
  <gazebo reference="LeftIndexFingerPitch3">
    <material>Gazebo/Gold</material>
  </gazebo>
  <link name="LeftIndexFingerPitch4">
    <inertial>
      <mass value="0.005"/>
      <origin rpy="0 0 0" xyz="0.00857 -0.000696 0"/>
      <inertia ixx="1.5375e-07" ixy="0.0" ixz="0.0" iyy="3.975e-07" iyz="0.0" izz="3.6375e-07"/>
    </inertial>
    <visual>
      <geometry>
        <mesh filename="package://valkyrie_description/meshes/reduced_polygon_meshes/pf4.stl"/>
      </geometry>
      <origin rpy="0 0 0" xyz="0 0 0"/>
      <material name="Gold"/>
    </visual>
    <collision>
      <geometry>
        <mesh filename="package://valkyrie_description/meshes/reduced_polygon_meshes/pf4.stl"/>
      </geometry>
      <origin rpy="0 0 0" xyz="0 0 0"/>
    </collision>
  </link>
  <gazebo reference="LeftIndexFingerPitch4">
    <material>Gazebo/Gold</material>
  </gazebo>
  <!-- PFJ1 -->
  <joint name="LeftPrimaryMPYaw" type="fixed">
    <origin rpy="-3.14159265359 0 -0.366519143" xyz="0.0776738914821 -0.0298162134085 -0.00254"/>
    <axis xyz="0 0 1"/>
    <parent link="LeftPalm"/>
    <child link="LeftIndexFingerPitch1"/>
  </joint>
  <!-- PFJ2 -->
  <joint name="LeftPrimaryMPExtensor" type="fixed">
    <origin rpy="-1.57079632679 0 0.0568977336" xyz="0.0169724899301 0.000966739661347 0"/>
    <axis xyz="0 0 1"/>
    <parent link="LeftIndexFingerPitch1"/>
    <child link="LeftIndexFingerPitch2"/>
  </joint>
  <!-- PFJ3 -->
  <joint name="LeftPrimaryPIPExtensor" type="fixed">
    <origin rpy="0 0 0" xyz="0.0381 0 0"/>
    <axis xyz="0 0 1"/>
    <parent link="LeftIndexFingerPitch2"/>
    <child link="LeftIndexFingerPitch3"/>
  </joint>
  <!-- PFJ4 -->
  <joint name="LeftPrimaryDIPExtensor" type="fixed">
    <origin rpy="0 0 0" xyz="0.02286 0 0"/>
    <axis xyz="0 0 1"/>
    <parent link="LeftIndexFingerPitch3"/>
    <child link="LeftIndexFingerPitch4"/>
  </joint>
  <!-- ===== LEFT MIDDLE FINGER ===== -->
  <!-- LINKS -->
  <link name="LeftMiddleFingerPitch1">
    <inertial>
      <mass value="0.02"/>
      <origin rpy="0 0 0" xyz="0.017 0 0"/>
      <inertia ixx="1.72833333333e-06" ixy="0.0" ixz="0.0" iyy="5.98666666667e-06" iyz="0.0" izz="5.46166666667e-06"/>
    </inertial>
    <visual>
      <geometry>
        <mesh filename="package://valkyrie_description/meshes/reduced_polygon_meshes/sf1.stl"/>
      </geometry>
      <origin rpy="0 0 0" xyz="0 0 0"/>
      <material name="Gold"/>
    </visual>
    <collision>
      <geometry>
        <mesh filename="package://valkyrie_description/meshes/reduced_polygon_meshes/sf1.stl"/>
      </geometry>
      <origin rpy="0 0 0" xyz="0 0 0"/>
    </collision>
  </link>
  <gazebo reference="LeftMiddleFingerPitch1">
    <material>Gazebo/Gold</material>
  </gazebo>
  <link name="LeftMiddleFingerPitch2">
    <inertial>
      <mass value="0.011"/>
      <origin rpy="0 0 0" xyz="0.011 0 0"/>
      <inertia ixx="5.98583333333e-07" ixy="0.0" ixz="0.0" iyy="1.50333333333e-06" iyz="0.0" izz="1.21458333333e-06"/>
    </inertial>
    <visual>
      <geometry>
        <mesh filename="package://valkyrie_description/meshes/reduced_polygon_meshes/sf2_ssf3.stl"/>
      </geometry>
      <origin rpy="0 0 0" xyz="0 0 0"/>
      <material name="Gold"/>
    </visual>
    <collision>
      <geometry>
        <mesh filename="package://valkyrie_description/meshes/reduced_polygon_meshes/sf2_ssf3.stl"/>
      </geometry>
      <origin rpy="0 0 0" xyz="0 0 0"/>
    </collision>
  </link>
  <gazebo reference="LeftMiddleFingerPitch2">
    <material>Gazebo/Gold</material>
  </gazebo>
  <link name="LeftMiddleFingerPitch3">
    <inertial>
      <mass value="0.006"/>
      <origin rpy="0 0 0" xyz="0.0086 0 0"/>
      <inertia ixx="2.525e-07" ixy="0.0" ixz="0.0" iyy="5.45e-07" iyz="0.0" izz="4.365e-07"/>
    </inertial>
    <visual>
      <geometry>
        <mesh filename="package://valkyrie_description/meshes/reduced_polygon_meshes/sf3_ssf4.stl"/>
      </geometry>
      <origin rpy="0 0 0" xyz="0 0 0"/>
      <material name="Gold"/>
    </visual>
    <collision>
      <geometry>
        <mesh filename="package://valkyrie_description/meshes/reduced_polygon_meshes/sf3_ssf4.stl"/>
      </geometry>
      <origin rpy="0 0 0" xyz="0 0 0"/>
    </collision>
  </link>
  <gazebo reference="LeftMiddleFingerPitch3">
    <material>Gazebo/Gold</material>
  </gazebo>
  <!-- MFJ1 -->
  <joint name="LeftMiddleFingerPitch1" type="fixed">
    <origin rpy="1.57079632679 0 0" xyz="0.09767 0 -0.00254"/>
    <axis xyz="0 0 1"/>
    <parent link="LeftPalm"/>
    <child link="LeftMiddleFingerPitch1"/>
  </joint>
  <!-- MFJ2 -->
  <joint name="LeftMiddleFingerPitch2" type="fixed">
    <origin rpy="0 0 0" xyz="0.0381 0 0"/>
    <axis xyz="0 0 1"/>
    <parent link="LeftMiddleFingerPitch1"/>
    <child link="LeftMiddleFingerPitch2"/>
  </joint>
  <!-- MFJ3 -->
  <joint name="LeftMiddleFingerPitch3" type="fixed">
    <origin rpy="0 0 0" xyz="0.02286 0 0"/>
    <axis xyz="0 0 1"/>
    <parent link="LeftMiddleFingerPitch2"/>
    <child link="LeftMiddleFingerPitch3"/>
  </joint>
  <!-- ===== LEFT LITTLE FINGER ===== -->
  <!-- LINKS -->
  <link name="LeftPinkyPitch1">
    <inertial>
      <mass value="0.047"/>
      <origin rpy="0 0 0" xyz="0 0 0"/>
      <inertia ixx="7.83333333333e-07" ixy="0.0" ixz="0.0" iyy="7.83333333333e-07" iyz="0.0" izz="7.83333333333e-07"/>
    </inertial>
    <visual>
      <geometry>
        <mesh filename="package://valkyrie_description/meshes/reduced_polygon_meshes/ssf1_Left.stl"/>
      </geometry>
      <origin rpy="0 0 0" xyz="0 0 0"/>
      <material name="Gold"/>
    </visual>
    <collision>
      <geometry>
        <mesh filename="package://valkyrie_description/meshes/reduced_polygon_meshes/ssf1_Left.stl"/>
      </geometry>
      <origin rpy="0 0 0" xyz="0 0 0"/>
    </collision>
  </link>
  <gazebo reference="LeftPinkyPitch1">
    <material>Gazebo/Gold</material>
  </gazebo>
  <link name="LeftPinkyPitch2">
    <inertial>
      <mass value="0.02"/>
      <origin rpy="0 0 0" xyz="0 -0.017 -0.050169"/>
      <inertia ixx="5.98666666667e-06" ixy="0.0" ixz="0.0" iyy="1.72833333333e-06" iyz="0.0" izz="5.46166666667e-06"/>
    </inertial>
    <visual>
      <geometry>
        <mesh filename="package://valkyrie_description/meshes/reduced_polygon_meshes/ssf2_Left.stl"/>
      </geometry>
      <origin rpy="0 0 0" xyz="0 0 0"/>
      <material name="Gold"/>
    </visual>
    <collision>
      <geometry>
        <mesh filename="package://valkyrie_description/meshes/reduced_polygon_meshes/ssf2_Left.stl"/>
      </geometry>
      <origin rpy="0 0 0" xyz="0 0 0"/>
    </collision>
  </link>
  <gazebo reference="LeftPinkyPitch2">
    <material>Gazebo/Gold</material>
  </gazebo>
  <link name="LeftPinkyPitch3">
    <inertial>
      <mass value="0.011"/>
      <origin rpy="0 0 0" xyz="0.011 0 0"/>
      <inertia ixx="5.98583333333e-07" ixy="0.0" ixz="0.0" iyy="1.50333333333e-06" iyz="0.0" izz="1.21458333333e-06"/>
    </inertial>
    <visual>
      <geometry>
        <mesh filename="package://valkyrie_description/meshes/reduced_polygon_meshes/sf2_ssf3.stl"/>
      </geometry>
      <origin rpy="0 0 0" xyz="0 0 0"/>
      <material name="Gold"/>
    </visual>
    <collision>
      <geometry>
        <mesh filename="package://valkyrie_description/meshes/reduced_polygon_meshes/sf2_ssf3.stl"/>
      </geometry>
      <origin rpy="0 0 0" xyz="0 0 0"/>
    </collision>
  </link>
  <gazebo reference="LeftPinkyPitch3">
    <material>Gazebo/Gold</material>
  </gazebo>
  <!-- LFJ1 -->
  <joint name="LeftPinkyPitch1" type="fixed">
    <origin rpy="1.57079632679 0 0.690626785" xyz="0.0427072303336 0.0352928446888 0.007747"/>
    <axis xyz="0 0 1"/>
    <parent link="LeftPalm"/>
    <child link="LeftPinkyPitch1"/>
  </joint>
  <!-- LFJ2 -->
  <joint name="LeftPinkyPitch2" type="fixed">
    <origin rpy="-0.690626785 0 1.57079632679" xyz="0 -0.010287 0.071327"/>
    <axis xyz="0 0 1"/>
    <parent link="LeftPinkyPitch1"/>
    <child link="LeftPinkyPitch2"/>
  </joint>
  <!-- LFJ3 -->
  <joint name="LeftPinkyPitch3" type="fixed">
    <origin rpy="0 0 -1.57079632679" xyz="0 -0.0381 -0.050169"/>
    <axis xyz="0 0 1"/>
    <parent link="LeftPinkyPitch2"/>
    <child link="LeftPinkyPitch3"/>
  </joint>
  <!-- ===== RIGHT LEG ===== -->
  <link name="RightHipYaw">
    <inertial>
      <mass value="2.39"/>
      <origin rpy="0 0 0" xyz="0.001307857 0.021764163 0.038670367"/>
      <inertia ixx="0.0172609783333" ixy="0.0" ixz="0.0" iyy="0.0148661983333" iyz="0.0" izz="0.0112381783333"/>
    </inertial>
    <visual>
      <geometry>
        <mesh filename="package://valkyrie_description/meshes/reduced_polygon_meshes/lj1_Right.stl"/>
      </geometry>
      <origin rpy="0 0 0" xyz="0 0 0"/>
      <material name="Gold"/>
    </visual>
    <collision>
      <geometry>
        <mesh filename="package://valkyrie_description/meshes/reduced_polygon_meshes/lj1_Right.stl"/>
      </geometry>
      <origin rpy="0 0 0" xyz="0 0 0"/>
    </collision>
  </link>
  <gazebo reference="RightHipYaw">
    <material>Gazebo/Gold</material>
  </gazebo>
  <link name="RightHipRoll">
    <inertial>
      <mass value="5.95"/>
      <origin rpy="0 0 0" xyz="0.024260044 0.019261751 -0.0018458616"/>
      <inertia ixx="0.0244713583333" ixy="0.0" ixz="0.0" iyy="0.0160104583333" iyz="0.0" izz="0.0254788916667"/>
    </inertial>
    <visual>
      <geometry>
        <mesh filename="package://valkyrie_description/meshes/reduced_polygon_meshes/lj2.stl"/>
      </geometry>
      <origin rpy="0 0 0" xyz="0 0 0"/>
      <material name="White"/>
    </visual>
    <collision>
      <geometry>
        <mesh filename="package://valkyrie_description/meshes/reduced_polygon_meshes/lj2.stl"/>
      </geometry>
      <origin rpy="0 0 0" xyz="0 0 0"/>
    </collision>
  </link>
  <gazebo reference="RightHipRoll">
    <material>Gazebo/White</material>
  </gazebo>
  <link name="RightHipPitch">
    <inertial>
      <mass value="10.3"/>
      <origin rpy="0 0 0" xyz="0.22 0 -0.05"/>
      <inertia ixx="0.0799327000001" ixy="0.0" ixz="0.0" iyy="0.293068" iyz="0.0" izz="0.314117"/>
    </inertial>
    <visual>
      <geometry>
        <mesh filename="package://valkyrie_description/meshes/reduced_polygon_meshes/lj3_Right.stl"/>
      </geometry>
      <origin rpy="0 0 0" xyz="0 0 0"/>
      <material name="White"/>
    </visual>
    <collision>
      <geometry>
        <mesh filename="package://valkyrie_description/meshes/reduced_polygon_meshes/lj3_Right.stl"/>
      </geometry>
      <origin rpy="0 0 0" xyz="0 0 0"/>
    </collision>
  </link>
  <gazebo reference="RightHipPitch">
    <material>Gazebo/White</material>
  </gazebo>
  <link name="RightKneePitch">
    <inertial>
      <mass value="7.4"/>
      <origin rpy="0 0 0" xyz="0.185 0.0 0.045"/>
      <inertia ixx="0.0514292" ixy="0.0" ixz="0.0" iyy="0.148318" iyz="0.0" izz="0.147657"/>
    </inertial>
    <visual>
      <geometry>
        <mesh filename="package://valkyrie_description/meshes/reduced_polygon_meshes/lj4_Right.stl"/>
      </geometry>
      <origin rpy="0 0 0" xyz="0 0 0"/>
      <material name="White"/>
    </visual>
    <collision>
      <geometry>
        <mesh filename="package://valkyrie_description/meshes/reduced_polygon_meshes/lj4_Right.stl"/>
      </geometry>
      <origin rpy="0 0 0" xyz="0 0 0"/>
    </collision>
  </link>
  <gazebo reference="RightKneePitch">
    <material>Gazebo/White</material>
  </gazebo>
  <link name="RightAnkleRoll">
    <inertial>
      <mass value="0.395"/>
      <origin rpy="0 0 0" xyz="0.0057963439 0.0020433211 9.0424431e-05"/>
      <inertia ixx="0.000210699583333" ixy="0.0" ixz="0.0" iyy="5.64191666667e-05" iyz="0.0" izz="0.000225972916667"/>
    </inertial>
    <visual>
      <geometry>
        <box size="0.033 0.076 0.025"/>
      </geometry>
      <origin rpy="0 0 0" xyz="0.0057963439 0.0020433211 9.0424431e-05"/>
      <material name="Gray"/>
    </visual>
    <collision>
      <geometry>
        <box size="0.033 0.076 0.025"/>
      </geometry>
      <origin rpy="0 0 0" xyz="0.0057963439 0.0020433211 9.0424431e-05"/>
    </collision>
  </link>
  <link name="RightFoot">
    <inertial>
      <mass value="1.888"/>
      <origin rpy="0 0.13 0" xyz="0.048263578 -3.1591183e-05 0.077849126"/>
      <inertia ixx="0.0167377493333" ixy="0.0" ixz="0.0" iyy="0.0152179093333" iyz="0.0" izz="0.00363565866667"/>
    </inertial>
    <visual>
      <geometry>
        <mesh filename="package://valkyrie_description/meshes/reduced_polygon_meshes/lj6_Right.stl"/>
      </geometry>
      <origin rpy="0 0.13 0" xyz="0 0 0"/>
      <material name="White"/>
    </visual>
    <collision>
      <origin rpy="0 0.13 0" xyz="0.048263578 -3.1591183e-05 0.077849126"/>
      <geometry>
        <box size="0.082 0.128 0.3"/>
      </geometry>
    </collision>
  </link>
  <gazebo reference="RightFoot">
    <material>Gazebo/White</material>
  </gazebo>
  <gazebo reference="RightFoot">
    <kp>100000.0</kp>
    <kd>1000.0</kd>
    <mu1>1.5</mu1>
    <mu2>1.5</mu2>
    <fdir1>0 0 1</fdir1>
    <maxVel>1.0</maxVel>
    <minDepth>0.00</minDepth>
  </gazebo>
  <!-- LJ1 -->
  <joint name="RightHipYaw" type="revolute">
    <origin rpy="0.0 0 -1.57079632679" xyz="0 -0.1016 -0.183"/>
    <axis xyz="0 0 1"/>
    <parent link="Pelvis"/>
    <child link="RightHipYaw"/>
    <limit effort="190" lower="-0.5235987753" upper="0.169296937347" velocity="5.89"/>
    <controller_gains Kd="500" Kp="15000"/>
    <dynamics damping="1.0" friction="0.0"/>
  </joint>
  <gazebo reference="RightHipYaw">
    <provideFeedback>1</provideFeedback>
  </gazebo>
  <joint name="RightHipRoll" type="revolute">
    <origin rpy="-1.57079632679 0 0" xyz="0 0 0"/>
    <axis xyz="0 0 1"/>
    <parent link="RightHipYaw"/>
    <child link="RightHipRoll"/>
    <limit effort="350" lower="-0.5235987753" upper="0.26179938765" velocity="7"/>
    <controller_gains Kd="500" Kp="15000"/>
    <dynamics damping="1.0" friction="0.0"/>
  </joint>
  <gazebo reference="RightHipRoll">
    <provideFeedback>1</provideFeedback>
  </gazebo>
  <joint name="RightHipPitch" type="revolute">
    <origin rpy="-1.57079632679 0 1.57079632679" xyz="0 0.061 0"/>
    <axis xyz="0 0 1"/>
    <parent link="RightHipRoll"/>
    <child link="RightHipPitch"/>
    <limit effort="350" lower="-2.35619448885" upper="1.71042266598" velocity="6.11"/>
    <controller_gains Kd="500" Kp="15000"/>
    <dynamics damping="1.0" friction="0.0"/>
  </joint>
  <gazebo reference="RightHipPitch">
    <provideFeedback>1</provideFeedback>
  </gazebo>
  <joint name="RightKneePitch" type="revolute">
    <origin rpy="3.14159265359 0 0" xyz="0.431 0 -0.0374"/>
    <axis xyz="0 0 1"/>
    <parent link="RightHipPitch"/>
    <child link="RightKneePitch"/>
    <limit effort="350" lower="-1.90240888359" upper="0.218166156375" velocity="6.11"/>
    <controller_gains Kd="500" Kp="15000"/>
    <dynamics damping="1.0" friction="0.0"/>
  </joint>
  <gazebo reference="RightKneePitch">
    <provideFeedback>1</provideFeedback>
  </gazebo>
  <!--     <xacro:fixed_joint jointName="${prefix}MedialAnkleActuatorOffset"
                       parent="${LJ4_Distal_Link_Box}" child="${LJ4_Distal_Link_Cylinder1}"
                       origin_xyz="0 0 0"
                       origin_rpy="0 0 0"/><controller_gains Kp="15000" Kd="2<controller_gains Kp="15000" Kd="500"/>
    <xacro:fixed_joint jointName="${prefix}LateralAnkleActuatorOffset"
                       parent="${LJ4_Distal_Link_Box}" child="${LJ4_Distal_Link_Cylinder2}"
                       origin_xyz="0 0 0"
                       origin_rpy="0 0 0"/> -->
  <joint name="RightAnklePitch" type="revolute">
    <origin rpy="3.14159265359 0 0" xyz="0.406 0 0"/>
    <axis xyz="0 0 1"/>
    <parent link="RightKneePitch"/>
    <child link="RightAnkleRoll"/>
    <limit effort="205" lower="-0.8726646255" upper="0.8726646255" velocity="11"/>
    <controller_gains Kd="400" Kp="15000"/>
    <dynamics damping="1.0" friction="0.0"/>
  </joint>
  <gazebo reference="RightAnklePitch">
    <provideFeedback>1</provideFeedback>
  </gazebo>
  <joint name="RightAnkleRoll" type="revolute">
    <origin rpy="1.57079632679 0 -0.13" xyz="0.0127 0 0"/>
    <axis xyz="0 0 1"/>
    <parent link="RightAnkleRoll"/>
    <child link="RightFoot"/>
    <limit effort="205" lower="-0.3490658502" upper="0.3490658502" velocity="11"/>
    <controller_gains Kd="400" Kp="15000"/>
    <dynamics damping="0.3" friction="0.0"/>
  </joint>
  <gazebo reference="RightAnkleRoll">
    <provideFeedback>1</provideFeedback>
  </gazebo>
  <xacro:make_foot_joints leg_root_link="Pelvis" prefix="Right" reflect="1"/>
  <!-- <xacro:v1_leg_actuators name1="${rightleg_name1}" type1="${leg_type1}"
                            name2="${rightleg_name2}" type2="${leg_type2}"
                            name3="${rightleg_name3}" type3="${leg_type3}"
                            name4="${rightleg_name4}" type4="${leg_type4}"
                            name5="${rightleg_name5}" type5="${leg_type5}"
                            name6="${rightleg_name6}" type6="${leg_type6}"/> -->
  <!-- <xacro:v1_leg_transmissions prefix="Right" reflect="1"
                                               actuator1="${rightleg_name1}"
                                               actuator2="${rightleg_name2}"
                                               actuator3="${rightleg_name3}"
                                               actuator4="${rightleg_name4}"
                                               actuator5="${rightleg_name5}"
                                               actuator6="${rightleg_name6}" /> -->
  <!-- <xacro:v1_leg_modes prefix="Right" actuator1="${rightleg_name1}"
                                       actuator2="${rightleg_name2}"
                                       actuator3="${rightleg_name3}"
                                       actuator4="${rightleg_name4}"
                                       actuator5="${rightleg_name5}"
                                       actuator6="${rightleg_name6}" /> -->
  <!-- <xacro:v1_leg_sensors prefix="Right" reflect="1" /> -->
  <!-- <xacro:v1_hw_sensors prefix="Right" hermes_node="${rightleg_hermes}" atidaq_node="${rightleg_ati}" mpu6000_node="${rightleg_mpu2000}" cop_node="${rightleg_cop}"/> -->
  <!-- ===== LEFT LEG ===== -->
  <link name="LeftHipYaw">
    <inertial>
      <mass value="2.39"/>
      <origin rpy="0 0 0" xyz="0.001307857 0.021764163 -0.038670367"/>
      <inertia ixx="0.0172609783333" ixy="0.0" ixz="0.0" iyy="0.0148661983333" iyz="0.0" izz="0.0112381783333"/>
    </inertial>
    <visual>
      <geometry>
        <mesh filename="package://valkyrie_description/meshes/reduced_polygon_meshes/lj1_Left.stl"/>
      </geometry>
      <origin rpy="0 0 0" xyz="0 0 0"/>
      <material name="Gold"/>
    </visual>
    <collision>
      <geometry>
        <mesh filename="package://valkyrie_description/meshes/reduced_polygon_meshes/lj1_Left.stl"/>
      </geometry>
      <origin rpy="0 0 0" xyz="0 0 0"/>
    </collision>
  </link>
  <gazebo reference="LeftHipYaw">
    <material>Gazebo/Gold</material>
  </gazebo>
  <link name="LeftHipRoll">
    <inertial>
      <mass value="5.95"/>
      <origin rpy="0 0 0" xyz="0.024260044 0.019261751 -0.0018458616"/>
      <inertia ixx="0.0244713583333" ixy="0.0" ixz="0.0" iyy="0.0160104583333" iyz="0.0" izz="0.0254788916667"/>
    </inertial>
    <visual>
      <geometry>
        <mesh filename="package://valkyrie_description/meshes/reduced_polygon_meshes/lj2.stl"/>
      </geometry>
      <origin rpy="0 0 0" xyz="0 0 0"/>
      <material name="White"/>
    </visual>
    <collision>
      <geometry>
        <mesh filename="package://valkyrie_description/meshes/reduced_polygon_meshes/lj2.stl"/>
      </geometry>
      <origin rpy="0 0 0" xyz="0 0 0"/>
    </collision>
  </link>
  <gazebo reference="LeftHipRoll">
    <material>Gazebo/White</material>
  </gazebo>
  <link name="LeftHipPitch">
    <inertial>
      <mass value="10.3"/>
      <origin rpy="0 0 0" xyz="0.22 0 0.05"/>
      <inertia ixx="0.0799327000001" ixy="0.0" ixz="0.0" iyy="0.293068" iyz="0.0" izz="0.314117"/>
    </inertial>
    <visual>
      <geometry>
        <mesh filename="package://valkyrie_description/meshes/reduced_polygon_meshes/lj3_Left.stl"/>
      </geometry>
      <origin rpy="0 0 0" xyz="0 0 0"/>
      <material name="White"/>
    </visual>
    <collision>
      <geometry>
        <mesh filename="package://valkyrie_description/meshes/reduced_polygon_meshes/lj3_Left.stl"/>
      </geometry>
      <origin rpy="0 0 0" xyz="0 0 0"/>
    </collision>
  </link>
  <gazebo reference="LeftHipPitch">
    <material>Gazebo/White</material>
  </gazebo>
  <link name="LeftKneePitch">
    <inertial>
      <mass value="7.4"/>
      <origin rpy="0 0 0" xyz="0.185 0.0 -0.045"/>
      <inertia ixx="0.0514292" ixy="0.0" ixz="0.0" iyy="0.148318" iyz="0.0" izz="0.147657"/>
    </inertial>
    <visual>
      <geometry>
        <mesh filename="package://valkyrie_description/meshes/reduced_polygon_meshes/lj4_Left.stl"/>
      </geometry>
      <origin rpy="0 0 0" xyz="0 0 0"/>
      <material name="White"/>
    </visual>
    <collision>
      <geometry>
        <mesh filename="package://valkyrie_description/meshes/reduced_polygon_meshes/lj4_Left.stl"/>
      </geometry>
      <origin rpy="0 0 0" xyz="0 0 0"/>
    </collision>
  </link>
  <gazebo reference="LeftKneePitch">
    <material>Gazebo/White</material>
  </gazebo>
  <link name="LeftAnkleRoll">
    <inertial>
      <mass value="0.395"/>
      <origin rpy="0 0 0" xyz="0.0057963439 0.0020433211 9.0424431e-05"/>
      <inertia ixx="0.000210699583333" ixy="0.0" ixz="0.0" iyy="5.64191666667e-05" iyz="0.0" izz="0.000225972916667"/>
    </inertial>
    <visual>
      <geometry>
        <box size="0.033 0.076 0.025"/>
      </geometry>
      <origin rpy="0 0 0" xyz="0.0057963439 0.0020433211 9.0424431e-05"/>
      <material name="Gray"/>
    </visual>
    <collision>
      <geometry>
        <box size="0.033 0.076 0.025"/>
      </geometry>
      <origin rpy="0 0 0" xyz="0.0057963439 0.0020433211 9.0424431e-05"/>
    </collision>
  </link>
  <link name="LeftFoot">
    <inertial>
      <mass value="1.888"/>
      <origin rpy="0 -0.13 0" xyz="0.048263578 -3.1591183e-05 -0.077849126"/>
      <inertia ixx="0.0167377493333" ixy="0.0" ixz="0.0" iyy="0.0152179093333" iyz="0.0" izz="0.00363565866667"/>
    </inertial>
    <visual>
      <geometry>
        <mesh filename="package://valkyrie_description/meshes/reduced_polygon_meshes/lj6_Left.stl"/>
      </geometry>
      <origin rpy="0 -0.13 0" xyz="0 0 0"/>
      <material name="White"/>
    </visual>
    <collision>
      <origin rpy="0 -0.13 0" xyz="0.048263578 -3.1591183e-05 -0.077849126"/>
      <geometry>
        <box size="0.082 0.128 0.3"/>
      </geometry>
    </collision>
  </link>
  <gazebo reference="LeftFoot">
    <material>Gazebo/White</material>
  </gazebo>
  <gazebo reference="LeftFoot">
    <kp>100000.0</kp>
    <kd>1000.0</kd>
    <mu1>1.5</mu1>
    <mu2>1.5</mu2>
    <fdir1>0 0 1</fdir1>
    <maxVel>1.0</maxVel>
    <minDepth>0.00</minDepth>
  </gazebo>
  <!-- LJ1 -->
  <joint name="LeftHipYaw" type="revolute">
    <origin rpy="3.14159265359 0 1.57079632679" xyz="0 0.1016 -0.183"/>
    <axis xyz="0 0 1"/>
    <parent link="Pelvis"/>
    <child link="LeftHipYaw"/>
    <limit effort="190" lower="-0.5235987753" upper="0.169296937347" velocity="5.89"/>
    <controller_gains Kd="500" Kp="15000"/>
    <dynamics damping="1.0" friction="0.0"/>
  </joint>
  <gazebo reference="LeftHipYaw">
    <provideFeedback>1</provideFeedback>
  </gazebo>
  <joint name="LeftHipRoll" type="revolute">
    <origin rpy="1.57079632679 0 0" xyz="0 0 0"/>
    <axis xyz="0 0 1"/>
    <parent link="LeftHipYaw"/>
    <child link="LeftHipRoll"/>
    <limit effort="350" lower="-0.5235987753" upper="0.26179938765" velocity="7"/>
    <controller_gains Kd="500" Kp="15000"/>
    <dynamics damping="1.0" friction="0.0"/>
  </joint>
  <gazebo reference="LeftHipRoll">
    <provideFeedback>1</provideFeedback>
  </gazebo>
  <joint name="LeftHipPitch" type="revolute">
    <origin rpy="1.57079632679 0 1.57079632679" xyz="0 0.061 0"/>
    <axis xyz="0 0 1"/>
    <parent link="LeftHipRoll"/>
    <child link="LeftHipPitch"/>
    <limit effort="350" lower="-2.35619448885" upper="1.71042266598" velocity="6.11"/>
    <controller_gains Kd="500" Kp="15000"/>
    <dynamics damping="1.0" friction="0.0"/>
  </joint>
  <gazebo reference="LeftHipPitch">
    <provideFeedback>1</provideFeedback>
  </gazebo>
  <joint name="LeftKneePitch" type="revolute">
    <origin rpy="3.14159265359 0 0" xyz="0.431 0 0.0374"/>
    <axis xyz="0 0 1"/>
    <parent link="LeftHipPitch"/>
    <child link="LeftKneePitch"/>
    <limit effort="350" lower="-1.90240888359" upper="0.218166156375" velocity="6.11"/>
    <controller_gains Kd="500" Kp="15000"/>
    <dynamics damping="1.0" friction="0.0"/>
  </joint>
  <gazebo reference="LeftKneePitch">
    <provideFeedback>1</provideFeedback>
  </gazebo>
  <!--     <xacro:fixed_joint jointName="${prefix}MedialAnkleActuatorOffset"
                       parent="${LJ4_Distal_Link_Box}" child="${LJ4_Distal_Link_Cylinder1}"
                       origin_xyz="0 0 0"
                       origin_rpy="0 0 0"/><controller_gains Kp="15000" Kd="2<controller_gains Kp="15000" Kd="500"/>
    <xacro:fixed_joint jointName="${prefix}LateralAnkleActuatorOffset"
                       parent="${LJ4_Distal_Link_Box}" child="${LJ4_Distal_Link_Cylinder2}"
                       origin_xyz="0 0 0"
                       origin_rpy="0 0 0"/> -->
  <joint name="LeftAnklePitch" type="revolute">
    <origin rpy="3.14159265359 0 0" xyz="0.406 0 0"/>
    <axis xyz="0 0 1"/>
    <parent link="LeftKneePitch"/>
    <child link="LeftAnkleRoll"/>
    <limit effort="205" lower="-0.8726646255" upper="0.8726646255" velocity="11"/>
    <controller_gains Kd="400" Kp="15000"/>
    <dynamics damping="1.0" friction="0.0"/>
  </joint>
  <gazebo reference="LeftAnklePitch">
    <provideFeedback>1</provideFeedback>
  </gazebo>
  <joint name="LeftAnkleRoll" type="revolute">
    <origin rpy="-1.57079632679 0 -0.13" xyz="0.0127 0 0"/>
    <axis xyz="0 0 1"/>
    <parent link="LeftAnkleRoll"/>
    <child link="LeftFoot"/>
    <limit effort="205" lower="-0.3490658502" upper="0.3490658502" velocity="11"/>
    <controller_gains Kd="400" Kp="15000"/>
    <dynamics damping="0.3" friction="0.0"/>
  </joint>
  <gazebo reference="LeftAnkleRoll">
    <provideFeedback>1</provideFeedback>
  </gazebo>
  <xacro:make_foot_joints leg_root_link="Pelvis" prefix="Left" reflect="-1"/>
  <!-- <xacro:v1_leg_actuators name1="${leftleg_name1}" type1="${leg_type1}"
                            name2="${leftleg_name2}" type2="${leg_type2}"
                            name3="${leftleg_name3}" type3="${leg_type3}"
                            name4="${leftleg_name4}" type4="${leg_type4}"
                            name5="${leftleg_name5}" type5="${leg_type5}"
                            name6="${leftleg_name6}" type6="${leg_type6}"/> -->
</robot>
