<?xml version="1.0" ?>
<!-- =================================================================================== -->
<!-- |    This document was autogenerated by xacro from xacro/V1.xacro                 | -->
<!-- |    EDITING THIS FILE BY HAND IS NOT RECOMMENDED                                 | -->
<!-- =================================================================================== -->
<robot name="valkyrie" xmlns:xacro="http://www.ros.org/wiki/xacro">
  <!-- ======================================================= -->
  <!-- DO NOT MODIFY URDF BY HAND! YOU ARE A FOOL IF YOU DO! -->
  <!-- ======================================================= -->
  <!-- <xacro:include filename="$(find common_xacro)/xacro/mode_setup_hw.xacro" /> -->
  <!-- <xacro:include filename="$(find valkyrie_description)/robots/valkyrie_A/xacro/common/hw_actuator_types.xacro"/> -->
  <!-- ======================================================= -->
  <!-- DO NOT MODIFY URDF BY HAND! YOU ARE A FOOL IF YOU DO! -->
  <!-- ======================================================= -->
  <!-- May 2015: However zero mass/inertials links are still useful. (And removed with gz sdf)
  This macro here was added to allow fixed links to have (almost) no effect on the output compound
  sdf mass and inertia
  -->
  <material name="White">
    <color rgba="1.0 1.0 1.0 1.0"/>
  </material>
  <material name="Gold">
    <color rgba="1.0 0.67 0 1.0"/>
  </material>
  <material name="Gray">
    <color rgba="0.5 0.5 0.5 1.0"/>
  </material>
  <material name="Pink">
    <color rgba="0.8 0 0.45 1.0"/>
  </material>
  <!-- Properties -->
  <!--
  Microstrain
  -->
  <!-- May 2015: mass made tiny to match with output inertias to IHMC's values -->
  <!--  <xacro:property name="MicrostrainMass" value="0.018"/> -->
  <!--
  Vritual sensor frame
  -->
  <!-- 
  FLEA3: FL3-U3-13Y3M-C & FL3-U3-13E4C-C
    Specs from:
    http://ww2.ptgrey.com/USB3/Flea3
  -->
  <!-- <xacro:property name="FleaFrameRate" value="30"/> -->
  <!-- Actuators -->
  <!-- Transmissions -->
  <!-- Modes -->
  <!-- Battery -->
  <!-- TODO: Get better numbers for battery center from mech team -->
  <!-- <xacro:fixed_joint jointName="battery_offset"
                     parent="/v1/trunk" child="/v1/battery"
                     origin_xyz=".3 0 -0.2"
                     origin_rpy="0 0 0" /> -->
  <!-- TODO: Get better approximation for battery -->
  <!-- <xacro:link_box name="/v1/battery"
                  width=".2" height="0.2" depth="0.2" mass="15.0"
                  origin_rpy="0 0 0"
                  origin_xyz="0 0 0" /> -->
  <!-- Properties -->
  <!-- 
  CAMBOARD
    Specs from:
    http://www.pmdtec.com/products_services/reference_design.php
  -->
  <!-- 
  FLEA3: FL3-U3-13Y3M-C & FL3-U3-13E4C-C
    Specs from:
    http://ww2.ptgrey.com/USB3/Flea3
  -->
  <!-- <xacro:property name="FleaFrameRate" value="30"/> -->
  <!-- 
  IBEO LUX 8L
    Specs from:
    http://www.ibeo-as.com/index.php/en/sensorsv
  -->
  <!-- <xacro:include filename="$(find valkyrie_description)/models/V1/xacro/sensors/asus.xacro"/> -->
  <!-- Link properties. -->
  <!-- Sensors -->
  <!-- Actuators -->
  <!-- Transmissions -->
  <!-- Modes -->
  <!-- 
  CAMBOARD
    Specs from:
    http://www.pmdtec.com/products_services/reference_design.php
  -->
  <!-- Link properties. -->
  <!-- Sensors -->
  <!-- Why is this not symmetric?? -->
  <!-- Actuators -->
  <!-- Transmissions -->
  <!-- Modes -->
  <!-- 
  CAMBOARD
    Specs from:
    http://www.pmdtec.com/products_services/reference_design.php
  -->
  <!-- 
  HOKUYO
    Specs from:
    http://bender.jsc.nasa.gov/confluence/download/attachments/13074784/UTM-30LX-EW_Specification.pdf?version=1&modificationDate=1354299754000&api=v2 
  -->
  <!-- <xacro:property name="HokuyoScanAngle" value="${270 * DEG2RAD}"/> -->
  <!-- <xacro:property name="HokuyoAngularResolution" value="${0.25 * DEG2RAD}"/> -->
  <!-- Using worse case (10-30m) standard deviation -->
  <!-- Link properties. -->
  <!-- Sensors -->
  <!-- Actuators -->
  <!-- Transmissions -->
  <!-- Note that the transmission requires the convention of [roll, pitch] and [inner_shin_motor, outer_shin_motor] -->
  <!-- Modes -->
  <!-- Link properties. -->
  <!-- Actuators -->
  <!-- Transmissions -->
  <!-- Modes -->
  <!-- Complete interface -->
  <!-- /v1/${prefix}Palm -->
  <!-- Link properties. -->
  <!-- Actuators -->
  <!-- Transmissions -->
  <!-- Modes -->
  <!-- Complete interface -->
  <!-- Simple interface -->
  <!-- Link properties. -->
  <!-- Actuators -->
  <!-- Transmissions -->
  <!-- Modes -->
  <!-- Complete interface -->
  <!-- Simple interface -->
  <!-- Link properties. -->
  <!-- Actuators -->
  <!-- Transmissions -->
  <!-- Modes -->
  <!-- Complete interface -->
  <!-- Simple interface -->
  <!-- 	<xacro:macro name="make_thumb_interface" params="prefix channel">
       <xacro:v1_thumb_actuators channel="${channel}" />
       <xacro:v1_thumb_transmissions prefix="${prefix}" channel="${channel}" />
       <xacro:v1_thumb_modes prefix="${prefix}" channel="${channel}" />
       </xacro:macro>
  -->
  <!-- 	<xacro:macro name="make_primary_finger_interface" params="prefix channel">
       <xacro:v1_primary_finger_actuators channel="${channel}" />
       <xacro:v1_primary_finger_transmissions prefix="${prefix}" channel="${channel}" />
       <xacro:v1_primary_finger_modes prefix="${prefix}" channel="${channel}" />
       </xacro:macro> -->
  <!-- 	<xacro:macro name="make_middle_finger_interface" params="prefix channel">
       <xacro:v1_middle_finger_actuators channel="${channel}" />
       <xacro:v1_middle_finger_transmissions prefix="${prefix}" channel="${channel}" />
       <xacro:v1_middle_finger_modes prefix="${prefix}" channel="${channel}" />
       </xacro:macro>

<xacro:macro name="make_little_finger_interface" params="prefix channel">
<xacro:v1_little_finger_actuators channel="${channel}" />
<xacro:v1_little_finger_transmissions prefix="${prefix}" channel="${channel}" />
<xacro:v1_little_finger_modes prefix="${prefix}" channel="${channel}" />
</xacro:macro> -->
  <!-- ===== GAZEBO PLUGINS ===== -->
  <gazebo>
    <plugin filename="libSMInterface.so" name="SharedMemoryInterface">
      <updateRate>1000</updateRate>
      <robotDescriptionParam>/robot_description_sim</robotDescriptionParam>
    </plugin>
    <plugin filename="libJointStatePublisher.so" name="JointStatePublisher">
      <updateRate>1000.0</updateRate>
      <topicName>joint_states_sim</topicName>
    </plugin>
    <plugin filename="libPinPlugin.so" name="PinPlugin">
      <node>/pin_plugin</node>
    </plugin>
  </gazebo>
  <!-- ===== PUBLISH ODOMETRY DATA ==== -->
  <!-- Gazebo ROS P3D xacro -->
  <gazebo>
    <plugin filename="libgazebo_ros_p3d.so" name="pos_plugin_ros">
      <alwaysOn>true</alwaysOn>
      <updateRate>1000.0</updateRate>
      <bodyName>/v1/Trunk</bodyName>
      <topicName>/v1/pose</topicName>
      <frameName>world</frameName>
      <rpyOffset>0 0 0</rpyOffset>
      <xyzOffset>0 0 0</xyzOffset>
    </plugin>
  </gazebo>
  <!-- ===== PUBLISH ODOMETRY DATA ==== -->
  <!-- Gazebo ROS P3D xacro -->
  <gazebo>
    <plugin filename="libgazebo_ros_p3d.so" name="pos_plugin_ros">
      <alwaysOn>true</alwaysOn>
      <updateRate>1000.0</updateRate>
      <bodyName>/v1/Pelvis</bodyName>
      <topicName>/v1/Pelvis/pose</topicName>
      <frameName>world</frameName>
      <rpyOffset>0 0 0</rpyOffset>
      <xyzOffset>0 0 0</xyzOffset>
    </plugin>
  </gazebo>
  <!-- ===== PELVIS ===== -->
  <link name="/v1/Pelvis">
    <inertial>
      <mass value="6.986"/>
      <origin rpy="0 0 0" xyz="0.000733954 -0.000895362 -0.0702552"/>
      <inertia ixx="0.147962" ixy="0.0" ixz="0.0" iyy="0.125353" iyz="0.0" izz="0.115537"/>
    </inertial>
    <visual>
      <geometry>
        <mesh filename="package://V1/meshes/reduced_polygon_meshes/pelvis.stl"/>
        <!-- <box size="${width} ${height} ${depth}"/> -->
      </geometry>
      <origin rpy="0 0 0" xyz="0 0 0"/>
      <!-- <origin rpy="${origin_rpy}" xyz="${origin_xyz}"/> -->
      <material name="White"/>
    </visual>
    <collision>
      <geometry>
        <mesh filename="package://V1/meshes/reduced_polygon_meshes/pelvis.stl"/>
      </geometry>
      <origin rpy="0 0 0" xyz="0 0 0"/>
    </collision>
  </link>
  <gazebo reference="/v1/Pelvis">
    <material>Gazebo/White</material>
  </gazebo>
  <!-- <xacro:v1_pelvis_sensors/> -->
  <!-- ===== TRUNK ===== -->
  <link name="/v1/Trunk">
    <inertial>
      <mass value="42.6"/>
      <origin rpy="0 0 0" xyz="0.219 0.03 -0.104"/>
      <inertia ixx="1.19515" ixy="0.0" ixz="0.0" iyy="1.43685" iyz="0.0" izz="1.36738"/>
    </inertial>
    <visual>
      <geometry>
        <mesh filename="package://V1/meshes/reduced_polygon_meshes/wj3.stl"/>
        <!-- <box size="${width} ${height} ${depth}"/> -->
      </geometry>
      <origin rpy="0 0 0" xyz="0 0 0"/>
      <!-- <origin rpy="${origin_rpy}" xyz="${origin_xyz}"/> -->
      <material name="White"/>
    </visual>
    <collision>
      <geometry>
        <mesh filename="package://V1/meshes/reduced_polygon_meshes/wj3.stl"/>
      </geometry>
      <origin rpy="0 0 0" xyz="0 0 0"/>
    </collision>
  </link>
  <gazebo reference="/v1/Trunk">
    <material>Gazebo/White</material>
  </gazebo>
  <!-- Links -->
  <link name="/v1/WaistRotator">
    <!-- Virtual Link -->
    <inertial>
      <mass value="0.1"/>
      <origin rpy="0 0 0" xyz="0 0 0"/>
      <inertia ixx="8.33333333333e-05" ixy="0.0" ixz="0.0" iyy="8.33333333333e-05" iyz="0.0" izz="0.000125"/>
    </inertial>
  </link>
  <link name="/v1/WaistExtensor">
    <!-- Virtual Link -->
    <inertial>
      <mass value="0.1"/>
      <origin rpy="0 0 0" xyz="0 0 0"/>
      <inertia ixx="8.33333333333e-05" ixy="0.0" ixz="0.0" iyy="8.33333333333e-05" iyz="0.0" izz="0.000125"/>
    </inertial>
  </link>
  <!-- WJ1 -->
  <joint name="WaistRotator" type="revolute">
    <origin rpy="0 0 0" xyz="0 0 0"/>
    <axis xyz="0 0 1"/>
    <parent link="/v1/Pelvis"/>
    <child link="/v1/WaistRotator"/>
    <limit effort="190" lower="-0.6981317004" upper="0.6981317004" velocity="5.89"/>
    <controller_gains Kd="400" Kp="20000"/>
    <dynamics damping="1.0" friction="0.0"/>
  </joint>
  <gazebo reference="WaistRotator">
    <provideFeedback>1</provideFeedback>
  </gazebo>
  <!-- WJ2 -->
  <joint name="WaistExtensor" type="revolute">
    <origin rpy="1.57079632679 0 0" xyz="0.04191 0 0"/>
    <axis xyz="0 0 1"/>
    <parent link="/v1/WaistRotator"/>
    <child link="/v1/WaistExtensor"/>
    <limit effort="150" lower="-0.6981317004" upper="0.08726646255" velocity="9"/>
    <controller_gains Kd="400" Kp="20000"/>
    <dynamics damping="1.0" friction="0.0"/>
  </joint>
  <gazebo reference="WaistExtensor">
    <provideFeedback>1</provideFeedback>
  </gazebo>
  <!-- WJ3 -->
  <joint name="WaistLateralExtensor" type="revolute">
    <origin rpy="1.57079632679 0 1.57079632679" xyz="0 0.020352 0"/>
    <axis xyz="0 0 1"/>
    <parent link="/v1/WaistExtensor"/>
    <child link="/v1/Trunk"/>
    <limit effort="150" lower="-0.26179938765" upper="0.26179938765" velocity="9"/>
    <controller_gains Kd="400" Kp="20000"/>
    <dynamics damping="1.0" friction="0.0"/>
  </joint>
  <gazebo reference="WaistLateralExtensor">
    <provideFeedback>1</provideFeedback>
  </gazebo>
  <!-- <xacro:v1_waist_actuators name1="${waist_name1}" type1="${waist_type1}" name2="${waist_name2}" type2="${waist_type2}" name3="${waist_name3}" type3="${waist_type3}"/> -->
  <!-- <xacro:v1_waist_transmissions actuator1="${waist_name1}" actuator2="${waist_name2}" actuator3="${waist_name3}" /> -->
  <!-- <xacro:v1_waist_modes actuator1="${waist_name1}" actuator2="${waist_name2}" actuator3="${waist_name3}" /> -->
  <!-- <xacro:v1_trunk_sensors/> -->
  <!-- ===== HEAD ===== -->
  <!-- LINKS -->
  <link name="/v1/LowerNeckExtensor">
    <!-- Virtual Link -->
    <inertial>
      <mass value="0.1"/>
      <origin rpy="0 0 0" xyz="0 0 0"/>
      <inertia ixx="8.33333333333e-05" ixy="0.0" ixz="0.0" iyy="8.33333333333e-05" iyz="0.0" izz="0.000125"/>
    </inertial>
    <visual>
      <origin rpy="0 0 0" xyz="0 0 0"/>
      <geometry>
        <mesh filename="package://V1/meshes/reduced_polygon_meshes/nj1.stl"/>
      </geometry>
      <material name="gold">
        <color rgba="1 0.67 0 1"/>
      </material>
    </visual>
    <collision>
      <origin rpy="0 0 0" xyz="0 0 0"/>
      <geometry>
        <mesh filename="package://V1/meshes/reduced_polygon_meshes/nj1.stl"/>
      </geometry>
    </collision>
  </link>
  <link name="/v1/NeckRotator">
    <!-- Virtual Link -->
    <inertial>
      <mass value="0.1"/>
      <origin rpy="0 0 0" xyz="0 0 0"/>
      <inertia ixx="8.33333333333e-05" ixy="0.0" ixz="0.0" iyy="8.33333333333e-05" iyz="0.0" izz="0.000125"/>
    </inertial>
    <visual>
      <origin rpy="0 0 0" xyz="0 0 0"/>
      <geometry>
        <mesh filename="package://V1/meshes/reduced_polygon_meshes/nj2.stl"/>
      </geometry>
      <material name="gold">
        <color rgba="1 0.67 0 1"/>
      </material>
    </visual>
    <collision>
      <origin rpy="0 0 0" xyz="0 0 0"/>
      <geometry>
        <mesh filename="package://V1/meshes/reduced_polygon_meshes/nj2.stl"/>
      </geometry>
    </collision>
  </link>
  <link name="/v1/Head">
    <inertial>
      <mass value="4.06"/>
      <origin rpy="0 0 0" xyz="-0.08380066 0.01114801 -0.00038569"/>
      <inertia ixx="0.031377304" ixy="0.0" ixz="0.0" iyy="0.031377304" iyz="0.0" izz="0.031377304"/>
    </inertial>
    <visual>
      <origin rpy="0 0 0" xyz="0 0 0"/>
      <!-- <origin rpy="${origin_rpy}" xyz="${origin_xyz}"/> -->
      <geometry>
        <mesh filename="package://V1/meshes/reduced_polygon_meshes/head.stl"/>
        <!-- <sphere radius="${radius}"/> -->
      </geometry>
      <material name="White"/>
    </visual>
    <collision>
      <origin rpy="0 0 0" xyz="0 0 0"/>
      <geometry>
        <mesh filename="package://V1/meshes/reduced_polygon_meshes/head.stl"/>
      </geometry>
    </collision>
  </link>
  <gazebo reference="/v1/Head">
    <material>Gazebo/White</material>
  </gazebo>
  <!-- NJ1 -->
  <joint name="LowerNeckExtensor" type="revolute">
    <origin rpy="-1.57079632679 0 0" xyz="0.3383 0 0.0519"/>
    <axis xyz="0 0 1"/>
    <parent link="/v1/Trunk"/>
    <child link="/v1/LowerNeckExtensor"/>
    <limit effort="26" lower="-1.5707963259" upper="0" velocity="5"/>
    <controller_gains Kd="0" Kp="20000"/>
    <dynamics damping="1.0" friction="0.0"/>
  </joint>
  <gazebo reference="LowerNeckExtensor">
    <provideFeedback>1</provideFeedback>
  </gazebo>
  <!-- NJ2 -->
  <joint name="NeckRotator" type="revolute">
    <origin rpy="1.57079632679 0 1.57079632679" xyz="0 0.0519 0"/>
    <axis xyz="0 0 1"/>
    <parent link="/v1/LowerNeckExtensor"/>
    <child link="/v1/NeckRotator"/>
    <limit effort="26" lower="-1.5707963259" upper="1.5707963259" velocity="5"/>
    <controller_gains Kd="0" Kp="20000"/>
    <dynamics damping="1.0" friction="0.0"/>
  </joint>
  <gazebo reference="NeckRotator">
    <provideFeedback>1</provideFeedback>
  </gazebo>
  <!-- NJ3 -->
  <joint name="UpperNeckExtensor" type="revolute">
    <origin rpy="-1.57079632679 0 0" xyz="0.06 0 0.196"/>
    <axis xyz="0 0 1"/>
    <parent link="/v1/NeckRotator"/>
    <child link="/v1/Head"/>
    <limit effort="26" lower="-0.08726646255" upper="0.78539816295" velocity="5"/>
    <controller_gains Kd="0" Kp="20000"/>
    <dynamics damping="1.0" friction="0.0"/>
  </joint>
  <gazebo reference="UpperNeckExtensor">
    <provideFeedback>1</provideFeedback>
  </gazebo>
  <!-- <xacro:make_head_interface name1="/neck/j1" type1="${neck_type1}"
                               name2="/neck/j2" type2="${neck_type2}"
                               name3="/neck/j3" type3="${neck_type3}"/> -->
  <!-- ===== RIGHT ARM ===== -->
  <!-- LINKS -->
  <link name="/v1/RightShoulderExtensor">
    <inertial>
      <mass value="2.65"/>
      <origin rpy="0 0 0" xyz="0 -0.01204 -0.251"/>
      <inertia ixx="0.0137181666667" ixy="0.0" ixz="0.0" iyy="0.0105028333333" iyz="0.0" izz="0.0148064333333"/>
    </inertial>
    <visual>
      <geometry>
        <mesh filename="package://V1/meshes/reduced_polygon_meshes/aj1_Right.stl"/>
        <!-- <box size="${width} ${height} ${depth}"/> -->
      </geometry>
      <origin rpy="0 0 0" xyz="0 0 0"/>
      <!-- <origin rpy="${origin_rpy}" xyz="${origin_xyz}"/> -->
      <material name="Gold"/>
    </visual>
    <collision>
      <geometry>
        <mesh filename="package://V1/meshes/reduced_polygon_meshes/aj1_Right.stl"/>
      </geometry>
      <origin rpy="0 0 0" xyz="0 0 0"/>
    </collision>
  </link>
  <gazebo reference="/v1/RightShoulderExtensor">
    <material>Gazebo/Gold</material>
  </gazebo>
  <link name="/v1/RightShoulderAdductor">
    <inertial>
      <mass value="2.87"/>
      <origin rpy="0 0 0" xyz="0.04 0.005 -0.02"/>
      <inertia ixx="0.0122024325" ixy="0.0" ixz="0.0" iyy="0.0175559325" iyz="0.0" izz="0.018176745"/>
    </inertial>
    <visual>
      <geometry>
        <mesh filename="package://V1/meshes/reduced_polygon_meshes/aj2.stl"/>
        <!-- <box size="${width} ${height} ${depth}"/> -->
      </geometry>
      <origin rpy="0 0 0" xyz="0 0 0"/>
      <!-- <origin rpy="${origin_rpy}" xyz="${origin_xyz}"/> -->
      <material name="White"/>
    </visual>
    <collision>
      <geometry>
        <mesh filename="package://V1/meshes/reduced_polygon_meshes/aj2.stl"/>
      </geometry>
      <origin rpy="0 0 0" xyz="0 0 0"/>
    </collision>
  </link>
  <gazebo reference="/v1/RightShoulderAdductor">
    <material>Gazebo/White</material>
  </gazebo>
  <link name="/v1/RightShoulderRotator">
    <inertial>
      <mass value="2.575"/>
      <origin rpy="0 0 0" xyz="0.02 -0.004 -0.273"/>
      <inertia ixx="0.0227863895833" ixy="0.0" ixz="0.0" iyy="0.0213984645833" iyz="0.0" izz="0.00932579166667"/>
    </inertial>
    <visual>
      <geometry>
        <mesh filename="package://V1/meshes/reduced_polygon_meshes/aj3_Right.stl"/>
        <!-- <box size="${width} ${height} ${depth}"/> -->
      </geometry>
      <origin rpy="0 0 0" xyz="0 0 0"/>
      <!-- <origin rpy="${origin_rpy}" xyz="${origin_xyz}"/> -->
      <material name="White"/>
    </visual>
    <collision>
      <geometry>
        <mesh filename="package://V1/meshes/reduced_polygon_meshes/aj3_Right.stl"/>
      </geometry>
      <origin rpy="0 0 0" xyz="0 0 0"/>
    </collision>
  </link>
  <gazebo reference="/v1/RightShoulderRotator">
    <material>Gazebo/White</material>
  </gazebo>
  <link name="/v1/RightElbowExtensor">
    <inertial>
      <mass value="2.367"/>
      <origin rpy="0 0 0" xyz="0.0270 -0.0802 0"/>
      <inertia ixx="0.00494170499998" ixy="0.0" ixz="0.0" iyy="0.00469849291665" iyz="0.0" izz="0.00530133991666"/>
    </inertial>
    <visual>
      <geometry>
        <mesh filename="package://V1/meshes/reduced_polygon_meshes/aj4.stl"/>
        <!-- <box size="${width} ${height} ${depth}"/> -->
      </geometry>
      <origin rpy="0 0 0" xyz="0 0 0"/>
      <!-- <origin rpy="${origin_rpy}" xyz="${origin_xyz}"/> -->
      <material name="Gold"/>
    </visual>
    <collision>
      <geometry>
        <mesh filename="package://V1/meshes/reduced_polygon_meshes/aj4.stl"/>
      </geometry>
      <origin rpy="0 0 0" xyz="0 0 0"/>
    </collision>
  </link>
  <gazebo reference="/v1/RightElbowExtensor">
    <material>Gazebo/Gold</material>
  </gazebo>
  <!-- AJ1 -->
  <joint name="RightShoulderExtensor" type="revolute">
    <origin rpy="1.57079632679 0 0" xyz="0.29842 0 -0.03157"/>
    <axis xyz="0 0 1"/>
    <parent link="/v1/Trunk"/>
    <child link="/v1/RightShoulderExtensor"/>
    <limit effort="190" lower="-3.1415926518" upper="3.1415926518" velocity="5.89"/>
    <controller_gains Kd="400" Kp="20000"/>
    <dynamics damping="1.0" friction="0.0"/>
  </joint>
  <gazebo reference="RightShoulderExtensor">
    <provideFeedback>1</provideFeedback>
  </gazebo>
  <!-- AJ2 -->
  <joint name="RightShoulderAdductor" type="revolute">
    <origin rpy="1.57079632679 0 3.14159265359" xyz="0 0 -0.246"/>
    <axis xyz="0 0 1"/>
    <parent link="/v1/RightShoulderExtensor"/>
    <child link="/v1/RightShoulderAdductor"/>
    <limit effort="190" lower="-3.05432618925" upper="-0.155" velocity="5.89"/>
    <controller_gains Kd="400" Kp="20000"/>
    <dynamics damping="1.0" friction="0.0"/>
  </joint>
  <gazebo reference="RightShoulderAdductor">
    <provideFeedback>1</provideFeedback>
  </gazebo>
  <!-- AJ3 -->
  <joint name="RightShoulderSupinator" type="revolute">
    <origin rpy="-1.57079632679 0 1.57079632679" xyz="0 0 0"/>
    <axis xyz="0 0 1"/>
    <parent link="/v1/RightShoulderAdductor"/>
    <child link="/v1/RightShoulderRotator"/>
    <limit effort="65" lower="-1.5707963259" upper="1.7" velocity="11.5"/>
    <controller_gains Kd="400" Kp="20000"/>
    <dynamics damping="1.0" friction="0.0"/>
  </joint>
  <gazebo reference="RightShoulderSupinator">
    <provideFeedback>1</provideFeedback>
  </gazebo>
  <!-- AJ4 -->
  <joint name="RightElbowExtensor" type="revolute">
    <origin rpy="1.57079632679 0 1.57079632679" xyz="0 -0.0254 -0.33"/>
    <axis xyz="0 0 1"/>
    <parent link="/v1/RightShoulderRotator"/>
    <child link="/v1/RightElbowExtensor"/>
    <limit effort="65" lower="-1.9198621761" upper="-0.08726646255" velocity="11.5"/>
    <controller_gains Kd="400" Kp="20000"/>
    <dynamics damping="1.0" friction="0.0"/>
  </joint>
  <gazebo reference="RightElbowExtensor">
    <provideFeedback>1</provideFeedback>
  </gazebo>
  <!-- LINKS -->
  <link name="/v1/RightForearm">
    <inertial>
      <mass value="2.903"/>
      <origin rpy="0 0 0" xyz="0.015 0.02 -0.11"/>
      <inertia ixx="0.0187305" ixy="0.0" ixz="0.0" iyy="0.0200111" iyz="0.0" izz="0.00761213000002"/>
    </inertial>
    <visual>
      <geometry>
        <mesh filename="package://V1/meshes/reduced_polygon_meshes/aj5_Right.stl"/>
        <!-- <box size="${width} ${height} ${depth}"/> -->
      </geometry>
      <origin rpy="0 0 0" xyz="0 0 0"/>
      <!-- <origin rpy="${origin_rpy}" xyz="${origin_xyz}"/> -->
      <material name="White"/>
    </visual>
    <collision>
      <geometry>
        <mesh filename="package://V1/meshes/reduced_polygon_meshes/aj5_Right.stl"/>
      </geometry>
      <origin rpy="0 0 0" xyz="0 0 0"/>
    </collision>
  </link>
  <gazebo reference="/v1/RightForearm">
    <material>Gazebo/White</material>
  </gazebo>
  <link name="/v1/RightWristYoke">
    <inertial>
      <mass value="0.1"/>
      <origin rpy="0 0 0" xyz="0 0 0"/>
      <inertia ixx="2.25083333333e-05" ixy="0.0" ixz="0.0" iyy="2.9175e-05" iyz="0.0" izz="8.33333333333e-06"/>
    </inertial>
    <visual>
      <geometry>
        <box size="0.03 0.01 0.051"/>
      </geometry>
      <origin rpy="0 0 0" xyz="0 0 0"/>
      <material name="Gray"/>
    </visual>
    <collision>
      <geometry>
        <box size="0.03 0.01 0.051"/>
      </geometry>
      <origin rpy="0 0 0" xyz="0 0 0"/>
    </collision>
  </link>
  <link name="/v1/RightPalm">
    <inertial>
      <mass value="0.712"/>
      <origin rpy="0 0 0" xyz="0.0425 0 0"/>
      <inertia ixx="0.000679010666667" ixy="0.0" ixz="0.0" iyy="0.000514360666667" iyz="0.0" izz="0.00102201666667"/>
    </inertial>
    <visual>
      <geometry>
        <mesh filename="package://V1/meshes/reduced_polygon_meshes/palm_Right.stl"/>
        <!-- <box size="${width} ${height} ${depth}"/> -->
      </geometry>
      <origin rpy="0 0 0" xyz="0 0 0"/>
      <!-- <origin rpy="${origin_rpy}" xyz="${origin_xyz}"/> -->
      <material name="Gold"/>
    </visual>
    <collision>
      <geometry>
        <mesh filename="package://V1/meshes/reduced_polygon_meshes/palm_Right.stl"/>
      </geometry>
      <origin rpy="0 0 0" xyz="0 0 0"/>
    </collision>
  </link>
  <gazebo reference="/v1/RightPalm">
    <material>Gazebo/Gold</material>
  </gazebo>
  <!-- AJ5 -->
  <joint name="RightForearmSupinator" type="revolute">
    <origin rpy="1.57079632679 0 3.14159265359" xyz="0.0254 0 0"/>
    <axis xyz="0 0 1"/>
    <parent link="/v1/RightElbowExtensor"/>
    <child link="/v1/RightForearm"/>
    <limit effort="26" lower="-2.35619448885" upper="2.35619448885" velocity="5"/>
    <controller_gains Kd="0" Kp="20000"/>
    <dynamics damping="1.0" friction="0.0"/>
  </joint>
  <gazebo reference="RightForearmSupinator">
    <provideFeedback>1</provideFeedback>
  </gazebo>
  <!-- AJ6 -->
  <joint name="RightWristExtensor" type="revolute">
    <origin rpy="-1.57079632679 0 1.57079632679" xyz="0 0 -0.287"/>
    <axis xyz="0 0 1"/>
    <parent link="/v1/RightForearm"/>
    <child link="/v1/RightWristYoke"/>
    <limit effort="14" lower="-0.8726646255" upper="0.6981317004" velocity="1"/>
    <controller_gains Kd="400" Kp="20000"/>
    <dynamics damping="1.0" friction="0.0"/>
  </joint>
  <gazebo reference="RightWristExtensor">
    <provideFeedback>1</provideFeedback>
  </gazebo>
  <!-- AJ7 -->
  <joint name="RightWrist" type="revolute">
    <origin rpy="1.57079632679 0 1.57079632679" xyz="0 0 0"/>
    <axis xyz="0 0 1"/>
    <parent link="/v1/RightWristYoke"/>
    <child link="/v1/RightPalm"/>
    <limit effort="14" lower="-0.5235987753" upper="0.43633231275" velocity="1"/>
    <controller_gains Kd="400" Kp="20000"/>
    <dynamics damping="1.0" friction="0.0"/>
  </joint>
  <gazebo reference="RightWrist">
    <provideFeedback>1</provideFeedback>
  </gazebo>
  <!-- <xacro:v1_arm_actuators name1="${rightarm_name1}" type1="${arm_type1}"
                            name2="${rightarm_name2}" type2="${arm_type2}"
                            name3="${rightarm_name3}" type3="${arm_type3}"
                            name4="${rightarm_name4}" type4="${arm_type4}"
                            name5="${rightarm_name5}" type5="${arm_type5}"
                            name6="${rightarm_name6}" type6="${arm_type6}"
                            name7="${rightarm_name7}" type7="${arm_type7}"/> -->
  <!-- <xacro:v1_upper_arm_transmissions prefix="Right" actuator1="${rightarm_name1}" actuator2="${rightarm_name2}" actuator3="${rightarm_name3}" actuator4="${rightarm_name4}"/> -->
  <!-- <xacro:v1_lower_arm_transmissions prefix="Right" actuator1="${rightarm_name5}" actuator2="${rightarm_name6}" actuator3="${rightarm_name7}"/> -->
  <!-- <xacro:v1_arm_modes prefix="Right" actuator1="${rightarm_name1}" actuator2="${rightarm_name2}" actuator3="${rightarm_name3}" actuator4="${rightarm_name4}" actuator5="${rightarm_name5}" actuator6="${rightarm_name6}" actuator7="${rightarm_name7}"/> -->
  <!-- Why is this not symmetric?? -->
  <!-- <xacro:v1_arm_sensors /> -->
  <!-- ===== RIGHT THUMB ===== -->
  <!-- LINKS -->
  <link name="/v1/RightThumbMetacarpal">
    <inertial>
      <mass value="0.017"/>
      <origin rpy="0 0 0" xyz="0 0 0"/>
      <inertia ixx="2.83333333333e-07" ixy="0.0" ixz="0.0" iyy="2.83333333333e-07" iyz="0.0" izz="2.83333333333e-07"/>
    </inertial>
    <visual>
      <geometry>
        <mesh filename="package://V1/meshes/reduced_polygon_meshes/tf1_Right.stl"/>
        <!-- <box size="${width} ${height} ${depth}"/> -->
      </geometry>
      <origin rpy="0 0 0" xyz="0 0 0"/>
      <!-- <origin rpy="${origin_rpy}" xyz="${origin_xyz}"/> -->
      <material name="Gold"/>
    </visual>
    <collision>
      <geometry>
        <mesh filename="package://V1/meshes/reduced_polygon_meshes/tf1_Right.stl"/>
      </geometry>
      <origin rpy="0 0 0" xyz="0 0 0"/>
    </collision>
  </link>
  <gazebo reference="/v1/RightThumbMetacarpal">
    <material>Gazebo/Gold</material>
  </gazebo>
  <link name="/v1/RightThumbProximalPhalanx">
    <inertial>
      <mass value="0.02"/>
      <origin rpy="0 0 0" xyz="0.017 0 0"/>
      <inertia ixx="1.72833333333e-06" ixy="0.0" ixz="0.0" iyy="5.98666666667e-06" iyz="0.0" izz="5.46166666667e-06"/>
    </inertial>
    <visual>
      <geometry>
        <mesh filename="package://V1/meshes/reduced_polygon_meshes/tf2.stl"/>
        <!-- <box size="${width} ${height} ${depth}"/> -->
      </geometry>
      <origin rpy="0 0 0" xyz="0 0 0"/>
      <!-- <origin rpy="${origin_rpy}" xyz="${origin_xyz}"/> -->
      <material name="Gold"/>
    </visual>
    <collision>
      <geometry>
        <mesh filename="package://V1/meshes/reduced_polygon_meshes/tf2.stl"/>
      </geometry>
      <origin rpy="0 0 0" xyz="0 0 0"/>
    </collision>
  </link>
  <gazebo reference="/v1/RightThumbProximalPhalanx">
    <material>Gazebo/Gold</material>
  </gazebo>
  <link name="/v1/RightThumbMedialPhalanx">
    <inertial>
      <mass value="0.013"/>
      <origin rpy="0 0 0" xyz="0.011 0 0"/>
      <inertia ixx="7.07416666667e-07" ixy="0.0" ixz="0.0" iyy="1.77666666667e-06" iyz="0.0" izz="1.43541666667e-06"/>
    </inertial>
    <visual>
      <geometry>
        <mesh filename="package://V1/meshes/reduced_polygon_meshes/tf3.stl"/>
        <!-- <box size="${width} ${height} ${depth}"/> -->
      </geometry>
      <origin rpy="0 0 0" xyz="0 0 0"/>
      <!-- <origin rpy="${origin_rpy}" xyz="${origin_xyz}"/> -->
      <material name="Gold"/>
    </visual>
    <collision>
      <geometry>
        <mesh filename="package://V1/meshes/reduced_polygon_meshes/tf3.stl"/>
      </geometry>
      <origin rpy="0 0 0" xyz="0 0 0"/>
    </collision>
  </link>
  <gazebo reference="/v1/RightThumbMedialPhalanx">
    <material>Gazebo/Gold</material>
  </gazebo>
  <link name="/v1/RightThumbDistalPhalanx">
    <inertial>
      <mass value="0.006"/>
      <origin rpy="0 0 0" xyz="0.0086 0 0"/>
      <inertia ixx="2.525e-07" ixy="0.0" ixz="0.0" iyy="5.45e-07" iyz="0.0" izz="4.365e-07"/>
    </inertial>
    <visual>
      <geometry>
        <mesh filename="package://V1/meshes/reduced_polygon_meshes/tf4.stl"/>
        <!-- <box size="${width} ${height} ${depth}"/> -->
      </geometry>
      <origin rpy="0 0 0" xyz="0 0 0"/>
      <!-- <origin rpy="${origin_rpy}" xyz="${origin_xyz}"/> -->
      <material name="Gold"/>
    </visual>
    <collision>
      <geometry>
        <mesh filename="package://V1/meshes/reduced_polygon_meshes/tf4.stl"/>
      </geometry>
      <origin rpy="0 0 0" xyz="0 0 0"/>
    </collision>
  </link>
  <gazebo reference="/v1/RightThumbDistalPhalanx">
    <material>Gazebo/Gold</material>
  </gazebo>
  <!-- TJ1 -->
  <joint name="RightThumbMPYaw" type="fixed">
    <origin rpy="1.57079632679 0 -1.34390352" xyz="0.00748367180673 -0.0324153432851 0.005182"/>
    <axis xyz="0 0 1"/>
    <parent link="/v1/RightPalm"/>
    <child link="/v1/RightThumbMetacarpal"/>
  </joint>
  <!-- TJ2 -->
  <joint name="RightThumbMPExtensor" type="fixed">
    <origin rpy="1.57079632679 0 0" xyz="0.02286 0 -0.025091"/>
    <axis xyz="0 0 1"/>
    <parent link="/v1/RightThumbMetacarpal"/>
    <child link="/v1/RightThumbProximalPhalanx"/>
  </joint>
  <!-- TJ3 -->
  <joint name="RightThumbPIPExtensor" type="fixed">
    <origin rpy="0 0 0" xyz="0.0381 0 0"/>
    <axis xyz="0 0 1"/>
    <parent link="/v1/RightThumbProximalPhalanx"/>
    <child link="/v1/RightThumbMedialPhalanx"/>
  </joint>
  <!-- TJ4 -->
  <joint name="RightThumbDIPExtensor" type="fixed">
    <origin rpy="0 0 0" xyz="0.02794 0 0"/>
    <axis xyz="0 0 1"/>
    <parent link="/v1/RightThumbMedialPhalanx"/>
    <child link="/v1/RightThumbDistalPhalanx"/>
  </joint>
  <!-- <xacro:make_right_thumb_interface api="${finger_api}"/> -->
  <!-- ===== RIGHT PRIMARY FINGER ===== -->
  <!-- LINKS -->
  <link name="/v1/RightPrimaryMetacarpal">
    <inertial>
      <mass value="0.006"/>
      <origin rpy="0 0 0" xyz="-0.0048 0 0"/>
      <inertia ixx="4.225e-07" ixy="0.0" ixz="0.0" iyy="6.625e-07" iyz="0.0" izz="6.01e-07"/>
    </inertial>
    <visual>
      <geometry>
        <mesh filename="package://V1/meshes/reduced_polygon_meshes/pf1.stl"/>
        <!-- <box size="${width} ${height} ${depth}"/> -->
      </geometry>
      <origin rpy="0 0 0" xyz="0 0 0"/>
      <!-- <origin rpy="${origin_rpy}" xyz="${origin_xyz}"/> -->
      <material name="Gold"/>
    </visual>
    <collision>
      <geometry>
        <mesh filename="package://V1/meshes/reduced_polygon_meshes/pf1.stl"/>
      </geometry>
      <origin rpy="0 0 0" xyz="0 0 0"/>
    </collision>
  </link>
  <gazebo reference="/v1/RightPrimaryMetacarpal">
    <material>Gazebo/Gold</material>
  </gazebo>
  <link name="/v1/RightPrimaryProximalPhalanx">
    <inertial>
      <mass value="0.018"/>
      <origin rpy="0 0 0" xyz="0.0175 0 0"/>
      <inertia ixx="1.203e-06" ixy="0.0" ixz="0.0" iyy="5.0355e-06" iyz="0.0" izz="4.9155e-06"/>
    </inertial>
    <visual>
      <geometry>
        <mesh filename="package://V1/meshes/reduced_polygon_meshes/pf2.stl"/>
        <!-- <box size="${width} ${height} ${depth}"/> -->
      </geometry>
      <origin rpy="0 0 0" xyz="0 0 0"/>
      <!-- <origin rpy="${origin_rpy}" xyz="${origin_xyz}"/> -->
      <material name="Gold"/>
    </visual>
    <collision>
      <geometry>
        <mesh filename="package://V1/meshes/reduced_polygon_meshes/pf2.stl"/>
      </geometry>
      <origin rpy="0 0 0" xyz="0 0 0"/>
    </collision>
  </link>
  <gazebo reference="/v1/RightPrimaryProximalPhalanx">
    <material>Gazebo/Gold</material>
  </gazebo>
  <link name="/v1/RightPrimaryMedialPhalanx">
    <inertial>
      <mass value="0.01"/>
      <origin rpy="0 0 0" xyz="0.0108 -0.0003 0"/>
      <inertia ixx="3.81666666667e-07" ixy="0.0" ixz="0.0" iyy="1.20416666667e-06" iyz="0.0" izz="1.10416666667e-06"/>
    </inertial>
    <visual>
      <geometry>
        <mesh filename="package://V1/meshes/reduced_polygon_meshes/pf3.stl"/>
        <!-- <box size="${width} ${height} ${depth}"/> -->
      </geometry>
      <origin rpy="0 0 0" xyz="0 0 0"/>
      <!-- <origin rpy="${origin_rpy}" xyz="${origin_xyz}"/> -->
      <material name="Gold"/>
    </visual>
    <collision>
      <geometry>
        <mesh filename="package://V1/meshes/reduced_polygon_meshes/pf3.stl"/>
      </geometry>
      <origin rpy="0 0 0" xyz="0 0 0"/>
    </collision>
  </link>
  <gazebo reference="/v1/RightPrimaryMedialPhalanx">
    <material>Gazebo/Gold</material>
  </gazebo>
  <link name="/v1/RightPrimaryDistalPhalanx">
    <inertial>
      <mass value="0.005"/>
      <origin rpy="0 0 0" xyz="0.00857 -0.000696 0"/>
      <inertia ixx="1.5375e-07" ixy="0.0" ixz="0.0" iyy="3.975e-07" iyz="0.0" izz="3.6375e-07"/>
    </inertial>
    <visual>
      <geometry>
        <mesh filename="package://V1/meshes/reduced_polygon_meshes/pf4.stl"/>
        <!-- <box size="${width} ${height} ${depth}"/> -->
      </geometry>
      <origin rpy="0 0 0" xyz="0 0 0"/>
      <!-- <origin rpy="${origin_rpy}" xyz="${origin_xyz}"/> -->
      <material name="Gold"/>
    </visual>
    <collision>
      <geometry>
        <mesh filename="package://V1/meshes/reduced_polygon_meshes/pf4.stl"/>
      </geometry>
      <origin rpy="0 0 0" xyz="0 0 0"/>
    </collision>
  </link>
  <gazebo reference="/v1/RightPrimaryDistalPhalanx">
    <material>Gazebo/Gold</material>
  </gazebo>
  <!-- PFJ1 -->
  <joint name="RightPrimaryMPYaw" type="fixed">
    <origin rpy="0.0 0 -0.366519143" xyz="0.0776738914821 -0.0298162134085 0.00254"/>
    <axis xyz="0 0 1"/>
    <parent link="/v1/RightPalm"/>
    <child link="/v1/RightPrimaryMetacarpal"/>
  </joint>
  <!-- PFJ2 -->
  <joint name="RightPrimaryMPExtensor" type="fixed">
    <origin rpy="-1.57079632679 0 0.0568977336" xyz="0.0169724899301 0.000966739661347 0"/>
    <axis xyz="0 0 1"/>
    <parent link="/v1/RightPrimaryMetacarpal"/>
    <child link="/v1/RightPrimaryProximalPhalanx"/>
  </joint>
  <!-- PFJ3 -->
  <joint name="RightPrimaryPIPExtensor" type="fixed">
    <origin rpy="0 0 0" xyz="0.0381 0 0"/>
    <axis xyz="0 0 1"/>
    <parent link="/v1/RightPrimaryProximalPhalanx"/>
    <child link="/v1/RightPrimaryMedialPhalanx"/>
  </joint>
  <!-- PFJ4 -->
  <joint name="RightPrimaryDIPExtensor" type="fixed">
    <origin rpy="0 0 0" xyz="0.02286 0 0"/>
    <axis xyz="0 0 1"/>
    <parent link="/v1/RightPrimaryMedialPhalanx"/>
    <child link="/v1/RightPrimaryDistalPhalanx"/>
  </joint>
  <!-- <xacro:make_right_primary_finger_interface api="${finger_api}"/> -->
  <!-- ===== RIGHT MIDDLE FINGER ===== -->
  <!-- LINKS -->
  <link name="/v1/RightMiddleProximalPhalanx">
    <inertial>
      <mass value="0.02"/>
      <origin rpy="0 0 0" xyz="0.017 0 0"/>
      <inertia ixx="1.72833333333e-06" ixy="0.0" ixz="0.0" iyy="5.98666666667e-06" iyz="0.0" izz="5.46166666667e-06"/>
    </inertial>
    <visual>
      <geometry>
        <mesh filename="package://V1/meshes/reduced_polygon_meshes/sf1.stl"/>
        <!-- <box size="${width} ${height} ${depth}"/> -->
      </geometry>
      <origin rpy="0 0 0" xyz="0 0 0"/>
      <!-- <origin rpy="${origin_rpy}" xyz="${origin_xyz}"/> -->
      <material name="Gold"/>
    </visual>
    <collision>
      <geometry>
        <mesh filename="package://V1/meshes/reduced_polygon_meshes/sf1.stl"/>
      </geometry>
      <origin rpy="0 0 0" xyz="0 0 0"/>
    </collision>
  </link>
  <gazebo reference="/v1/RightMiddleProximalPhalanx">
    <material>Gazebo/Gold</material>
  </gazebo>
  <link name="/v1/RightMiddleMedialPhalanx">
    <inertial>
      <mass value="0.011"/>
      <origin rpy="0 0 0" xyz="0.011 0 0"/>
      <inertia ixx="5.98583333333e-07" ixy="0.0" ixz="0.0" iyy="1.50333333333e-06" iyz="0.0" izz="1.21458333333e-06"/>
    </inertial>
    <visual>
      <geometry>
        <mesh filename="package://V1/meshes/reduced_polygon_meshes/sf2_ssf3.stl"/>
        <!-- <box size="${width} ${height} ${depth}"/> -->
      </geometry>
      <origin rpy="0 0 0" xyz="0 0 0"/>
      <!-- <origin rpy="${origin_rpy}" xyz="${origin_xyz}"/> -->
      <material name="Gold"/>
    </visual>
    <collision>
      <geometry>
        <mesh filename="package://V1/meshes/reduced_polygon_meshes/sf2_ssf3.stl"/>
      </geometry>
      <origin rpy="0 0 0" xyz="0 0 0"/>
    </collision>
  </link>
  <gazebo reference="/v1/RightMiddleMedialPhalanx">
    <material>Gazebo/Gold</material>
  </gazebo>
  <link name="/v1/RightMiddleDistalPhalanx">
    <inertial>
      <mass value="0.006"/>
      <origin rpy="0 0 0" xyz="0.0086 0 0"/>
      <inertia ixx="2.525e-07" ixy="0.0" ixz="0.0" iyy="5.45e-07" iyz="0.0" izz="4.365e-07"/>
    </inertial>
    <visual>
      <geometry>
        <mesh filename="package://V1/meshes/reduced_polygon_meshes/sf3_ssf4.stl"/>
        <!-- <box size="${width} ${height} ${depth}"/> -->
      </geometry>
      <origin rpy="0 0 0" xyz="0 0 0"/>
      <!-- <origin rpy="${origin_rpy}" xyz="${origin_xyz}"/> -->
      <material name="Gold"/>
    </visual>
    <collision>
      <geometry>
        <mesh filename="package://V1/meshes/reduced_polygon_meshes/sf3_ssf4.stl"/>
      </geometry>
      <origin rpy="0 0 0" xyz="0 0 0"/>
    </collision>
  </link>
  <gazebo reference="/v1/RightMiddleDistalPhalanx">
    <material>Gazebo/Gold</material>
  </gazebo>
  <!-- MFJ1 -->
  <joint name="RightMiddleMPExtensor" type="fixed">
    <origin rpy="-1.57079632679 0 0" xyz="0.09767 0 0.00254"/>
    <axis xyz="0 0 1"/>
    <parent link="/v1/RightPalm"/>
    <child link="/v1/RightMiddleProximalPhalanx"/>
  </joint>
  <!-- MFJ2 -->
  <joint name="RightMiddlePIPExtensor" type="fixed">
    <origin rpy="0 0 0" xyz="0.0381 0 0"/>
    <axis xyz="0 0 1"/>
    <parent link="/v1/RightMiddleProximalPhalanx"/>
    <child link="/v1/RightMiddleMedialPhalanx"/>
  </joint>
  <!-- MFJ3 -->
  <joint name="RightMiddleDIPExtensor" type="fixed">
    <origin rpy="0 0 0" xyz="0.02286 0 0"/>
    <axis xyz="0 0 1"/>
    <parent link="/v1/RightMiddleMedialPhalanx"/>
    <child link="/v1/RightMiddleDistalPhalanx"/>
  </joint>
  <!-- <xacro:make_right_middle_finger_interface api="${finger_api}"/> -->
  <!-- ===== RIGHT LITTLE FINGER ===== -->
  <!-- LINKS -->
  <link name="/v1/RightMedialMetacarpal">
    <inertial>
      <mass value="0.047"/>
      <origin rpy="0 0 0" xyz="0 0 0"/>
      <inertia ixx="7.83333333333e-07" ixy="0.0" ixz="0.0" iyy="7.83333333333e-07" iyz="0.0" izz="7.83333333333e-07"/>
    </inertial>
    <visual>
      <geometry>
        <mesh filename="package://V1/meshes/reduced_polygon_meshes/ssf1_Right.stl"/>
        <!-- <box size="${width} ${height} ${depth}"/> -->
      </geometry>
      <origin rpy="0 0 0" xyz="0 0 0"/>
      <!-- <origin rpy="${origin_rpy}" xyz="${origin_xyz}"/> -->
      <material name="Gold"/>
    </visual>
    <collision>
      <geometry>
        <mesh filename="package://V1/meshes/reduced_polygon_meshes/ssf1_Right.stl"/>
      </geometry>
      <origin rpy="0 0 0" xyz="0 0 0"/>
    </collision>
  </link>
  <gazebo reference="/v1/RightMedialMetacarpal">
    <material>Gazebo/Gold</material>
  </gazebo>
  <link name="/v1/RightLittleProximalPhalanx">
    <inertial>
      <mass value="0.02"/>
      <origin rpy="0 0 0" xyz="0 0.017 0.050169"/>
      <inertia ixx="5.98666666667e-06" ixy="0.0" ixz="0.0" iyy="1.72833333333e-06" iyz="0.0" izz="5.46166666667e-06"/>
    </inertial>
    <visual>
      <geometry>
        <mesh filename="package://V1/meshes/reduced_polygon_meshes/ssf2_Right.stl"/>
        <!-- <box size="${width} ${height} ${depth}"/> -->
      </geometry>
      <origin rpy="0 0 0" xyz="0 0 0"/>
      <!-- <origin rpy="${origin_rpy}" xyz="${origin_xyz}"/> -->
      <material name="Gold"/>
    </visual>
    <collision>
      <geometry>
        <mesh filename="package://V1/meshes/reduced_polygon_meshes/ssf2_Right.stl"/>
      </geometry>
      <origin rpy="0 0 0" xyz="0 0 0"/>
    </collision>
  </link>
  <gazebo reference="/v1/RightLittleProximalPhalanx">
    <material>Gazebo/Gold</material>
  </gazebo>
  <link name="/v1/RightLittleMedialPhalanx">
    <inertial>
      <mass value="0.011"/>
      <origin rpy="0 0 0" xyz="0.011 0 0"/>
      <inertia ixx="5.98583333333e-07" ixy="0.0" ixz="0.0" iyy="1.50333333333e-06" iyz="0.0" izz="1.21458333333e-06"/>
    </inertial>
    <visual>
      <geometry>
        <mesh filename="package://V1/meshes/reduced_polygon_meshes/sf2_ssf3.stl"/>
        <!-- <box size="${width} ${height} ${depth}"/> -->
      </geometry>
      <origin rpy="0 0 0" xyz="0 0 0"/>
      <!-- <origin rpy="${origin_rpy}" xyz="${origin_xyz}"/> -->
      <material name="Gold"/>
    </visual>
    <collision>
      <geometry>
        <mesh filename="package://V1/meshes/reduced_polygon_meshes/sf2_ssf3.stl"/>
      </geometry>
      <origin rpy="0 0 0" xyz="0 0 0"/>
    </collision>
  </link>
  <gazebo reference="/v1/RightLittleMedialPhalanx">
    <material>Gazebo/Gold</material>
  </gazebo>
  <link name="/v1/RightLittleDistalPhalanx">
    <inertial>
      <mass value="0.006"/>
      <origin rpy="0 0 0" xyz="0.0086 0 0"/>
      <inertia ixx="2.525e-07" ixy="0.0" ixz="0.0" iyy="5.45e-07" iyz="0.0" izz="4.365e-07"/>
    </inertial>
    <visual>
      <geometry>
        <mesh filename="package://V1/meshes/reduced_polygon_meshes/sf3_ssf4.stl"/>
        <!-- <box size="${width} ${height} ${depth}"/> -->
      </geometry>
      <origin rpy="0 0 0" xyz="0 0 0"/>
      <!-- <origin rpy="${origin_rpy}" xyz="${origin_xyz}"/> -->
      <material name="Gold"/>
    </visual>
    <collision>
      <geometry>
        <mesh filename="package://V1/meshes/reduced_polygon_meshes/sf3_ssf4.stl"/>
      </geometry>
      <origin rpy="0 0 0" xyz="0 0 0"/>
    </collision>
  </link>
  <gazebo reference="/v1/RightLittleDistalPhalanx">
    <material>Gazebo/Gold</material>
  </gazebo>
  <!-- LFJ1 -->
  <joint name="RightLittleMPYaw" type="fixed">
    <origin rpy="-1.57079632679 0 0.690626785" xyz="0.0427072303336 0.0352928446888 -0.007747"/>
    <axis xyz="0 0 1"/>
    <parent link="/v1/RightPalm"/>
    <child link="/v1/RightMedialMetacarpal"/>
  </joint>
  <!-- LFJ2 -->
  <joint name="RightLittleMPExtensor" type="fixed">
    <origin rpy="-0.690626785 0 -1.57079632679" xyz="0 -0.010287 -0.071327"/>
    <axis xyz="0 0 1"/>
    <parent link="/v1/RightMedialMetacarpal"/>
    <child link="/v1/RightLittleProximalPhalanx"/>
  </joint>
  <!-- LFJ3 -->
  <joint name="RightLittlePIPExtensor" type="fixed">
    <origin rpy="0 0 1.57079632679" xyz="0 0.0381 0.050169"/>
    <axis xyz="0 0 1"/>
    <parent link="/v1/RightLittleProximalPhalanx"/>
    <child link="/v1/RightLittleMedialPhalanx"/>
  </joint>
  <!-- LFJ4 -->
  <joint name="RightLittleDIPExtensor" type="fixed">
    <origin rpy="0 0 0" xyz="0.02286 0 0"/>
    <axis xyz="0 0 1"/>
    <parent link="/v1/RightLittleMedialPhalanx"/>
    <child link="/v1/RightLittleDistalPhalanx"/>
  </joint>
  <!-- <xacro:make_right_little_finger_interface api="${finger_api}"/> -->
  <!-- ===== LEFT ARM ===== -->
  <!-- LINKS -->
  <link name="/v1/LeftShoulderExtensor">
    <inertial>
      <mass value="2.65"/>
      <origin rpy="0 0 0" xyz="0 -0.01204 0.251"/>
      <inertia ixx="0.0137181666667" ixy="0.0" ixz="0.0" iyy="0.0105028333333" iyz="0.0" izz="0.0148064333333"/>
    </inertial>
    <visual>
      <geometry>
        <mesh filename="package://V1/meshes/reduced_polygon_meshes/aj1_Left.stl"/>
        <!-- <box size="${width} ${height} ${depth}"/> -->
      </geometry>
      <origin rpy="0 0 0" xyz="0 0 0"/>
      <!-- <origin rpy="${origin_rpy}" xyz="${origin_xyz}"/> -->
      <material name="Gold"/>
    </visual>
    <collision>
      <geometry>
        <mesh filename="package://V1/meshes/reduced_polygon_meshes/aj1_Left.stl"/>
      </geometry>
      <origin rpy="0 0 0" xyz="0 0 0"/>
    </collision>
  </link>
  <gazebo reference="/v1/LeftShoulderExtensor">
    <material>Gazebo/Gold</material>
  </gazebo>
  <link name="/v1/LeftShoulderAdductor">
    <inertial>
      <mass value="2.87"/>
      <origin rpy="0 0 0" xyz="0.04 0.005 0.02"/>
      <inertia ixx="0.0122024325" ixy="0.0" ixz="0.0" iyy="0.0175559325" iyz="0.0" izz="0.018176745"/>
    </inertial>
    <visual>
      <geometry>
        <mesh filename="package://V1/meshes/reduced_polygon_meshes/aj2.stl"/>
        <!-- <box size="${width} ${height} ${depth}"/> -->
      </geometry>
      <origin rpy="0 0 0" xyz="0 0 0"/>
      <!-- <origin rpy="${origin_rpy}" xyz="${origin_xyz}"/> -->
      <material name="White"/>
    </visual>
    <collision>
      <geometry>
        <mesh filename="package://V1/meshes/reduced_polygon_meshes/aj2.stl"/>
      </geometry>
      <origin rpy="0 0 0" xyz="0 0 0"/>
    </collision>
  </link>
  <gazebo reference="/v1/LeftShoulderAdductor">
    <material>Gazebo/White</material>
  </gazebo>
  <link name="/v1/LeftShoulderRotator">
    <inertial>
      <mass value="2.575"/>
      <origin rpy="0 0 0" xyz="-0.02 0.004 0.273"/>
      <inertia ixx="0.0227863895833" ixy="0.0" ixz="0.0" iyy="0.0213984645833" iyz="0.0" izz="0.00932579166667"/>
    </inertial>
    <visual>
      <geometry>
        <mesh filename="package://V1/meshes/reduced_polygon_meshes/aj3_Left.stl"/>
        <!-- <box size="${width} ${height} ${depth}"/> -->
      </geometry>
      <origin rpy="0 0 0" xyz="0 0 0"/>
      <!-- <origin rpy="${origin_rpy}" xyz="${origin_xyz}"/> -->
      <material name="White"/>
    </visual>
    <collision>
      <geometry>
        <mesh filename="package://V1/meshes/reduced_polygon_meshes/aj3_Left.stl"/>
      </geometry>
      <origin rpy="0 0 0" xyz="0 0 0"/>
    </collision>
  </link>
  <gazebo reference="/v1/LeftShoulderRotator">
    <material>Gazebo/White</material>
  </gazebo>
  <link name="/v1/LeftElbowExtensor">
    <inertial>
      <mass value="2.367"/>
      <origin rpy="0 0 0" xyz="0.0270 -0.0802 0"/>
      <inertia ixx="0.00494170499998" ixy="0.0" ixz="0.0" iyy="0.00469849291665" iyz="0.0" izz="0.00530133991666"/>
    </inertial>
    <visual>
      <geometry>
        <mesh filename="package://V1/meshes/reduced_polygon_meshes/aj4.stl"/>
        <!-- <box size="${width} ${height} ${depth}"/> -->
      </geometry>
      <origin rpy="0 0 0" xyz="0 0 0"/>
      <!-- <origin rpy="${origin_rpy}" xyz="${origin_xyz}"/> -->
      <material name="Gold"/>
    </visual>
    <collision>
      <geometry>
        <mesh filename="package://V1/meshes/reduced_polygon_meshes/aj4.stl"/>
      </geometry>
      <origin rpy="0 0 0" xyz="0 0 0"/>
    </collision>
  </link>
  <gazebo reference="/v1/LeftElbowExtensor">
    <material>Gazebo/Gold</material>
  </gazebo>
  <!-- AJ1 -->
  <joint name="LeftShoulderExtensor" type="revolute">
    <origin rpy="1.57079632679 0 0" xyz="0.29842 0 -0.03157"/>
    <axis xyz="0 0 1"/>
    <parent link="/v1/Trunk"/>
    <child link="/v1/LeftShoulderExtensor"/>
    <limit effort="190" lower="-3.1415926518" upper="3.1415926518" velocity="5.89"/>
    <controller_gains Kd="400" Kp="20000"/>
    <dynamics damping="1.0" friction="0.0"/>
  </joint>
  <gazebo reference="LeftShoulderExtensor">
    <provideFeedback>1</provideFeedback>
  </gazebo>
  <!-- AJ2 -->
  <joint name="LeftShoulderAdductor" type="revolute">
    <origin rpy="-1.57079632679 0 3.14159265359" xyz="0 0 0.246"/>
    <axis xyz="0 0 1"/>
    <parent link="/v1/LeftShoulderExtensor"/>
    <child link="/v1/LeftShoulderAdductor"/>
    <limit effort="190" lower="-3.05432618925" upper="-0.155" velocity="5.89"/>
    <controller_gains Kd="400" Kp="20000"/>
    <dynamics damping="1.0" friction="0.0"/>
  </joint>
  <gazebo reference="LeftShoulderAdductor">
    <provideFeedback>1</provideFeedback>
  </gazebo>
  <!-- AJ3 -->
  <joint name="LeftShoulderSupinator" type="revolute">
    <origin rpy="-1.57079632679 0 -1.57079632679" xyz="0 0 0"/>
    <axis xyz="0 0 1"/>
    <parent link="/v1/LeftShoulderAdductor"/>
    <child link="/v1/LeftShoulderRotator"/>
    <limit effort="65" lower="-1.5707963259" upper="1.7" velocity="11.5"/>
    <controller_gains Kd="400" Kp="20000"/>
    <dynamics damping="1.0" friction="0.0"/>
  </joint>
  <gazebo reference="LeftShoulderSupinator">
    <provideFeedback>1</provideFeedback>
  </gazebo>
  <!-- AJ4 -->
  <joint name="LeftElbowExtensor" type="revolute">
    <origin rpy="-1.57079632679 0 -1.57079632679" xyz="0 0.0254 0.33"/>
    <axis xyz="0 0 1"/>
    <parent link="/v1/LeftShoulderRotator"/>
    <child link="/v1/LeftElbowExtensor"/>
    <limit effort="65" lower="-1.9198621761" upper="-0.08726646255" velocity="11.5"/>
    <controller_gains Kd="400" Kp="20000"/>
    <dynamics damping="1.0" friction="0.0"/>
  </joint>
  <gazebo reference="LeftElbowExtensor">
    <provideFeedback>1</provideFeedback>
  </gazebo>
  <!-- LINKS -->
  <link name="/v1/LeftForearm">
    <inertial>
      <mass value="2.903"/>
      <origin rpy="0 0 0" xyz="0.015 -0.02 0.11"/>
      <inertia ixx="0.0187305" ixy="0.0" ixz="0.0" iyy="0.0200111" iyz="0.0" izz="0.00761213000002"/>
    </inertial>
    <visual>
      <geometry>
        <mesh filename="package://V1/meshes/reduced_polygon_meshes/aj5_Left.stl"/>
        <!-- <box size="${width} ${height} ${depth}"/> -->
      </geometry>
      <origin rpy="0 0 0" xyz="0 0 0"/>
      <!-- <origin rpy="${origin_rpy}" xyz="${origin_xyz}"/> -->
      <material name="White"/>
    </visual>
    <collision>
      <geometry>
        <mesh filename="package://V1/meshes/reduced_polygon_meshes/aj5_Left.stl"/>
      </geometry>
      <origin rpy="0 0 0" xyz="0 0 0"/>
    </collision>
  </link>
  <gazebo reference="/v1/LeftForearm">
    <material>Gazebo/White</material>
  </gazebo>
  <link name="/v1/LeftWristYoke">
    <inertial>
      <mass value="0.1"/>
      <origin rpy="0 0 0" xyz="0 0 0"/>
      <inertia ixx="2.25083333333e-05" ixy="0.0" ixz="0.0" iyy="2.9175e-05" iyz="0.0" izz="8.33333333333e-06"/>
    </inertial>
    <visual>
      <geometry>
        <box size="0.03 0.01 0.051"/>
      </geometry>
      <origin rpy="0 0 0" xyz="0 0 0"/>
      <material name="Gray"/>
    </visual>
    <collision>
      <geometry>
        <box size="0.03 0.01 0.051"/>
      </geometry>
      <origin rpy="0 0 0" xyz="0 0 0"/>
    </collision>
  </link>
  <link name="/v1/LeftPalm">
    <inertial>
      <mass value="0.712"/>
      <origin rpy="0 0 0" xyz="0.0425 0 0"/>
      <inertia ixx="0.000679010666667" ixy="0.0" ixz="0.0" iyy="0.000514360666667" iyz="0.0" izz="0.00102201666667"/>
    </inertial>
    <visual>
      <geometry>
        <mesh filename="package://V1/meshes/reduced_polygon_meshes/palm_Left.stl"/>
        <!-- <box size="${width} ${height} ${depth}"/> -->
      </geometry>
      <origin rpy="0 0 0" xyz="0 0 0"/>
      <!-- <origin rpy="${origin_rpy}" xyz="${origin_xyz}"/> -->
      <material name="Gold"/>
    </visual>
    <collision>
      <geometry>
        <mesh filename="package://V1/meshes/reduced_polygon_meshes/palm_Left.stl"/>
      </geometry>
      <origin rpy="0 0 0" xyz="0 0 0"/>
    </collision>
  </link>
  <gazebo reference="/v1/LeftPalm">
    <material>Gazebo/Gold</material>
  </gazebo>
  <!-- AJ5 -->
  <joint name="LeftForearmSupinator" type="revolute">
    <origin rpy="-1.57079632679 0 3.14159265359" xyz="0.0254 0 0"/>
    <axis xyz="0 0 1"/>
    <parent link="/v1/LeftElbowExtensor"/>
    <child link="/v1/LeftForearm"/>
    <limit effort="26" lower="-2.35619448885" upper="2.35619448885" velocity="5"/>
    <controller_gains Kd="0" Kp="20000"/>
    <dynamics damping="1.0" friction="0.0"/>
  </joint>
  <gazebo reference="LeftForearmSupinator">
    <provideFeedback>1</provideFeedback>
  </gazebo>
  <!-- AJ6 -->
  <joint name="LeftWristExtensor" type="revolute">
    <origin rpy="-1.57079632679 0 -1.57079632679" xyz="0 0 0.287"/>
    <axis xyz="0 0 1"/>
    <parent link="/v1/LeftForearm"/>
    <child link="/v1/LeftWristYoke"/>
    <limit effort="14" lower="-0.8726646255" upper="0.6981317004" velocity="1"/>
    <controller_gains Kd="400" Kp="20000"/>
    <dynamics damping="1.0" friction="0.0"/>
  </joint>
  <gazebo reference="LeftWristExtensor">
    <provideFeedback>1</provideFeedback>
  </gazebo>
  <!-- AJ7 -->
  <joint name="LeftWrist" type="revolute">
    <origin rpy="-1.57079632679 0 -1.57079632679" xyz="0 0 0"/>
    <axis xyz="0 0 1"/>
    <parent link="/v1/LeftWristYoke"/>
    <child link="/v1/LeftPalm"/>
    <limit effort="14" lower="-0.5235987753" upper="0.43633231275" velocity="1"/>
    <controller_gains Kd="400" Kp="20000"/>
    <dynamics damping="1.0" friction="0.0"/>
  </joint>
  <gazebo reference="LeftWrist">
    <provideFeedback>1</provideFeedback>
  </gazebo>
  <!-- <xacro:v1_arm_actuators name1="${leftarm_name1}" type1="${arm_type1}"
                            name2="${leftarm_name2}" type2="${arm_type2}"
                            name3="${leftarm_name3}" type3="${arm_type3}"
                            name4="${leftarm_name4}" type4="${arm_type4}"
                            name5="${leftarm_name5}" type5="${arm_type5}"
                            name6="${leftarm_name6}" type6="${arm_type6}"
                            name7="${leftarm_name7}" type7="${arm_type7}"/> -->
  <!-- <xacro:v1_upper_arm_transmissions prefix="Left" actuator1="${leftarm_name1}" actuator2="${leftarm_name2}" actuator3="${leftarm_name3}" actuator4="${leftarm_name4}"/> -->
  <!-- <xacro:v1_lower_arm_transmissions prefix="Left" actuator1="${leftarm_name5}" actuator2="${leftarm_name6}" actuator3="${leftarm_name7}"/> -->
  <!-- <xacro:v1_arm_modes prefix="Left" actuator1="${leftarm_name1}" actuator2="${leftarm_name2}" actuator3="${leftarm_name3}" actuator4="${leftarm_name4}" actuator5="${leftarm_name5}" actuator6="${leftarm_name6}" actuator7="${leftarm_name7}"/> -->
  <!-- ===== LEFT THUMB ===== -->
  <!-- LINKS -->
  <link name="/v1/LeftThumbMetacarpal">
    <inertial>
      <mass value="0.017"/>
      <origin rpy="0 0 0" xyz="0 0 0"/>
      <inertia ixx="2.83333333333e-07" ixy="0.0" ixz="0.0" iyy="2.83333333333e-07" iyz="0.0" izz="2.83333333333e-07"/>
    </inertial>
    <visual>
      <geometry>
        <mesh filename="package://V1/meshes/reduced_polygon_meshes/tf1_Left.stl"/>
        <!-- <box size="${width} ${height} ${depth}"/> -->
      </geometry>
      <origin rpy="0 0 0" xyz="0 0 0"/>
      <!-- <origin rpy="${origin_rpy}" xyz="${origin_xyz}"/> -->
      <material name="Gold"/>
    </visual>
    <collision>
      <geometry>
        <mesh filename="package://V1/meshes/reduced_polygon_meshes/tf1_Left.stl"/>
      </geometry>
      <origin rpy="0 0 0" xyz="0 0 0"/>
    </collision>
  </link>
  <gazebo reference="/v1/LeftThumbMetacarpal">
    <material>Gazebo/Gold</material>
  </gazebo>
  <link name="/v1/LeftThumbProximalPhalanx">
    <inertial>
      <mass value="0.02"/>
      <origin rpy="0 0 0" xyz="0.017 0 0"/>
      <inertia ixx="1.72833333333e-06" ixy="0.0" ixz="0.0" iyy="5.98666666667e-06" iyz="0.0" izz="5.46166666667e-06"/>
    </inertial>
    <visual>
      <geometry>
        <mesh filename="package://V1/meshes/reduced_polygon_meshes/tf2.stl"/>
        <!-- <box size="${width} ${height} ${depth}"/> -->
      </geometry>
      <origin rpy="0 0 0" xyz="0 0 0"/>
      <!-- <origin rpy="${origin_rpy}" xyz="${origin_xyz}"/> -->
      <material name="Gold"/>
    </visual>
    <collision>
      <geometry>
        <mesh filename="package://V1/meshes/reduced_polygon_meshes/tf2.stl"/>
      </geometry>
      <origin rpy="0 0 0" xyz="0 0 0"/>
    </collision>
  </link>
  <gazebo reference="/v1/LeftThumbProximalPhalanx">
    <material>Gazebo/Gold</material>
  </gazebo>
  <link name="/v1/LeftThumbMedialPhalanx">
    <inertial>
      <mass value="0.013"/>
      <origin rpy="0 0 0" xyz="0.011 0 0"/>
      <inertia ixx="7.07416666667e-07" ixy="0.0" ixz="0.0" iyy="1.77666666667e-06" iyz="0.0" izz="1.43541666667e-06"/>
    </inertial>
    <visual>
      <geometry>
        <mesh filename="package://V1/meshes/reduced_polygon_meshes/tf3.stl"/>
        <!-- <box size="${width} ${height} ${depth}"/> -->
      </geometry>
      <origin rpy="0 0 0" xyz="0 0 0"/>
      <!-- <origin rpy="${origin_rpy}" xyz="${origin_xyz}"/> -->
      <material name="Gold"/>
    </visual>
    <collision>
      <geometry>
        <mesh filename="package://V1/meshes/reduced_polygon_meshes/tf3.stl"/>
      </geometry>
      <origin rpy="0 0 0" xyz="0 0 0"/>
    </collision>
  </link>
  <gazebo reference="/v1/LeftThumbMedialPhalanx">
    <material>Gazebo/Gold</material>
  </gazebo>
  <link name="/v1/LeftThumbDistalPhalanx">
    <inertial>
      <mass value="0.006"/>
      <origin rpy="0 0 0" xyz="0.0086 0 0"/>
      <inertia ixx="2.525e-07" ixy="0.0" ixz="0.0" iyy="5.45e-07" iyz="0.0" izz="4.365e-07"/>
    </inertial>
    <visual>
      <geometry>
        <mesh filename="package://V1/meshes/reduced_polygon_meshes/tf4.stl"/>
        <!-- <box size="${width} ${height} ${depth}"/> -->
      </geometry>
      <origin rpy="0 0 0" xyz="0 0 0"/>
      <!-- <origin rpy="${origin_rpy}" xyz="${origin_xyz}"/> -->
      <material name="Gold"/>
    </visual>
    <collision>
      <geometry>
        <mesh filename="package://V1/meshes/reduced_polygon_meshes/tf4.stl"/>
      </geometry>
      <origin rpy="0 0 0" xyz="0 0 0"/>
    </collision>
  </link>
  <gazebo reference="/v1/LeftThumbDistalPhalanx">
    <material>Gazebo/Gold</material>
  </gazebo>
  <!-- TJ1 -->
  <joint name="LeftThumbMPYaw" type="fixed">
    <origin rpy="-1.57079632679 0 -1.34390352" xyz="0.00748367180673 -0.0324153432851 -0.005182"/>
    <axis xyz="0 0 1"/>
    <parent link="/v1/LeftPalm"/>
    <child link="/v1/LeftThumbMetacarpal"/>
  </joint>
  <!-- TJ2 -->
  <joint name="LeftThumbMPExtensor" type="fixed">
    <origin rpy="-1.57079632679 0 0" xyz="0.02286 0 0.025091"/>
    <axis xyz="0 0 1"/>
    <parent link="/v1/LeftThumbMetacarpal"/>
    <child link="/v1/LeftThumbProximalPhalanx"/>
  </joint>
  <!-- TJ3 -->
  <joint name="LeftThumbPIPExtensor" type="fixed">
    <origin rpy="0 0 0" xyz="0.0381 0 0"/>
    <axis xyz="0 0 1"/>
    <parent link="/v1/LeftThumbProximalPhalanx"/>
    <child link="/v1/LeftThumbMedialPhalanx"/>
  </joint>
  <!-- TJ4 -->
  <joint name="LeftThumbDIPExtensor" type="fixed">
    <origin rpy="0 0 0" xyz="0.02794 0 0"/>
    <axis xyz="0 0 1"/>
    <parent link="/v1/LeftThumbMedialPhalanx"/>
    <child link="/v1/LeftThumbDistalPhalanx"/>
  </joint>
  <!-- <xacro:make_left_thumb_interface api="${finger_api}"/> -->
  <!-- ===== LEFT PRIMARY FINGER ===== -->
  <!-- LINKS -->
  <link name="/v1/LeftPrimaryMetacarpal">
    <inertial>
      <mass value="0.006"/>
      <origin rpy="0 0 0" xyz="-0.0048 0 0"/>
      <inertia ixx="4.225e-07" ixy="0.0" ixz="0.0" iyy="6.625e-07" iyz="0.0" izz="6.01e-07"/>
    </inertial>
    <visual>
      <geometry>
        <mesh filename="package://V1/meshes/reduced_polygon_meshes/pf1.stl"/>
        <!-- <box size="${width} ${height} ${depth}"/> -->
      </geometry>
      <origin rpy="0 0 0" xyz="0 0 0"/>
      <!-- <origin rpy="${origin_rpy}" xyz="${origin_xyz}"/> -->
      <material name="Gold"/>
    </visual>
    <collision>
      <geometry>
        <mesh filename="package://V1/meshes/reduced_polygon_meshes/pf1.stl"/>
      </geometry>
      <origin rpy="0 0 0" xyz="0 0 0"/>
    </collision>
  </link>
  <gazebo reference="/v1/LeftPrimaryMetacarpal">
    <material>Gazebo/Gold</material>
  </gazebo>
  <link name="/v1/LeftPrimaryProximalPhalanx">
    <inertial>
      <mass value="0.018"/>
      <origin rpy="0 0 0" xyz="0.0175 0 0"/>
      <inertia ixx="1.203e-06" ixy="0.0" ixz="0.0" iyy="5.0355e-06" iyz="0.0" izz="4.9155e-06"/>
    </inertial>
    <visual>
      <geometry>
        <mesh filename="package://V1/meshes/reduced_polygon_meshes/pf2.stl"/>
        <!-- <box size="${width} ${height} ${depth}"/> -->
      </geometry>
      <origin rpy="0 0 0" xyz="0 0 0"/>
      <!-- <origin rpy="${origin_rpy}" xyz="${origin_xyz}"/> -->
      <material name="Gold"/>
    </visual>
    <collision>
      <geometry>
        <mesh filename="package://V1/meshes/reduced_polygon_meshes/pf2.stl"/>
      </geometry>
      <origin rpy="0 0 0" xyz="0 0 0"/>
    </collision>
  </link>
  <gazebo reference="/v1/LeftPrimaryProximalPhalanx">
    <material>Gazebo/Gold</material>
  </gazebo>
  <link name="/v1/LeftPrimaryMedialPhalanx">
    <inertial>
      <mass value="0.01"/>
      <origin rpy="0 0 0" xyz="0.0108 -0.0003 0"/>
      <inertia ixx="3.81666666667e-07" ixy="0.0" ixz="0.0" iyy="1.20416666667e-06" iyz="0.0" izz="1.10416666667e-06"/>
    </inertial>
    <visual>
      <geometry>
        <mesh filename="package://V1/meshes/reduced_polygon_meshes/pf3.stl"/>
        <!-- <box size="${width} ${height} ${depth}"/> -->
      </geometry>
      <origin rpy="0 0 0" xyz="0 0 0"/>
      <!-- <origin rpy="${origin_rpy}" xyz="${origin_xyz}"/> -->
      <material name="Gold"/>
    </visual>
    <collision>
      <geometry>
        <mesh filename="package://V1/meshes/reduced_polygon_meshes/pf3.stl"/>
      </geometry>
      <origin rpy="0 0 0" xyz="0 0 0"/>
    </collision>
  </link>
  <gazebo reference="/v1/LeftPrimaryMedialPhalanx">
    <material>Gazebo/Gold</material>
  </gazebo>
  <link name="/v1/LeftPrimaryDistalPhalanx">
    <inertial>
      <mass value="0.005"/>
      <origin rpy="0 0 0" xyz="0.00857 -0.000696 0"/>
      <inertia ixx="1.5375e-07" ixy="0.0" ixz="0.0" iyy="3.975e-07" iyz="0.0" izz="3.6375e-07"/>
    </inertial>
    <visual>
      <geometry>
        <mesh filename="package://V1/meshes/reduced_polygon_meshes/pf4.stl"/>
        <!-- <box size="${width} ${height} ${depth}"/> -->
      </geometry>
      <origin rpy="0 0 0" xyz="0 0 0"/>
      <!-- <origin rpy="${origin_rpy}" xyz="${origin_xyz}"/> -->
      <material name="Gold"/>
    </visual>
    <collision>
      <geometry>
        <mesh filename="package://V1/meshes/reduced_polygon_meshes/pf4.stl"/>
      </geometry>
      <origin rpy="0 0 0" xyz="0 0 0"/>
    </collision>
  </link>
  <gazebo reference="/v1/LeftPrimaryDistalPhalanx">
    <material>Gazebo/Gold</material>
  </gazebo>
  <!-- PFJ1 -->
  <joint name="LeftPrimaryMPYaw" type="fixed">
    <origin rpy="-3.14159265359 0 -0.366519143" xyz="0.0776738914821 -0.0298162134085 -0.00254"/>
    <axis xyz="0 0 1"/>
    <parent link="/v1/LeftPalm"/>
    <child link="/v1/LeftPrimaryMetacarpal"/>
  </joint>
  <!-- PFJ2 -->
  <joint name="LeftPrimaryMPExtensor" type="fixed">
    <origin rpy="-1.57079632679 0 0.0568977336" xyz="0.0169724899301 0.000966739661347 0"/>
    <axis xyz="0 0 1"/>
    <parent link="/v1/LeftPrimaryMetacarpal"/>
    <child link="/v1/LeftPrimaryProximalPhalanx"/>
  </joint>
  <!-- PFJ3 -->
  <joint name="LeftPrimaryPIPExtensor" type="fixed">
    <origin rpy="0 0 0" xyz="0.0381 0 0"/>
    <axis xyz="0 0 1"/>
    <parent link="/v1/LeftPrimaryProximalPhalanx"/>
    <child link="/v1/LeftPrimaryMedialPhalanx"/>
  </joint>
  <!-- PFJ4 -->
  <joint name="LeftPrimaryDIPExtensor" type="fixed">
    <origin rpy="0 0 0" xyz="0.02286 0 0"/>
    <axis xyz="0 0 1"/>
    <parent link="/v1/LeftPrimaryMedialPhalanx"/>
    <child link="/v1/LeftPrimaryDistalPhalanx"/>
  </joint>
  <!-- <xacro:make_left_primary_finger_interface api="${finger_api}"/> -->
  <!-- ===== LEFT MIDDLE FINGER ===== -->
  <!-- LINKS -->
  <link name="/v1/LeftMiddleProximalPhalanx">
    <inertial>
      <mass value="0.02"/>
      <origin rpy="0 0 0" xyz="0.017 0 0"/>
      <inertia ixx="1.72833333333e-06" ixy="0.0" ixz="0.0" iyy="5.98666666667e-06" iyz="0.0" izz="5.46166666667e-06"/>
    </inertial>
    <visual>
      <geometry>
        <mesh filename="package://V1/meshes/reduced_polygon_meshes/sf1.stl"/>
        <!-- <box size="${width} ${height} ${depth}"/> -->
      </geometry>
      <origin rpy="0 0 0" xyz="0 0 0"/>
      <!-- <origin rpy="${origin_rpy}" xyz="${origin_xyz}"/> -->
      <material name="Gold"/>
    </visual>
    <collision>
      <geometry>
        <mesh filename="package://V1/meshes/reduced_polygon_meshes/sf1.stl"/>
      </geometry>
      <origin rpy="0 0 0" xyz="0 0 0"/>
    </collision>
  </link>
  <gazebo reference="/v1/LeftMiddleProximalPhalanx">
    <material>Gazebo/Gold</material>
  </gazebo>
  <link name="/v1/LeftMiddleMedialPhalanx">
    <inertial>
      <mass value="0.011"/>
      <origin rpy="0 0 0" xyz="0.011 0 0"/>
      <inertia ixx="5.98583333333e-07" ixy="0.0" ixz="0.0" iyy="1.50333333333e-06" iyz="0.0" izz="1.21458333333e-06"/>
    </inertial>
    <visual>
      <geometry>
        <mesh filename="package://V1/meshes/reduced_polygon_meshes/sf2_ssf3.stl"/>
        <!-- <box size="${width} ${height} ${depth}"/> -->
      </geometry>
      <origin rpy="0 0 0" xyz="0 0 0"/>
      <!-- <origin rpy="${origin_rpy}" xyz="${origin_xyz}"/> -->
      <material name="Gold"/>
    </visual>
    <collision>
      <geometry>
        <mesh filename="package://V1/meshes/reduced_polygon_meshes/sf2_ssf3.stl"/>
      </geometry>
      <origin rpy="0 0 0" xyz="0 0 0"/>
    </collision>
  </link>
  <gazebo reference="/v1/LeftMiddleMedialPhalanx">
    <material>Gazebo/Gold</material>
  </gazebo>
  <link name="/v1/LeftMiddleDistalPhalanx">
    <inertial>
      <mass value="0.006"/>
      <origin rpy="0 0 0" xyz="0.0086 0 0"/>
      <inertia ixx="2.525e-07" ixy="0.0" ixz="0.0" iyy="5.45e-07" iyz="0.0" izz="4.365e-07"/>
    </inertial>
    <visual>
      <geometry>
        <mesh filename="package://V1/meshes/reduced_polygon_meshes/sf3_ssf4.stl"/>
        <!-- <box size="${width} ${height} ${depth}"/> -->
      </geometry>
      <origin rpy="0 0 0" xyz="0 0 0"/>
      <!-- <origin rpy="${origin_rpy}" xyz="${origin_xyz}"/> -->
      <material name="Gold"/>
    </visual>
    <collision>
      <geometry>
        <mesh filename="package://V1/meshes/reduced_polygon_meshes/sf3_ssf4.stl"/>
      </geometry>
      <origin rpy="0 0 0" xyz="0 0 0"/>
    </collision>
  </link>
  <gazebo reference="/v1/LeftMiddleDistalPhalanx">
    <material>Gazebo/Gold</material>
  </gazebo>
  <!-- MFJ1 -->
  <joint name="LeftMiddleMPExtensor" type="fixed">
    <origin rpy="1.57079632679 0 0" xyz="0.09767 0 -0.00254"/>
    <axis xyz="0 0 1"/>
    <parent link="/v1/LeftPalm"/>
    <child link="/v1/LeftMiddleProximalPhalanx"/>
  </joint>
  <!-- MFJ2 -->
  <joint name="LeftMiddlePIPExtensor" type="fixed">
    <origin rpy="0 0 0" xyz="0.0381 0 0"/>
    <axis xyz="0 0 1"/>
    <parent link="/v1/LeftMiddleProximalPhalanx"/>
    <child link="/v1/LeftMiddleMedialPhalanx"/>
  </joint>
  <!-- MFJ3 -->
  <joint name="LeftMiddleDIPExtensor" type="fixed">
    <origin rpy="0 0 0" xyz="0.02286 0 0"/>
    <axis xyz="0 0 1"/>
    <parent link="/v1/LeftMiddleMedialPhalanx"/>
    <child link="/v1/LeftMiddleDistalPhalanx"/>
  </joint>
  <!-- <xacro:make_left_middle_finger_interface api="${finger_api}"/> -->
  <!-- ===== LEFT LITTLE FINGER ===== -->
  <!-- LINKS -->
  <link name="/v1/LeftMedialMetacarpal">
    <inertial>
      <mass value="0.047"/>
      <origin rpy="0 0 0" xyz="0 0 0"/>
      <inertia ixx="7.83333333333e-07" ixy="0.0" ixz="0.0" iyy="7.83333333333e-07" iyz="0.0" izz="7.83333333333e-07"/>
    </inertial>
    <visual>
      <geometry>
        <mesh filename="package://V1/meshes/reduced_polygon_meshes/ssf1_Left.stl"/>
        <!-- <box size="${width} ${height} ${depth}"/> -->
      </geometry>
      <origin rpy="0 0 0" xyz="0 0 0"/>
      <!-- <origin rpy="${origin_rpy}" xyz="${origin_xyz}"/> -->
      <material name="Gold"/>
    </visual>
    <collision>
      <geometry>
        <mesh filename="package://V1/meshes/reduced_polygon_meshes/ssf1_Left.stl"/>
      </geometry>
      <origin rpy="0 0 0" xyz="0 0 0"/>
    </collision>
  </link>
  <gazebo reference="/v1/LeftMedialMetacarpal">
    <material>Gazebo/Gold</material>
  </gazebo>
  <link name="/v1/LeftLittleProximalPhalanx">
    <inertial>
      <mass value="0.02"/>
      <origin rpy="0 0 0" xyz="0 -0.017 -0.050169"/>
      <inertia ixx="5.98666666667e-06" ixy="0.0" ixz="0.0" iyy="1.72833333333e-06" iyz="0.0" izz="5.46166666667e-06"/>
    </inertial>
    <visual>
      <geometry>
        <mesh filename="package://V1/meshes/reduced_polygon_meshes/ssf2_Left.stl"/>
        <!-- <box size="${width} ${height} ${depth}"/> -->
      </geometry>
      <origin rpy="0 0 0" xyz="0 0 0"/>
      <!-- <origin rpy="${origin_rpy}" xyz="${origin_xyz}"/> -->
      <material name="Gold"/>
    </visual>
    <collision>
      <geometry>
        <mesh filename="package://V1/meshes/reduced_polygon_meshes/ssf2_Left.stl"/>
      </geometry>
      <origin rpy="0 0 0" xyz="0 0 0"/>
    </collision>
  </link>
  <gazebo reference="/v1/LeftLittleProximalPhalanx">
    <material>Gazebo/Gold</material>
  </gazebo>
  <link name="/v1/LeftLittleMedialPhalanx">
    <inertial>
      <mass value="0.011"/>
      <origin rpy="0 0 0" xyz="0.011 0 0"/>
      <inertia ixx="5.98583333333e-07" ixy="0.0" ixz="0.0" iyy="1.50333333333e-06" iyz="0.0" izz="1.21458333333e-06"/>
    </inertial>
    <visual>
      <geometry>
        <mesh filename="package://V1/meshes/reduced_polygon_meshes/sf2_ssf3.stl"/>
        <!-- <box size="${width} ${height} ${depth}"/> -->
      </geometry>
      <origin rpy="0 0 0" xyz="0 0 0"/>
      <!-- <origin rpy="${origin_rpy}" xyz="${origin_xyz}"/> -->
      <material name="Gold"/>
    </visual>
    <collision>
      <geometry>
        <mesh filename="package://V1/meshes/reduced_polygon_meshes/sf2_ssf3.stl"/>
      </geometry>
      <origin rpy="0 0 0" xyz="0 0 0"/>
    </collision>
  </link>
  <gazebo reference="/v1/LeftLittleMedialPhalanx">
    <material>Gazebo/Gold</material>
  </gazebo>
  <link name="/v1/LeftLittleDistalPhalanx">
    <inertial>
      <mass value="0.006"/>
      <origin rpy="0 0 0" xyz="0.0086 0 0"/>
      <inertia ixx="2.525e-07" ixy="0.0" ixz="0.0" iyy="5.45e-07" iyz="0.0" izz="4.365e-07"/>
    </inertial>
    <visual>
      <geometry>
        <mesh filename="package://V1/meshes/reduced_polygon_meshes/sf3_ssf4.stl"/>
        <!-- <box size="${width} ${height} ${depth}"/> -->
      </geometry>
      <origin rpy="0 0 0" xyz="0 0 0"/>
      <!-- <origin rpy="${origin_rpy}" xyz="${origin_xyz}"/> -->
      <material name="Gold"/>
    </visual>
    <collision>
      <geometry>
        <mesh filename="package://V1/meshes/reduced_polygon_meshes/sf3_ssf4.stl"/>
      </geometry>
      <origin rpy="0 0 0" xyz="0 0 0"/>
    </collision>
  </link>
  <gazebo reference="/v1/LeftLittleDistalPhalanx">
    <material>Gazebo/Gold</material>
  </gazebo>
  <!-- LFJ1 -->
  <joint name="LeftLittleMPYaw" type="fixed">
    <origin rpy="1.57079632679 0 0.690626785" xyz="0.0427072303336 0.0352928446888 0.007747"/>
    <axis xyz="0 0 1"/>
    <parent link="/v1/LeftPalm"/>
    <child link="/v1/LeftMedialMetacarpal"/>
  </joint>
  <!-- LFJ2 -->
  <joint name="LeftLittleMPExtensor" type="fixed">
    <origin rpy="-0.690626785 0 1.57079632679" xyz="0 -0.010287 0.071327"/>
    <axis xyz="0 0 1"/>
    <parent link="/v1/LeftMedialMetacarpal"/>
    <child link="/v1/LeftLittleProximalPhalanx"/>
  </joint>
  <!-- LFJ3 -->
  <joint name="LeftLittlePIPExtensor" type="fixed">
    <origin rpy="0 0 -1.57079632679" xyz="0 -0.0381 -0.050169"/>
    <axis xyz="0 0 1"/>
    <parent link="/v1/LeftLittleProximalPhalanx"/>
    <child link="/v1/LeftLittleMedialPhalanx"/>
  </joint>
  <!-- LFJ4 -->
  <joint name="LeftLittleDIPExtensor" type="fixed">
    <origin rpy="0 0 0" xyz="0.02286 0 0"/>
    <axis xyz="0 0 1"/>
    <parent link="/v1/LeftLittleMedialPhalanx"/>
    <child link="/v1/LeftLittleDistalPhalanx"/>
  </joint>
  <!-- <xacro:make_left_little_finger_interface api="${finger_api}"/> -->
  <!-- ===== RIGHT LEG ===== -->
  <!-- LINKS -->
  <link name="/v1/RightHipRotator">
    <inertial>
      <mass value="2.39"/>
      <origin rpy="0 0 0" xyz="0.001307857 0.021764163 0.038670367"/>
      <inertia ixx="0.0172609783333" ixy="0.0" ixz="0.0" iyy="0.0148661983333" iyz="0.0" izz="0.0112381783333"/>
    </inertial>
    <visual>
      <geometry>
        <mesh filename="package://V1/meshes/reduced_polygon_meshes/lj1_Right.stl"/>
        <!-- <box size="${width} ${height} ${depth}"/> -->
      </geometry>
      <origin rpy="0 0 0" xyz="0 0 0"/>
      <!-- <origin rpy="${origin_rpy}" xyz="${origin_xyz}"/> -->
      <material name="Gold"/>
    </visual>
    <collision>
      <geometry>
        <mesh filename="package://V1/meshes/reduced_polygon_meshes/lj1_Right.stl"/>
      </geometry>
      <origin rpy="0 0 0" xyz="0 0 0"/>
    </collision>
  </link>
  <gazebo reference="/v1/RightHipRotator">
    <material>Gazebo/Gold</material>
  </gazebo>
  <link name="/v1/RightHipAdductor">
    <inertial>
      <mass value="5.95"/>
      <origin rpy="0 0 0" xyz="0.024260044 0.019261751 -0.0018458616"/>
      <inertia ixx="0.0244713583333" ixy="0.0" ixz="0.0" iyy="0.0160104583333" iyz="0.0" izz="0.0254788916667"/>
    </inertial>
    <visual>
      <geometry>
        <mesh filename="package://V1/meshes/reduced_polygon_meshes/lj2.stl"/>
        <!-- <box size="${width} ${height} ${depth}"/> -->
      </geometry>
      <origin rpy="0 0 0" xyz="0 0 0"/>
      <!-- <origin rpy="${origin_rpy}" xyz="${origin_xyz}"/> -->
      <material name="White"/>
    </visual>
    <collision>
      <geometry>
        <mesh filename="package://V1/meshes/reduced_polygon_meshes/lj2.stl"/>
      </geometry>
      <origin rpy="0 0 0" xyz="0 0 0"/>
    </collision>
  </link>
  <gazebo reference="/v1/RightHipAdductor">
    <material>Gazebo/White</material>
  </gazebo>
  <link name="/v1/RightLeg">
    <inertial>
      <mass value="10.3"/>
      <origin rpy="0 0 0" xyz="0.22 0 -0.05"/>
      <inertia ixx="0.0799327000001" ixy="0.0" ixz="0.0" iyy="0.293068" iyz="0.0" izz="0.314117"/>
    </inertial>
    <visual>
      <geometry>
        <mesh filename="package://V1/meshes/reduced_polygon_meshes/lj3_Right.stl"/>
        <!-- <box size="${width} ${height} ${depth}"/> -->
      </geometry>
      <origin rpy="0 0 0" xyz="0 0 0"/>
      <!-- <origin rpy="${origin_rpy}" xyz="${origin_xyz}"/> -->
      <material name="White"/>
    </visual>
    <collision>
      <geometry>
        <mesh filename="package://V1/meshes/reduced_polygon_meshes/lj3_Right.stl"/>
      </geometry>
      <origin rpy="0 0 0" xyz="0 0 0"/>
    </collision>
  </link>
  <gazebo reference="/v1/RightLeg">
    <material>Gazebo/White</material>
  </gazebo>
  <link name="/v1/RightShankStructure">
    <inertial>
      <mass value="7.4"/>
      <origin rpy="0 0 0" xyz="0.185 0.0 0.045"/>
      <inertia ixx="0.0514292" ixy="0.0" ixz="0.0" iyy="0.148318" iyz="0.0" izz="0.147657"/>
    </inertial>
    <visual>
      <geometry>
        <mesh filename="package://V1/meshes/reduced_polygon_meshes/lj4_Right.stl"/>
        <!-- <box size="${width} ${height} ${depth}"/> -->
      </geometry>
      <origin rpy="0 0 0" xyz="0 0 0"/>
      <!-- <origin rpy="${origin_rpy}" xyz="${origin_xyz}"/> -->
      <material name="White"/>
    </visual>
    <collision>
      <geometry>
        <mesh filename="package://V1/meshes/reduced_polygon_meshes/lj4_Right.stl"/>
      </geometry>
      <origin rpy="0 0 0" xyz="0 0 0"/>
    </collision>
  </link>
  <gazebo reference="/v1/RightShankStructure">
    <material>Gazebo/White</material>
  </gazebo>
  <link name="/v1/RightAnkleYoke">
    <inertial>
      <mass value="0.395"/>
      <origin rpy="0 0 0" xyz="0.0057963439 0.0020433211 9.0424431e-05"/>
      <inertia ixx="0.000210699583333" ixy="0.0" ixz="0.0" iyy="5.64191666667e-05" iyz="0.0" izz="0.000225972916667"/>
    </inertial>
    <visual>
      <geometry>
        <box size="0.033 0.076 0.025"/>
      </geometry>
      <origin rpy="0 0 0" xyz="0.0057963439 0.0020433211 9.0424431e-05"/>
      <material name="Gray"/>
    </visual>
    <collision>
      <geometry>
        <box size="0.033 0.076 0.025"/>
      </geometry>
      <origin rpy="0 0 0" xyz="0.0057963439 0.0020433211 9.0424431e-05"/>
    </collision>
  </link>
  <link name="/v1/RightUpperFoot">
    <inertial>
      <mass value="1.888"/>
      <origin rpy="0 0.13 0" xyz="0.048263578 -3.1591183e-05 0.077849126"/>
      <inertia ixx="0.0167377493333" ixy="0.0" ixz="0.0" iyy="0.0152179093333" iyz="0.0" izz="0.00363565866667"/>
    </inertial>
    <visual>
      <geometry>
        <mesh filename="package://V1/meshes/reduced_polygon_meshes/lj6_Right.stl"/>
        <!-- <box size="${width} ${height} ${depth}"/> -->
      </geometry>
      <origin rpy="0 0.13 0" xyz="0 0 0"/>
      <!-- <origin rpy="${origin_rpy}" xyz="${origin_xyz}"/> -->
      <material name="White"/>
    </visual>
    <collision>
      <origin rpy="0 0.13 0" xyz="0.048263578 -3.1591183e-05 0.077849126"/>
      <geometry>
        <box size="0.082 0.128 0.3"/>
      </geometry>
    </collision>
  </link>
  <gazebo reference="/v1/RightUpperFoot">
    <material>Gazebo/White</material>
  </gazebo>
  <!-- From Atlas URDF -->
  <gazebo reference="/v1/RightUpperFoot">
    <kp>100000.0</kp>
    <kd>1000.0</kd>
    <mu1>1.5</mu1>
    <mu2>1.5</mu2>
    <fdir1>0 0 1</fdir1>
    <maxVel>1.0</maxVel>
    <minDepth>0.00</minDepth>
  </gazebo>
  <!-- <xacro:box_link_no_mesh name="v1/${prefix}_Foot_Segment1"
                    width="${Foot_Segment_Width}" height="${Foot_Segment_Height}" depth="${Foot_Segment_Depth}" mass="${Foot_Segment_Mass}"
                    origin_rpy="0 0 0"
                    origin_xyz="${Foot_Segment1_Origin_X} ${reflect * Foot_Segment1_Origin_Y} ${reflect * Foot_Segment1_Origin_Z}"/>

    <xacro:box_link_no_mesh name="v1/${prefix}_Foot_Segment2"
                    width="${Foot_Segment_Width}" height="${Foot_Segment_Height}" depth="${Foot_Segment_Depth}" mass="${Foot_Segment_Mass}"
                    origin_rpy="0 0 0"
                    origin_xyz="${Foot_Segment2_Origin_X} ${reflect * Foot_Segment2_Origin_Y} ${reflect * Foot_Segment2_Origin_Z}"/>

    <xacro:box_link_no_mesh name="v1/${prefix}_Foot_Segment3"
                    width="${Foot_Segment_Width}" height="${Foot_Segment_Height}" depth="${Foot_Segment_Depth}" mass="${Foot_Segment_Mass}"
                    origin_rpy="0 0 0"
                    origin_xyz="${Foot_Segment3_Origin_X} ${reflect * Foot_Segment3_Origin_Y} ${reflect * Foot_Segment3_Origin_Z}"/> -->
  <!--     <xacro:box_link_no_mesh name="v1/${prefix}_Foot_Segment4"
                    width="${Foot_Segment_Width}" height="${Foot_Segment_Height}" depth="${Foot_Segment_Depth}" mass="${Foot_Segment_Mass}"
                    origin_rpy="0 0 0"
                    origin_xyz="${Foot_Segment4_Origin_X} ${reflect * Foot_Segment4_Origin_Y} ${reflect * Foot_Segment4_Origin_Z}"/> -->
  <!-- <xacro:box_link_no_mesh name="v1/${prefix}_Foot_Segment5"
                    width="${Foot_Segment_Width}" height="${Foot_Segment_Height}" depth="${Foot_Segment_Depth}" mass="${Foot_Segment_Mass}"
                    origin_rpy="0 0 0"
                    origin_xyz="${Foot_Segment5_Origin_X} ${reflect * Foot_Segment5_Origin_Y} ${reflect * Foot_Segment5_Origin_Z}"/>

    <xacro:box_link_no_mesh name="v1/${prefix}_Foot_Segment6"
                    width="${Foot_Segment_Width}" height="${Foot_Segment_Height}" depth="${Foot_Segment_Depth}" mass="${Foot_Segment_Mass}"
                    origin_rpy="0 0 0"
                    origin_xyz="${Foot_Segment6_Origin_X} ${reflect * Foot_Segment6_Origin_Y} ${reflect * Foot_Segment6_Origin_Z}"/> -->
  <!-- LJ1 -->
  <joint name="RightHipRotator" type="revolute">
    <origin rpy="0.0 0 -1.57079632679" xyz="0 -0.1016 -0.183"/>
    <axis xyz="0 0 1"/>
    <parent link="/v1/Pelvis"/>
    <child link="/v1/RightHipRotator"/>
    <limit effort="190" lower="-0.5235987753" upper="0.169296937347" velocity="5.89"/>
    <controller_gains Kd="500" Kp="15000"/>
    <dynamics damping="1.0" friction="0.0"/>
  </joint>
  <gazebo reference="RightHipRotator">
    <provideFeedback>1</provideFeedback>
  </gazebo>
  <!-- LJ2 -->
  <joint name="RightHipAdductor" type="revolute">
    <origin rpy="-1.57079632679 0 0" xyz="0 0 0"/>
    <axis xyz="0 0 1"/>
    <parent link="/v1/RightHipRotator"/>
    <child link="/v1/RightHipAdductor"/>
    <limit effort="350" lower="-0.5235987753" upper="0.26179938765" velocity="7"/>
    <controller_gains Kd="500" Kp="15000"/>
    <dynamics damping="1.0" friction="0.0"/>
  </joint>
  <gazebo reference="RightHipAdductor">
    <provideFeedback>1</provideFeedback>
  </gazebo>
  <!-- LJ3 -->
  <joint name="RightHipExtensor" type="revolute">
    <origin rpy="-1.57079632679 0 1.57079632679" xyz="0 0.061 0"/>
    <axis xyz="0 0 1"/>
    <parent link="/v1/RightHipAdductor"/>
    <child link="/v1/RightLeg"/>
    <limit effort="350" lower="-2.35619448885" upper="1.71042266598" velocity="6.11"/>
    <controller_gains Kd="500" Kp="15000"/>
    <dynamics damping="1.0" friction="0.0"/>
  </joint>
  <gazebo reference="RightHipExtensor">
    <provideFeedback>1</provideFeedback>
  </gazebo>
  <!-- LJ4 -->
  <joint name="RightKneeExtensor" type="revolute">
    <origin rpy="3.14159265359 0 0" xyz="0.431 0 -0.0374"/>
    <axis xyz="0 0 1"/>
    <parent link="/v1/RightLeg"/>
    <child link="/v1/RightShankStructure"/>
    <limit effort="350" lower="-1.90240888359" upper="0.218166156375" velocity="6.11"/>
    <controller_gains Kd="500" Kp="15000"/>
    <dynamics damping="1.0" friction="0.0"/>
  </joint>
  <gazebo reference="RightKneeExtensor">
    <provideFeedback>1</provideFeedback>
  </gazebo>
  <!--     <xacro:fixed_joint jointName="${prefix}MedialAnkleActuatorOffset"
                       parent="${LJ4_Distal_Link_Box}" child="${LJ4_Distal_Link_Cylinder1}"
                       origin_xyz="0 0 0"
                       origin_rpy="0 0 0"/><controller_gains Kp="15000" Kd="2<controller_gains Kp="15000" Kd="500"/>
    <xacro:fixed_joint jointName="${prefix}LateralAnkleActuatorOffset"
                       parent="${LJ4_Distal_Link_Box}" child="${LJ4_Distal_Link_Cylinder2}"
                       origin_xyz="0 0 0"
                       origin_rpy="0 0 0"/> -->
  <!-- LJ5 -->
  <joint name="RightAnkleExtensor" type="revolute">
    <origin rpy="3.14159265359 0 0" xyz="0.406 0 0"/>
    <axis xyz="0 0 1"/>
    <parent link="/v1/RightShankStructure"/>
    <child link="/v1/RightAnkleYoke"/>
    <limit effort="205" lower="-0.8726646255" upper="0.8726646255" velocity="11"/>
    <controller_gains Kd="400" Kp="15000"/>
    <dynamics damping="1.0" friction="0.0"/>
  </joint>
  <gazebo reference="RightAnkleExtensor">
    <provideFeedback>1</provideFeedback>
  </gazebo>
  <!-- LJ6 -->
  <joint name="RightAnkle" type="revolute">
    <origin rpy="1.57079632679 0 -0.13" xyz="0.0127 0 0"/>
    <axis xyz="0 0 1"/>
    <parent link="/v1/RightAnkleYoke"/>
    <child link="/v1/RightUpperFoot"/>
    <limit effort="205" lower="-0.3490658502" upper="0.3490658502" velocity="11"/>
    <controller_gains Kd="400" Kp="15000"/>
    <dynamics damping="0.3" friction="0.0"/>
  </joint>
  <gazebo reference="RightAnkle">
    <provideFeedback>1</provideFeedback>
  </gazebo>
  <!-- JOINTS -->
  <!-- <xacro:fixed_joint jointName="${prefix}FootSegment1Offset"
                       parent="${LJ6_Distal_Link}" child="v1/${prefix}_Foot_Segment1"
                       origin_rpy="0 0 0"
                       origin_xyz="0 0 0"/>

    <xacro:fixed_joint jointName="${prefix}FootSegment2Offset"
                       parent="${LJ6_Distal_Link}" child="v1/${prefix}_Foot_Segment2"
                       origin_rpy="0 0 0"
                       origin_xyz="0 0 0"/>

    <xacro:fixed_joint jointName="${prefix}FootSegment3Offset"
                       parent="${LJ6_Distal_Link}" child="v1/${prefix}_Foot_Segment3"
                       origin_rpy="0 0 0"
                       origin_xyz="0 0 0"/> -->
  <!--
    <xacro:fixed_joint jointName="${prefix}FootSegment4Offset"
                       parent="${LJ6_Distal_Link}" child="v1/${prefix}_Foot_Segment4"
                       origin_rpy="0 0 0"
                       origin_xyz="0 0 0"/> -->
  <!-- <xacro:fixed_joint jointName="${prefix}FootSegment5Offset"
                       parent="${LJ6_Distal_Link}" child="v1/${prefix}_Foot_Segment5"
                       origin_rpy="0 0 0"
                       origin_xyz="0 0 0"/>

    <xacro:fixed_joint jointName="${prefix}FootSegmen65Offset"
                       parent="${LJ6_Distal_Link}" child="v1/${prefix}_Foot_Segment6"
                       origin_rpy="0 0 0"
                       origin_xyz="0 0 0"/> -->
  <!-- <xacro:v1_leg_actuators name1="${rightleg_name1}" type1="${leg_type1}"
                            name2="${rightleg_name2}" type2="${leg_type2}"
                            name3="${rightleg_name3}" type3="${leg_type3}"
                            name4="${rightleg_name4}" type4="${leg_type4}"
                            name5="${rightleg_name5}" type5="${leg_type5}"
                            name6="${rightleg_name6}" type6="${leg_type6}"/> -->
  <!-- <xacro:v1_leg_transmissions prefix="Right" reflect="1"
                                               actuator1="${rightleg_name1}"
                                               actuator2="${rightleg_name2}"
                                               actuator3="${rightleg_name3}"
                                               actuator4="${rightleg_name4}"
                                               actuator5="${rightleg_name5}"
                                               actuator6="${rightleg_name6}" /> -->
  <!-- <xacro:v1_leg_modes prefix="Right" actuator1="${rightleg_name1}"
                                       actuator2="${rightleg_name2}"
                                       actuator3="${rightleg_name3}"
                                       actuator4="${rightleg_name4}"
                                       actuator5="${rightleg_name5}"
                                       actuator6="${rightleg_name6}" /> -->
  <!-- <xacro:v1_leg_sensors prefix="Right" reflect="1" /> -->
  <!-- <xacro:v1_hw_sensors prefix="Right" hermes_node="${rightleg_hermes}" atidaq_node="${rightleg_ati}" mpu6000_node="${rightleg_mpu2000}" cop_node="${rightleg_cop}"/> -->
  <!-- ===== LEFT LEG ===== -->
  <!-- LINKS -->
  <link name="/v1/LeftHipRotator">
    <inertial>
      <mass value="2.39"/>
      <origin rpy="0 0 0" xyz="0.001307857 0.021764163 -0.038670367"/>
      <inertia ixx="0.0172609783333" ixy="0.0" ixz="0.0" iyy="0.0148661983333" iyz="0.0" izz="0.0112381783333"/>
    </inertial>
    <visual>
      <geometry>
        <mesh filename="package://V1/meshes/reduced_polygon_meshes/lj1_Left.stl"/>
        <!-- <box size="${width} ${height} ${depth}"/> -->
      </geometry>
      <origin rpy="0 0 0" xyz="0 0 0"/>
      <!-- <origin rpy="${origin_rpy}" xyz="${origin_xyz}"/> -->
      <material name="Gold"/>
    </visual>
    <collision>
      <geometry>
        <mesh filename="package://V1/meshes/reduced_polygon_meshes/lj1_Left.stl"/>
      </geometry>
      <origin rpy="0 0 0" xyz="0 0 0"/>
    </collision>
  </link>
  <gazebo reference="/v1/LeftHipRotator">
    <material>Gazebo/Gold</material>
  </gazebo>
  <link name="/v1/LeftHipAdductor">
    <inertial>
      <mass value="5.95"/>
      <origin rpy="0 0 0" xyz="0.024260044 0.019261751 -0.0018458616"/>
      <inertia ixx="0.0244713583333" ixy="0.0" ixz="0.0" iyy="0.0160104583333" iyz="0.0" izz="0.0254788916667"/>
    </inertial>
    <visual>
      <geometry>
        <mesh filename="package://V1/meshes/reduced_polygon_meshes/lj2.stl"/>
        <!-- <box size="${width} ${height} ${depth}"/> -->
      </geometry>
      <origin rpy="0 0 0" xyz="0 0 0"/>
      <!-- <origin rpy="${origin_rpy}" xyz="${origin_xyz}"/> -->
      <material name="White"/>
    </visual>
    <collision>
      <geometry>
        <mesh filename="package://V1/meshes/reduced_polygon_meshes/lj2.stl"/>
      </geometry>
      <origin rpy="0 0 0" xyz="0 0 0"/>
    </collision>
  </link>
  <gazebo reference="/v1/LeftHipAdductor">
    <material>Gazebo/White</material>
  </gazebo>
  <link name="/v1/LeftLeg">
    <inertial>
      <mass value="10.3"/>
      <origin rpy="0 0 0" xyz="0.22 0 0.05"/>
      <inertia ixx="0.0799327000001" ixy="0.0" ixz="0.0" iyy="0.293068" iyz="0.0" izz="0.314117"/>
    </inertial>
    <visual>
      <geometry>
        <mesh filename="package://V1/meshes/reduced_polygon_meshes/lj3_Left.stl"/>
        <!-- <box size="${width} ${height} ${depth}"/> -->
      </geometry>
      <origin rpy="0 0 0" xyz="0 0 0"/>
      <!-- <origin rpy="${origin_rpy}" xyz="${origin_xyz}"/> -->
      <material name="White"/>
    </visual>
    <collision>
      <geometry>
        <mesh filename="package://V1/meshes/reduced_polygon_meshes/lj3_Left.stl"/>
      </geometry>
      <origin rpy="0 0 0" xyz="0 0 0"/>
    </collision>
  </link>
  <gazebo reference="/v1/LeftLeg">
    <material>Gazebo/White</material>
  </gazebo>
  <link name="/v1/LeftShankStructure">
    <inertial>
      <mass value="7.4"/>
      <origin rpy="0 0 0" xyz="0.185 0.0 -0.045"/>
      <inertia ixx="0.0514292" ixy="0.0" ixz="0.0" iyy="0.148318" iyz="0.0" izz="0.147657"/>
    </inertial>
    <visual>
      <geometry>
        <mesh filename="package://V1/meshes/reduced_polygon_meshes/lj4_Left.stl"/>
        <!-- <box size="${width} ${height} ${depth}"/> -->
      </geometry>
      <origin rpy="0 0 0" xyz="0 0 0"/>
      <!-- <origin rpy="${origin_rpy}" xyz="${origin_xyz}"/> -->
      <material name="White"/>
    </visual>
    <collision>
      <geometry>
        <mesh filename="package://V1/meshes/reduced_polygon_meshes/lj4_Left.stl"/>
      </geometry>
      <origin rpy="0 0 0" xyz="0 0 0"/>
    </collision>
  </link>
  <gazebo reference="/v1/LeftShankStructure">
    <material>Gazebo/White</material>
  </gazebo>
  <link name="/v1/LeftAnkleYoke">
    <inertial>
      <mass value="0.395"/>
      <origin rpy="0 0 0" xyz="0.0057963439 0.0020433211 9.0424431e-05"/>
      <inertia ixx="0.000210699583333" ixy="0.0" ixz="0.0" iyy="5.64191666667e-05" iyz="0.0" izz="0.000225972916667"/>
    </inertial>
    <visual>
      <geometry>
        <box size="0.033 0.076 0.025"/>
      </geometry>
      <origin rpy="0 0 0" xyz="0.0057963439 0.0020433211 9.0424431e-05"/>
      <material name="Gray"/>
    </visual>
    <collision>
      <geometry>
        <box size="0.033 0.076 0.025"/>
      </geometry>
      <origin rpy="0 0 0" xyz="0.0057963439 0.0020433211 9.0424431e-05"/>
    </collision>
  </link>
  <link name="/v1/LeftUpperFoot">
    <inertial>
      <mass value="1.888"/>
      <origin rpy="0 -0.13 0" xyz="0.048263578 -3.1591183e-05 -0.077849126"/>
      <inertia ixx="0.0167377493333" ixy="0.0" ixz="0.0" iyy="0.0152179093333" iyz="0.0" izz="0.00363565866667"/>
    </inertial>
    <visual>
      <geometry>
        <mesh filename="package://V1/meshes/reduced_polygon_meshes/lj6_Left.stl"/>
        <!-- <box size="${width} ${height} ${depth}"/> -->
      </geometry>
      <origin rpy="0 -0.13 0" xyz="0 0 0"/>
      <!-- <origin rpy="${origin_rpy}" xyz="${origin_xyz}"/> -->
      <material name="White"/>
    </visual>
    <collision>
      <origin rpy="0 -0.13 0" xyz="0.048263578 -3.1591183e-05 -0.077849126"/>
      <geometry>
        <box size="0.082 0.128 0.3"/>
      </geometry>
    </collision>
  </link>
  <gazebo reference="/v1/LeftUpperFoot">
    <material>Gazebo/White</material>
  </gazebo>
  <!-- From Atlas URDF -->
  <gazebo reference="/v1/LeftUpperFoot">
    <kp>100000.0</kp>
    <kd>1000.0</kd>
    <mu1>1.5</mu1>
    <mu2>1.5</mu2>
    <fdir1>0 0 1</fdir1>
    <maxVel>1.0</maxVel>
    <minDepth>0.00</minDepth>
  </gazebo>
  <!-- <xacro:box_link_no_mesh name="v1/${prefix}_Foot_Segment1"
                    width="${Foot_Segment_Width}" height="${Foot_Segment_Height}" depth="${Foot_Segment_Depth}" mass="${Foot_Segment_Mass}"
                    origin_rpy="0 0 0"
                    origin_xyz="${Foot_Segment1_Origin_X} ${reflect * Foot_Segment1_Origin_Y} ${reflect * Foot_Segment1_Origin_Z}"/>

    <xacro:box_link_no_mesh name="v1/${prefix}_Foot_Segment2"
                    width="${Foot_Segment_Width}" height="${Foot_Segment_Height}" depth="${Foot_Segment_Depth}" mass="${Foot_Segment_Mass}"
                    origin_rpy="0 0 0"
                    origin_xyz="${Foot_Segment2_Origin_X} ${reflect * Foot_Segment2_Origin_Y} ${reflect * Foot_Segment2_Origin_Z}"/>

    <xacro:box_link_no_mesh name="v1/${prefix}_Foot_Segment3"
                    width="${Foot_Segment_Width}" height="${Foot_Segment_Height}" depth="${Foot_Segment_Depth}" mass="${Foot_Segment_Mass}"
                    origin_rpy="0 0 0"
                    origin_xyz="${Foot_Segment3_Origin_X} ${reflect * Foot_Segment3_Origin_Y} ${reflect * Foot_Segment3_Origin_Z}"/> -->
  <!--     <xacro:box_link_no_mesh name="v1/${prefix}_Foot_Segment4"
                    width="${Foot_Segment_Width}" height="${Foot_Segment_Height}" depth="${Foot_Segment_Depth}" mass="${Foot_Segment_Mass}"
                    origin_rpy="0 0 0"
                    origin_xyz="${Foot_Segment4_Origin_X} ${reflect * Foot_Segment4_Origin_Y} ${reflect * Foot_Segment4_Origin_Z}"/> -->
  <!-- <xacro:box_link_no_mesh name="v1/${prefix}_Foot_Segment5"
                    width="${Foot_Segment_Width}" height="${Foot_Segment_Height}" depth="${Foot_Segment_Depth}" mass="${Foot_Segment_Mass}"
                    origin_rpy="0 0 0"
                    origin_xyz="${Foot_Segment5_Origin_X} ${reflect * Foot_Segment5_Origin_Y} ${reflect * Foot_Segment5_Origin_Z}"/>

    <xacro:box_link_no_mesh name="v1/${prefix}_Foot_Segment6"
                    width="${Foot_Segment_Width}" height="${Foot_Segment_Height}" depth="${Foot_Segment_Depth}" mass="${Foot_Segment_Mass}"
                    origin_rpy="0 0 0"
                    origin_xyz="${Foot_Segment6_Origin_X} ${reflect * Foot_Segment6_Origin_Y} ${reflect * Foot_Segment6_Origin_Z}"/> -->
  <!-- LJ1 -->
  <joint name="LeftHipRotator" type="revolute">
    <origin rpy="3.14159265359 0 1.57079632679" xyz="0 0.1016 -0.183"/>
    <axis xyz="0 0 1"/>
    <parent link="/v1/Pelvis"/>
    <child link="/v1/LeftHipRotator"/>
    <limit effort="190" lower="-0.5235987753" upper="0.169296937347" velocity="5.89"/>
    <controller_gains Kd="500" Kp="15000"/>
    <dynamics damping="1.0" friction="0.0"/>
  </joint>
  <gazebo reference="LeftHipRotator">
    <provideFeedback>1</provideFeedback>
  </gazebo>
  <!-- LJ2 -->
  <joint name="LeftHipAdductor" type="revolute">
    <origin rpy="1.57079632679 0 0" xyz="0 0 0"/>
    <axis xyz="0 0 1"/>
    <parent link="/v1/LeftHipRotator"/>
    <child link="/v1/LeftHipAdductor"/>
    <limit effort="350" lower="-0.5235987753" upper="0.26179938765" velocity="7"/>
    <controller_gains Kd="500" Kp="15000"/>
    <dynamics damping="1.0" friction="0.0"/>
  </joint>
  <gazebo reference="LeftHipAdductor">
    <provideFeedback>1</provideFeedback>
  </gazebo>
  <!-- LJ3 -->
  <joint name="LeftHipExtensor" type="revolute">
    <origin rpy="1.57079632679 0 1.57079632679" xyz="0 0.061 0"/>
    <axis xyz="0 0 1"/>
    <parent link="/v1/LeftHipAdductor"/>
    <child link="/v1/LeftLeg"/>
    <limit effort="350" lower="-2.35619448885" upper="1.71042266598" velocity="6.11"/>
    <controller_gains Kd="500" Kp="15000"/>
    <dynamics damping="1.0" friction="0.0"/>
  </joint>
  <gazebo reference="LeftHipExtensor">
    <provideFeedback>1</provideFeedback>
  </gazebo>
  <!-- LJ4 -->
  <joint name="LeftKneeExtensor" type="revolute">
    <origin rpy="3.14159265359 0 0" xyz="0.431 0 0.0374"/>
    <axis xyz="0 0 1"/>
    <parent link="/v1/LeftLeg"/>
    <child link="/v1/LeftShankStructure"/>
    <limit effort="350" lower="-1.90240888359" upper="0.218166156375" velocity="6.11"/>
    <controller_gains Kd="500" Kp="15000"/>
    <dynamics damping="1.0" friction="0.0"/>
  </joint>
  <gazebo reference="LeftKneeExtensor">
    <provideFeedback>1</provideFeedback>
  </gazebo>
  <!--     <xacro:fixed_joint jointName="${prefix}MedialAnkleActuatorOffset"
                       parent="${LJ4_Distal_Link_Box}" child="${LJ4_Distal_Link_Cylinder1}"
                       origin_xyz="0 0 0"
                       origin_rpy="0 0 0"/><controller_gains Kp="15000" Kd="2<controller_gains Kp="15000" Kd="500"/>
    <xacro:fixed_joint jointName="${prefix}LateralAnkleActuatorOffset"
                       parent="${LJ4_Distal_Link_Box}" child="${LJ4_Distal_Link_Cylinder2}"
                       origin_xyz="0 0 0"
                       origin_rpy="0 0 0"/> -->
  <!-- LJ5 -->
  <joint name="LeftAnkleExtensor" type="revolute">
    <origin rpy="3.14159265359 0 0" xyz="0.406 0 0"/>
    <axis xyz="0 0 1"/>
    <parent link="/v1/LeftShankStructure"/>
    <child link="/v1/LeftAnkleYoke"/>
    <limit effort="205" lower="-0.8726646255" upper="0.8726646255" velocity="11"/>
    <controller_gains Kd="400" Kp="15000"/>
    <dynamics damping="1.0" friction="0.0"/>
  </joint>
  <gazebo reference="LeftAnkleExtensor">
    <provideFeedback>1</provideFeedback>
  </gazebo>
  <!-- LJ6 -->
  <joint name="LeftAnkle" type="revolute">
    <origin rpy="-1.57079632679 0 -0.13" xyz="0.0127 0 0"/>
    <axis xyz="0 0 1"/>
    <parent link="/v1/LeftAnkleYoke"/>
    <child link="/v1/LeftUpperFoot"/>
    <limit effort="205" lower="-0.3490658502" upper="0.3490658502" velocity="11"/>
    <controller_gains Kd="400" Kp="15000"/>
    <dynamics damping="0.3" friction="0.0"/>
  </joint>
  <gazebo reference="LeftAnkle">
    <provideFeedback>1</provideFeedback>
  </gazebo>
  <!-- JOINTS -->
  <!-- <xacro:fixed_joint jointName="${prefix}FootSegment1Offset"
                       parent="${LJ6_Distal_Link}" child="v1/${prefix}_Foot_Segment1"
                       origin_rpy="0 0 0"
                       origin_xyz="0 0 0"/>

    <xacro:fixed_joint jointName="${prefix}FootSegment2Offset"
                       parent="${LJ6_Distal_Link}" child="v1/${prefix}_Foot_Segment2"
                       origin_rpy="0 0 0"
                       origin_xyz="0 0 0"/>

    <xacro:fixed_joint jointName="${prefix}FootSegment3Offset"
                       parent="${LJ6_Distal_Link}" child="v1/${prefix}_Foot_Segment3"
                       origin_rpy="0 0 0"
                       origin_xyz="0 0 0"/> -->
  <!--
    <xacro:fixed_joint jointName="${prefix}FootSegment4Offset"
                       parent="${LJ6_Distal_Link}" child="v1/${prefix}_Foot_Segment4"
                       origin_rpy="0 0 0"
                       origin_xyz="0 0 0"/> -->
  <!-- <xacro:fixed_joint jointName="${prefix}FootSegment5Offset"
                       parent="${LJ6_Distal_Link}" child="v1/${prefix}_Foot_Segment5"
                       origin_rpy="0 0 0"
                       origin_xyz="0 0 0"/>

    <xacro:fixed_joint jointName="${prefix}FootSegmen65Offset"
                       parent="${LJ6_Distal_Link}" child="v1/${prefix}_Foot_Segment6"
                       origin_rpy="0 0 0"
                       origin_xyz="0 0 0"/> -->
  <!-- <xacro:v1_leg_actuators name1="${leftleg_name1}" type1="${leg_type1}"
                            name2="${leftleg_name2}" type2="${leg_type2}"
                            name3="${leftleg_name3}" type3="${leg_type3}"
                            name4="${leftleg_name4}" type4="${leg_type4}"
                            name5="${leftleg_name5}" type5="${leg_type5}"
                            name6="${leftleg_name6}" type6="${leg_type6}"/> -->
  <!-- <xacro:v1_leg_transmissions prefix="Left" reflect="-1"
                                               actuator1="${leftleg_name1}"
                                               actuator2="${leftleg_name2}"
                                               actuator3="${leftleg_name3}"
                                               actuator4="${leftleg_name4}"
                                               actuator5="${leftleg_name5}"
                                               actuator6="${leftleg_name6}" /> -->
  <!-- <xacro:v1_leg_modes prefix="Left" actuator1="${leftleg_name1}"
                                       actuator2="${leftleg_name2}"
                                       actuator3="${leftleg_name3}"
                                       actuator4="${leftleg_name4}"
                                       actuator5="${leftleg_name5}"
                                       actuator6="${leftleg_name6}" /> -->
</robot>
